Workbook
Name CONST_CNTR_TotProd: #REF!
Name CONST_ElecConsumption: #REF!

Sheet 温室气体盘查清册 (2)
B1: 温室气体盘查清册 | L1: 编号：DY-GHG-2025-01
L2: 版本/版次：A/1
L3: 日期：2025/7/3
B4: 组织名称： | C4: 大冶特殊钢有限公司
B5: 组织边界： | C5: 湖北省黄石市黄石大道316号
B6: 盘查覆盖周期: | C6: 2024年1月1日至2024年12月31日
B7: 编制 ： | E7: 审核： | K7: 核准：
B8: 报告边界 | C8: 运营控制权 | E8: 范围一排放量： | F8: =F14 -> #REF! | K8: 单位：tCO2e
E9: 范围二（基于位置）排放量： | F9: =F47 -> 1043611.1
E10: 范围二（基于市场）排放量： | F10: =F48 -> 1186800.3
B11: 排放 | E11: 范围三排放量： | F11: =SUM(F50,F76,F89,F101,F106,F113,F118,F124,F130,F136) -> #REF!
B12: 编号 | C12: 排放源 | D12: 排放设施 | E12: 备注 | F12: 总排放量 | G12: CO2 | H12: CH4 | I12: N2O | J12: HFCs | K12: PFCs | L12: SF6 | M12: NF3
G13: tCO2e
B14: 范围一 直接排放 | F14: =F15+F24+F27+F33 -> #REF! | G14: =G15+G24+G27+G33 -> #REF! | H14: =H15+H24+H27+H33 -> #REF! | I14: =I15+I24+I27+I33 -> #REF! | J14: =J15+J24+J27+J33 -> #REF! | K14: =K15+K24+K27+K33 -> #REF! | L14: =L15+L24+L27+L33 -> #REF! | M14: =M15+M24+M27+M33 -> #REF!
B15: 1.1 | C15: 固定源燃烧直接排放 | F15: =SUM(G15:M15) -> #REF! | G15: =SUM(G16:G23) -> #REF! | H15: =SUM(H16:H23) -> #REF! | I15: =SUM(I16:I23) -> #REF! | J15: =SUM(J16:J23) -> #REF! | K15: =SUM(K16:K23) -> #REF! | L15: =SUM(L16:L23) -> #REF! | M15: =SUM(M16:M23) -> #REF!
B16: 1.1.1 | C16: =表1温室气体盘查表!C5 -> 天然气燃烧 | D16: =表1温室气体盘查表!D5 -> 热处理炉（加热炉） | F16: =SUM(G16:M16) -> 31469.159 | G16: =表1温室气体盘查表!AF5 -> 31438.225 | H16: =表1温室气体盘查表!AG5 -> 15.635053 | I16: =表1温室气体盘查表!AH5 -> 15.298816 | J16: =表1温室气体盘查表!AI5 -> 0 | K16: =表1温室气体盘查表!AJ5 -> 0 | L16: =表1温室气体盘查表!AK5 -> 0 | M16: =表1温室气体盘查表!AL5 -> 0
B17: 1.1.2 | C17: =表1温室气体盘查表!C6 -> 液化石油气燃烧 | D17: =表1温室气体盘查表!D6 -> 冶钢宾馆 | F17: =SUM(G17:M17) -> 29.286595 | G17: =表1温室气体盘查表!AF6 -> 29.260998 | H17: =表1温室气体盘查表!AG6 -> 0.012937905 | I17: =表1温室气体盘查表!AH6 -> 0.012659671 | J17: =表1温室气体盘查表!AI6 -> 0 | K17: =表1温室气体盘查表!AJ6 -> 0 | L17: =表1温室气体盘查表!AK6 -> 0 | M17: =表1温室气体盘查表!AL6 -> 0
B18: 1.1.3 | C18: =表1温室气体盘查表!C7 -> 烟煤燃烧 | D18: =表1温室气体盘查表!D7 -> 高炉 | F18: =SUM(G18:M18) -> 749580.33 | G18: =表1温室气体盘查表!AF7 -> 746259.74 | H18: =表1温室气体盘查表!AG7 -> 211.80719 | I18: =表1温室气体盘查表!AH7 -> 3108.783 | J18: =表1温室气体盘查表!AI7 -> 0 | K18: =表1温室气体盘查表!AJ7 -> 0 | L18: =表1温室气体盘查表!AK7 -> 0 | M18: =表1温室气体盘查表!AL7 -> 0
B19: 1.1.4 | C19: =表1温室气体盘查表!C8 -> 无烟煤燃烧 | D19: =表1温室气体盘查表!D8 -> 高炉、烧结 | F19: =SUM(G19:M19) -> 820622.2 | G19: =表1温室气体盘查表!AF8 -> 816986.9 | H19: =表1温室气体盘查表!AG8 -> 231.88133 | I19: =表1温室气体盘查表!AH8 -> 3403.4195 | J19: =表1温室气体盘查表!AI8 -> 0 | K19: =表1温室气体盘查表!AJ8 -> 0 | L19: =表1温室气体盘查表!AK8 -> 0 | M19: =表1温室气体盘查表!AL8 -> 0
B20: 1.1.5 | C20: =表1温室气体盘查表!C9 -> 洗精煤燃烧 | D20: =表1温室气体盘查表!D9 -> 焦炉 | F20: =SUM(G20:M20) -> 5189313.3 | G20: =表1温室气体盘查表!AF9 -> 5165430 | H20: =表1温室气体盘查表!AG9 -> 1523.4196 | I20: =表1温室气体盘查表!AH9 -> 22359.869 | J20: =表1温室气体盘查表!AI9 -> 0 | K20: =表1温室气体盘查表!AJ9 -> 0 | L20: =表1温室气体盘查表!AK9 -> 0 | M20: =表1温室气体盘查表!AL9 -> 0
B21: 1.1.6 | C21: =表1温室气体盘查表!C10 -> 焦炭燃烧 | D21: =表1温室气体盘查表!D10 -> 高炉 | F21: =SUM(G21:M21) -> 669939.56 | G21: =表1温室气体盘查表!AF10 -> 667212.1 | H21: =表1温室气体盘查表!AG10 -> 173.974 | I21: =表1温室气体盘查表!AH10 -> 2553.4893 | J21: =表1温室气体盘查表!AI10 -> 0 | K21: =表1温室气体盘查表!AJ10 -> 0 | L21: =表1温室气体盘查表!AK10 -> 0 | M21: =表1温室气体盘查表!AL10 -> 0
B22: 1.1.7 | C22: =表1温室气体盘查表!#REF! -> #REF! | D22: =表1温室气体盘查表!#REF! -> #REF! | F22: =SUM(G22:M22) -> #REF! | G22: =表1温室气体盘查表!#REF! -> #REF! | H22: =表1温室气体盘查表!#REF! -> #REF! | I22: =表1温室气体盘查表!#REF! -> #REF! | J22: =表1温室气体盘查表!#REF! -> #REF! | K22: =表1温室气体盘查表!#REF! -> #REF! | L22: =表1温室气体盘查表!#REF! -> #REF! | M22: =表1温室气体盘查表!#REF! -> #REF!
B23: 1.1.8 | C23: =表1温室气体盘查表!C11 -> 焦炉煤气燃烧 | D23: =表1温室气体盘查表!D11 -> 外售 | F23: =SUM(G23:M23) -> -6034.9102 | G23: =表1温室气体盘查表!AF11 -> -6027.4166 | H23: =表1温室气体盘查表!AG11 -> -3.7874983 | I23: =表1温室气体盘查表!AH11 -> -3.7060467 | J23: =表1温室气体盘查表!AI11 -> 0 | K23: =表1温室气体盘查表!AJ11 -> 0 | L23: =表1温室气体盘查表!AK11 -> 0 | M23: =表1温室气体盘查表!AL11 -> 0
B24: 1.2 | C24: 移动源燃烧直接排放 | F24: =SUM(G24:M24) -> 4620.5168 | G24: =SUM(G25:G26) -> 4544.9741 | H24: =SUM(H25:H26) -> 7.8643134 | I24: =SUM(I25:I26) -> 67.678446 | J24: =SUM(J25:J26) -> 0 | K24: =SUM(K25:K26) -> 0 | L24: =SUM(L25:L26) -> 0 | M24: =SUM(M25:M26) -> 0
B25: 1.2.1 | C25: =表1温室气体盘查表!C12 -> 柴油燃烧 | D25: =表1温室气体盘查表!D12 -> 场内运输 | F25: =SUM(G25:M25) -> 4476.287 | G25: =表1温室气体盘查表!AF12 -> 4406.5019 | H25: =表1温室气体盘查表!AG12 -> 6.4706002 | I25: =表1温室气体盘查表!AH12 -> 63.314475 | J25: =表1温室气体盘查表!AI12 -> 0 | K25: =表1温室气体盘查表!AJ12 -> 0 | L25: =表1温室气体盘查表!AK12 -> 0 | M25: =表1温室气体盘查表!AL12 -> 0
B26: 1.2.2 | C26: =表1温室气体盘查表!C13 -> 汽油燃烧 | D26: =表1温室气体盘查表!D13 -> 公务车 | F26: =SUM(G26:M26) -> 144.22983 | G26: =表1温室气体盘查表!AF13 -> 138.47215 | H26: =表1温室气体盘查表!AG13 -> 1.3937132 | I26: =表1温室气体盘查表!AH13 -> 4.3639708 | J26: =表1温室气体盘查表!AI13 -> 0 | K26: =表1温室气体盘查表!AJ13 -> 0 | L26: =表1温室气体盘查表!AK13 -> 0 | M26: =表1温室气体盘查表!AL13 -> 0
B27: 1.3 | C27: 逸散源直接排放 | F27: =SUM(G27:M27) -> #REF! | G27: =SUM(G28:G32) -> #REF! | H27: =SUM(H28:H32) -> #REF! | I27: =SUM(I28:I32) -> #REF! | J27: =SUM(J28:J32) -> #REF! | K27: =SUM(K28:K32) -> #REF! | L27: =SUM(L28:L32) -> #REF! | M27: =SUM(M28:M32) -> #REF!
B28: 1.3.1 | C28: =表1温室气体盘查表!C14 -> 制冷剂逸散（R32） | D28: =表1温室气体盘查表!D14 -> 分体式空调 | F28: =SUM(G28:M28) -> 570.54 | G28: =表1温室气体盘查表!AF14 -> 0 | H28: =表1温室气体盘查表!AG14 -> 0 | I28: =表1温室气体盘查表!AH14 -> 0 | J28: =表1温室气体盘查表!AI14 -> 570.54 | K28: =表1温室气体盘查表!AJ14 -> 0 | L28: =表1温室气体盘查表!AK14 -> 0 | M28: =表1温室气体盘查表!AL14 -> 0
B29: 1.3.2 | C29: =表1温室气体盘查表!C15 -> CO2逸散 | D29: =表1温室气体盘查表!D15 -> 二氧化碳灭火器 | F29: =SUM(G29:M29) -> 0.56 | G29: =表1温室气体盘查表!AF15 -> 0.56 | H29: =表1温室气体盘查表!AG15 -> 0 | I29: =表1温室气体盘查表!AH15 -> 0 | J29: =表1温室气体盘查表!AI15 -> 0 | K29: =表1温室气体盘查表!AJ15 -> 0 | L29: =表1温室气体盘查表!AK15 -> 0 | M29: =表1温室气体盘查表!AL15 -> 0
B30: 1.3.3 | C30: =表1温室气体盘查表!C16 -> CH4逸散 | D30: =表1温室气体盘查表!D16 -> 化粪池 | F30: =SUM(G30:M30) -> 116.30952 | G30: =表1温室气体盘查表!AF16 -> 0 | H30: =表1温室气体盘查表!AG16 -> 116.30952 | I30: =表1温室气体盘查表!AH16 -> 0 | J30: =表1温室气体盘查表!AI16 -> 0 | K30: =表1温室气体盘查表!AJ16 -> 0 | L30: =表1温室气体盘查表!AK16 -> 0 | M30: =表1温室气体盘查表!AL16 -> 0
B31: 1.3.4 | C31: =表1温室气体盘查表!C17 -> CH4逸散 | D31: =表1温室气体盘查表!D17 -> 耗氧池 | F31: =SUM(G31:M31) -> 8408.8577 | G31: =表1温室气体盘查表!AF17 -> 0 | H31: =表1温室气体盘查表!AG17 -> 8408.8577 | I31: =表1温室气体盘查表!AH17 -> 0 | J31: =表1温室气体盘查表!AI17 -> 0 | K31: =表1温室气体盘查表!AJ17 -> 0 | L31: =表1温室气体盘查表!AK17 -> 0 | M31: =表1温室气体盘查表!AL17 -> 0
B32: 1.3.5 | C32: =表1温室气体盘查表!#REF! -> #REF! | D32: =表1温室气体盘查表!#REF! -> #REF! | F32: =SUM(G32:M32) -> #REF! | G32: =表1温室气体盘查表!#REF! -> #REF! | H32: =表1温室气体盘查表!#REF! -> #REF! | I32: =表1温室气体盘查表!#REF! -> #REF! | J32: =表1温室气体盘查表!#REF! -> #REF! | K32: =表1温室气体盘查表!#REF! -> #REF! | L32: =表1温室气体盘查表!#REF! -> #REF! | M32: =表1温室气体盘查表!#REF! -> #REF!
B33: 1.4 | C33: 制程排放 | F33: =SUM(G33:M33) -> #REF! | G33: =SUM(G34:G45) -> #REF! | H33: =SUM(H34:H45) -> #REF! | I33: =SUM(I34:I45) -> #REF! | J33: =SUM(J34:J45) -> #REF! | K33: =SUM(K34:K45) -> #REF! | L33: =SUM(L34:L45) -> #REF! | M33: =SUM(M34:M45) -> #REF!
B34: 1.4.1 | C34: =表1温室气体盘查表!#REF! -> #REF! | D34: =表1温室气体盘查表!#REF! -> #REF! | F34: =SUM(G34:M34) -> #REF! | G34: =表1温室气体盘查表!#REF! -> #REF! | H34: =表1温室气体盘查表!#REF! -> #REF! | I34: =表1温室气体盘查表!#REF! -> #REF! | J34: =表1温室气体盘查表!#REF! -> #REF! | K34: =表1温室气体盘查表!#REF! -> #REF! | L34: =表1温室气体盘查表!#REF! -> #REF! | M34: =表1温室气体盘查表!#REF! -> #REF!
B35: 1.4.2 | C35: =表1温室气体盘查表!C18 -> 白云石 | D35: =表1温室气体盘查表!D18 -> 高炉 | F35: =SUM(G35:M35) -> 18406.658 | G35: =表1温室气体盘查表!AF18 -> 18406.658 | H35: =表1温室气体盘查表!AG18 -> 0 | I35: =表1温室气体盘查表!AH18 -> 0 | J35: =表1温室气体盘查表!AI18 -> 0 | K35: =表1温室气体盘查表!AJ18 -> 0 | L35: =表1温室气体盘查表!AK18 -> 0 | M35: =表1温室气体盘查表!AL18 -> 0
B36: 1.4.3 | C36: =表1温室气体盘查表!C19 -> 电极 | D36: =表1温室气体盘查表!D19 -> 炼钢 | F36: =SUM(G36:M36) -> 18334.963 | G36: =表1温室气体盘查表!AF19 -> 18334.963 | H36: =表1温室气体盘查表!AG19 -> 0 | I36: =表1温室气体盘查表!AH19 -> 0 | J36: =表1温室气体盘查表!AI19 -> 0 | K36: =表1温室气体盘查表!AJ19 -> 0 | L36: =表1温室气体盘查表!AK19 -> 0 | M36: =表1温室气体盘查表!AL19 -> 0
B37: 1.4.4 | C37: =表1温室气体盘查表!C20 -> 废钢 | D37: =表1温室气体盘查表!D20 -> 炼钢 | F37: =SUM(G37:M37) -> 41425.779 | G37: =表1温室气体盘查表!AF20 -> 41425.779 | H37: =表1温室气体盘查表!AG20 -> 0 | I37: =表1温室气体盘查表!AH20 -> 0 | J37: =表1温室气体盘查表!AI20 -> 0 | K37: =表1温室气体盘查表!AJ20 -> 0 | L37: =表1温室气体盘查表!AK20 -> 0 | M37: =表1温室气体盘查表!AL20 -> 0
B38: 1.4.5 | C38: =表1温室气体盘查表!C21 -> 高碳锰铁 | D38: =表1温室气体盘查表!D21 -> 炼钢 | F38: =SUM(G38:M38) -> 11407.872 | G38: =表1温室气体盘查表!AF21 -> 11407.872 | H38: =表1温室气体盘查表!AG21 -> 0 | I38: =表1温室气体盘查表!AH21 -> 0 | J38: =表1温室气体盘查表!AI21 -> 0 | K38: =表1温室气体盘查表!AJ21 -> 0 | L38: =表1温室气体盘查表!AK21 -> 0 | M38: =表1温室气体盘查表!AL21 -> 0
B39: 1.4.6 | C39: =表1温室气体盘查表!C23 -> 镍铁 | D39: =表1温室气体盘查表!D23 -> 炼钢 | F39: =SUM(G39:M39) -> 367.8984 | G39: =表1温室气体盘查表!AF23 -> 367.8984 | H39: =表1温室气体盘查表!AG23 -> 0 | I39: =表1温室气体盘查表!AH23 -> 0 | J39: =表1温室气体盘查表!AI23 -> 0 | K39: =表1温室气体盘查表!AJ23 -> 0 | L39: =表1温室气体盘查表!AK23 -> 0 | M39: =表1温室气体盘查表!AL23 -> 0
B40: 1.4.7 | C40: =表1温室气体盘查表!C24 -> 高碳铬铁 | D40: =表1温室气体盘查表!D24 -> 炼钢 | F40: =SUM(G40:M40) -> 13992.429 | G40: =表1温室气体盘查表!AF24 -> 13992.429 | H40: =表1温室气体盘查表!AG24 -> 0 | I40: =表1温室气体盘查表!AH24 -> 0 | J40: =表1温室气体盘查表!AI24 -> 0 | K40: =表1温室气体盘查表!AJ24 -> 0 | L40: =表1温室气体盘查表!AK24 -> 0 | M40: =表1温室气体盘查表!AL24 -> 0
...

Sheet 修改日志&问题
C2: 修改日志 | D2: 问题
B3: 2026.3.17 | C3: 完成了表1温室气体盘查表数据填写并比对两年数据
B4: 2026.3.18 | C4: 更新了“附表2-EF”，并同步更新了其他表格 | D4: 部分排放因子需和核查老师确认是否需要更新

Sheet 基本信息
A1: 变量名 | B1: 变量名 | C1: 值
A2: 公司名称 | B2: company_name | C2: 大冶特殊钢有限公司
A3: 报告周期 | B3: reporting_period | C3: 2025年1月1日至2025年12月31日
A4: 报告编号 | B4: document_number | C4: DY-GHG-2026-01
A5: 生成日期 | B5: posted_time | C5: 46206
A6: 统一社会信用代码 | B6: Unified_Social_Credit_Identifier | C6: 91420000798750168P
A7: 法人代表 | B7: legal_person | C7: 蒋乔
A8: 注册资金 | B8: registered_capital | C8: 207218.53万元
A9: 注册日期 | B9: date_of_establishment | C9: 39150
A10: 注册地址 | B10: registered_address | C10: 湖北省黄石市黄石大道316号
A11: 生产地址 | B11: production_address | C11: 湖北省黄石市黄石大道316号
A12: 经营范围 | B12: scope_of_business | C12: 大冶特殊钢有限公司成立于2007年03月09日，注册地位于湖北省黄石市黄石大道316号，法定代表人为蒋乔。经营范围包括黑色、有色金属冶炼、压延加工；生产、销售高温合金材料、耐蚀合金材料、铁矿石、钢坯、钢锭、钢材、金属制品、钢管及管件和相应的工业辅助材料及承接来料加工业务；钢铁和合金材料检测；再生资源回收经营；货物或技术进出口（国家限定公司经营或禁止进出口的商品和技术除外）；机械零件、汽车零部件制造和加工；机械、仪表、电器制造和修理；化工产品（不含危险品和限制类产品）制造；港口码头建设及经营；煤气、热力、自来水、工业用水生产和供应；餐饮经营与管理。（涉及许可经营项目，应取得相关部门许可后方可经营）。
A13: 公司简介 | B13: company_profile | C13: 大冶特殊钢有限公司（简称：大冶特钢）是中国近代“钢铁摇篮”，地处中国矿冶之都、先进制造业基地湖北省黄石市。隶属中信泰富特钢集团，是其沿海沿江产业链的战略布局中的重要一环。 大冶特钢是国家高新技术企业、全国首批两化融合示范企业、全国首批绿色制造示范企业、全国绿化模范单位。拥有国家认定企业技术中心、院士专家工作站、博士后科研工作站、高品质特殊钢湖北省重点实验室，先后承担国家多项冶金课题的项目攻关，主持或参与起草修订了多项国家和行业技术标准。先后荣获“全国质量奖”、“全国质量标杆”、“中国工业大奖表彰奖”，多项产品荣获国家冶金产品实物质量“金杯奖”、“国家科学技术进步一等奖、二等奖”、“冶金科学技术奖一等奖”、“国家知识产权优势企业”、“中国航天突出贡献供应商”、“中国工模具行业最具影响力钢厂品牌”等奖项。 大冶特钢是中国品种规格最齐全的高品质棒材、高端中厚壁无缝钢管、高合金锻材三大特钢生产基地，工艺技术和装备具备世界先进水平。主要产品有轴承钢、汽车用钢、能源用钢、工程机械用钢、航空航天用钢等。主要服务于航天航空、海洋、核电、风电、交通、火电、油气、工程机械、重燃、船舶、石化、汽车、高铁等关键领域。 从中国第一炉电渣钢到第一根极薄壁高温合金旋压管，从第一个飞机用高温合金涡轮盘，到第一根轧制的飞机大梁(毛坯)，从中国第一颗人造地球卫星，到神舟系列飞船的上天，到“嫦娥”奔月，再到“天宫”“北斗”发射升空，大冶特钢均提供了关键部件的用钢。工程机械用无缝钢管已连续13年产销量全国第一、13年全球第一，石油工具及装备用中厚壁无缝钢管连续10年产销量全国第一，大口径厚壁高压锅炉用管连续5年产销量全国第一。 大冶特钢秉承“诚信、创新、融合、卓越”的理念，牢记为客户创造价值，为员工创造幸福，为股东创造效益，为社会创造财富的企业使命，致力于为客户提供多规格、多品种、高品质的特殊钢产品及整体服务方案，致力于“创建全球最具竞争力的特钢企业集团”。
A14: DDL | B14: deadline | C14: 2026年6月底前
A15: 规则文件 | B15: rule_file | C15: 《大冶特殊钢温室气体盘查控制程序（DY-GHG-2023）》
A16: GWP值来源文件 | B16: GWP_Value_Reference_Document | C16: IPCC 2021年出具的《第六次评估报告AR6》
B17: source_file | C17: 《温室气体盘查清册》-表2 不确定性评估
A18: 制作 | B18: producer | C18: 杨春英
A19: 审核 | B19: auditor
A20: 核准 | B20: approver
A21: 报告年 | B21: report_year | C21: 2025
A22: 下一年 | B22: next_year | C22: =C21+1 -> 2026

Sheet 温室气体盘查清册
B1: 温室气体盘查清册 | L1: 编号：DY-GHG-2025-01
L2: 版本/版次：A/1
L3: 日期：2026/7/3
B4: 组织名称： | C4: 大冶特殊钢有限公司
B5: 组织边界： | C5: 湖北省黄石市黄石大道316号
B6: 盘查覆盖周期: | C6: 2025年1月1日至2025年12月31日
B7: 编制 ： | E7: 审核： | K7: 核准：
B8: 报告边界 | C8: 运营控制权 | E8: 范围一排放量： | F8: =F14 -> 7174685 | K8: 单位：tCO2e
E9: 范围二（基于位置）排放量： | F9: =F45 -> 1043611.1
E10: 范围二（基于市场）排放量： | F10: =F46 -> 1186800.3
B11: 排放 | E11: 范围三排放量： | F11: =SUM(F48,F74,F85,F96,F101,F107,F112,F119,F125,F134,F131) -> 7161889.5
B12: 编号 | C12: 排放源 | D12: 排放设施 | E12: 备注 | F12: 总排放量 | G12: CO2 | H12: CH4 | I12: N2O | J12: HFCs | K12: PFCs | L12: SF6 | M12: NF3
G13: tCO2e
B14: 范围一 直接排放 | F14: =F15+F23+F26+F31 -> 7174685 | G14: =G15+G23+G26+G31 -> 7131923.6 | H14: =H15+H23+H26+H31 -> 10685.974 | I14: =I15+I23+I26+I31 -> 31504.844 | J14: =J15+J23+J26+J31 -> 570.54 | K14: =K15+K23+K26+K31 -> 0 | L14: =L15+L23+L26+L31 -> 0 | M14: =M15+M23+M26+M31 -> 0
B15: 1.1 | C15: 固定源燃烧直接排放 | F15: =SUM(G15:M15) -> 7454918.9 | G15: =SUM(G16:G22) -> 7421328.8 | H15: =SUM(H16:H22) -> 2152.9426 | I15: =SUM(I16:I22) -> 31437.166 | J15: =SUM(J16:J22) -> 0 | K15: =SUM(K16:K22) -> 0 | L15: =SUM(L16:L22) -> 0 | M15: =SUM(M16:M22) -> 0
B16: 1.1.1 | C16: =表1温室气体盘查表!C5 -> 天然气燃烧 | D16: =表1温室气体盘查表!D5 -> 热处理炉（加热炉） | F16: =SUM(G16:M16) -> 31469.159 | G16: =表1温室气体盘查表!AF5 -> 31438.225 | H16: =表1温室气体盘查表!AG5 -> 15.635053 | I16: =表1温室气体盘查表!AH5 -> 15.298816 | J16: =表1温室气体盘查表!AI5 -> 0 | K16: =表1温室气体盘查表!AJ5 -> 0 | L16: =表1温室气体盘查表!AK5 -> 0 | M16: =表1温室气体盘查表!AL5 -> 0
B17: 1.1.2 | C17: =表1温室气体盘查表!C6 -> 液化石油气燃烧 | D17: =表1温室气体盘查表!D6 -> 冶钢宾馆 | F17: =SUM(G17:M17) -> 29.286595 | G17: =表1温室气体盘查表!AF6 -> 29.260998 | H17: =表1温室气体盘查表!AG6 -> 0.012937905 | I17: =表1温室气体盘查表!AH6 -> 0.012659671 | J17: =表1温室气体盘查表!AI6 -> 0 | K17: =表1温室气体盘查表!AJ6 -> 0 | L17: =表1温室气体盘查表!AK6 -> 0 | M17: =表1温室气体盘查表!AL6 -> 0
B18: 1.1.3 | C18: =表1温室气体盘查表!C7 -> 烟煤燃烧 | D18: =表1温室气体盘查表!D7 -> 高炉 | F18: =SUM(G18:M18) -> 749580.33 | G18: =表1温室气体盘查表!AF7 -> 746259.74 | H18: =表1温室气体盘查表!AG7 -> 211.80719 | I18: =表1温室气体盘查表!AH7 -> 3108.783 | J18: =表1温室气体盘查表!AI7 -> 0 | K18: =表1温室气体盘查表!AJ7 -> 0 | L18: =表1温室气体盘查表!AK7 -> 0 | M18: =表1温室气体盘查表!AL7 -> 0
B19: 1.1.4 | C19: =表1温室气体盘查表!C8 -> 无烟煤燃烧 | D19: =表1温室气体盘查表!D8 -> 高炉、烧结 | F19: =SUM(G19:M19) -> 820622.2 | G19: =表1温室气体盘查表!AF8 -> 816986.9 | H19: =表1温室气体盘查表!AG8 -> 231.88133 | I19: =表1温室气体盘查表!AH8 -> 3403.4195 | J19: =表1温室气体盘查表!AI8 -> 0 | K19: =表1温室气体盘查表!AJ8 -> 0 | L19: =表1温室气体盘查表!AK8 -> 0 | M19: =表1温室气体盘查表!AL8 -> 0
B20: 1.1.5 | C20: =表1温室气体盘查表!C9 -> 洗精煤燃烧 | D20: =表1温室气体盘查表!D9 -> 焦炉 | F20: =SUM(G20:M20) -> 5189313.3 | G20: =表1温室气体盘查表!AF9 -> 5165430 | H20: =表1温室气体盘查表!AG9 -> 1523.4196 | I20: =表1温室气体盘查表!AH9 -> 22359.869 | J20: =表1温室气体盘查表!AI9 -> 0 | K20: =表1温室气体盘查表!AJ9 -> 0 | L20: =表1温室气体盘查表!AK9 -> 0 | M20: =表1温室气体盘查表!AL9 -> 0
B21: 1.1.6 | C21: =表1温室气体盘查表!C10 -> 焦炭燃烧 | D21: =表1温室气体盘查表!D10 -> 高炉 | F21: =SUM(G21:M21) -> 669939.56 | G21: =表1温室气体盘查表!AF10 -> 667212.1 | H21: =表1温室气体盘查表!AG10 -> 173.974 | I21: =表1温室气体盘查表!AH10 -> 2553.4893 | J21: =表1温室气体盘查表!AI10 -> 0 | K21: =表1温室气体盘查表!AJ10 -> 0 | L21: =表1温室气体盘查表!AK10 -> 0 | M21: =表1温室气体盘查表!AL10 -> 0
B22: 1.1.7 | C22: =表1温室气体盘查表!C11 -> 焦炉煤气燃烧 | D22: =表1温室气体盘查表!D11 -> 外售 | F22: =SUM(G22:M22) -> -6034.9102 | G22: =表1温室气体盘查表!AF11 -> -6027.4166 | H22: =表1温室气体盘查表!AG11 -> -3.7874983 | I22: =表1温室气体盘查表!AH11 -> -3.7060467 | J22: =表1温室气体盘查表!AI11 -> 0 | K22: =表1温室气体盘查表!AJ11 -> 0 | L22: =表1温室气体盘查表!AK11 -> 0 | M22: =表1温室气体盘查表!AL11 -> 0
B23: 1.2 | C23: 移动源燃烧直接排放 | F23: =SUM(G23:M23) -> 4620.5168 | G23: =SUM(G24:G25) -> 4544.9741 | H23: =SUM(H24:H25) -> 7.8643134 | I23: =SUM(I24:I25) -> 67.678446 | J23: =SUM(J24:J25) -> 0 | K23: =SUM(K24:K25) -> 0 | L23: =SUM(L24:L25) -> 0 | M23: =SUM(M24:M25) -> 0
B24: 1.2.1 | C24: =表1温室气体盘查表!C12 -> 柴油燃烧 | D24: =表1温室气体盘查表!D12 -> 场内运输 | F24: =SUM(G24:M24) -> 4476.287 | G24: =表1温室气体盘查表!AF12 -> 4406.5019 | H24: =表1温室气体盘查表!AG12 -> 6.4706002 | I24: =表1温室气体盘查表!AH12 -> 63.314475 | J24: =表1温室气体盘查表!AI12 -> 0 | K24: =表1温室气体盘查表!AJ12 -> 0 | L24: =表1温室气体盘查表!AK12 -> 0 | M24: =表1温室气体盘查表!AL12 -> 0
B25: 1.2.2 | C25: =表1温室气体盘查表!C13 -> 汽油燃烧 | D25: =表1温室气体盘查表!D13 -> 公务车 | F25: =SUM(G25:M25) -> 144.22983 | G25: =表1温室气体盘查表!AF13 -> 138.47215 | H25: =表1温室气体盘查表!AG13 -> 1.3937132 | I25: =表1温室气体盘查表!AH13 -> 4.3639708 | J25: =表1温室气体盘查表!AI13 -> 0 | K25: =表1温室气体盘查表!AJ13 -> 0 | L25: =表1温室气体盘查表!AK13 -> 0 | M25: =表1温室气体盘查表!AL13 -> 0
B26: 1.3 | C26: 逸散源直接排放 | F26: =SUM(G26:M26) -> 9096.2672 | G26: =SUM(G27:G30) -> 0.56 | H26: =SUM(H27:H30) -> 8525.1672 | I26: =SUM(I27:I30) -> 0 | J26: =SUM(J27:J30) -> 570.54 | K26: =SUM(K27:K30) -> 0 | L26: =SUM(L27:L30) -> 0 | M26: =SUM(M27:M30) -> 0
B27: 1.3.1 | C27: =表1温室气体盘查表!C14 -> 制冷剂逸散（R32） | D27: =表1温室气体盘查表!D14 -> 分体式空调 | F27: =SUM(G27:M27) -> 570.54 | G27: =表1温室气体盘查表!AF14 -> 0 | H27: =表1温室气体盘查表!AG14 -> 0 | I27: =表1温室气体盘查表!AH14 -> 0 | J27: =表1温室气体盘查表!AI14 -> 570.54 | K27: =表1温室气体盘查表!AJ14 -> 0 | L27: =表1温室气体盘查表!AK14 -> 0 | M27: =表1温室气体盘查表!AL14 -> 0
B28: 1.3.2 | C28: =表1温室气体盘查表!C15 -> CO2逸散 | D28: =表1温室气体盘查表!D15 -> 二氧化碳灭火器 | F28: =SUM(G28:M28) -> 0.56 | G28: =表1温室气体盘查表!AF15 -> 0.56 | H28: =表1温室气体盘查表!AG15 -> 0 | I28: =表1温室气体盘查表!AH15 -> 0 | J28: =表1温室气体盘查表!AI15 -> 0 | K28: =表1温室气体盘查表!AJ15 -> 0 | L28: =表1温室气体盘查表!AK15 -> 0 | M28: =表1温室气体盘查表!AL15 -> 0
B29: 1.3.3 | C29: =表1温室气体盘查表!C16 -> CH4逸散 | D29: =表1温室气体盘查表!D16 -> 化粪池 | F29: =SUM(G29:M29) -> 116.30952 | G29: =表1温室气体盘查表!AF16 -> 0 | H29: =表1温室气体盘查表!AG16 -> 116.30952 | I29: =表1温室气体盘查表!AH16 -> 0 | J29: =表1温室气体盘查表!AI16 -> 0 | K29: =表1温室气体盘查表!AJ16 -> 0 | L29: =表1温室气体盘查表!AK16 -> 0 | M29: =表1温室气体盘查表!AL16 -> 0
B30: 1.3.4 | C30: =表1温室气体盘查表!C17 -> CH4逸散 | D30: =表1温室气体盘查表!D17 -> 耗氧池 | F30: =SUM(G30:M30) -> 8408.8577 | G30: =表1温室气体盘查表!AF17 -> 0 | H30: =表1温室气体盘查表!AG17 -> 8408.8577 | I30: =表1温室气体盘查表!AH17 -> 0 | J30: =表1温室气体盘查表!AI17 -> 0 | K30: =表1温室气体盘查表!AJ17 -> 0 | L30: =表1温室气体盘查表!AK17 -> 0 | M30: =表1温室气体盘查表!AL17 -> 0
B31: 1.4 | C31: 制程排放 | F31: =SUM(G31:M31) -> -293950.76 | G31: =SUM(G32:G43) -> -293950.76 | H31: =SUM(H32:H43) -> 0 | I31: =SUM(I32:I43) -> 0 | J31: =SUM(J32:J43) -> 0 | K31: =SUM(K32:K43) -> 0 | L31: =SUM(L32:L43) -> 0 | M31: =SUM(M32:M43) -> 0
B32: 1.4.1 | C32: =表1温室气体盘查表!C18 -> 白云石 | D32: =表1温室气体盘查表!D18 -> 高炉 | F32: =SUM(G32:M32) -> 18406.658 | G32: =表1温室气体盘查表!AF18 -> 18406.658 | H32: =表1温室气体盘查表!AG18 -> 0 | I32: =表1温室气体盘查表!AH18 -> 0 | J32: =表1温室气体盘查表!AI18 -> 0 | K32: =表1温室气体盘查表!AJ18 -> 0 | L32: =表1温室气体盘查表!AK18 -> 0 | M32: =表1温室气体盘查表!AL18 -> 0
B33: 1.4.2 | C33: =表1温室气体盘查表!C19 -> 电极 | D33: =表1温室气体盘查表!D19 -> 炼钢 | F33: =SUM(G33:M33) -> 18334.963 | G33: =表1温室气体盘查表!AF19 -> 18334.963 | H33: =表1温室气体盘查表!AG19 -> 0 | I33: =表1温室气体盘查表!AH19 -> 0 | J33: =表1温室气体盘查表!AI19 -> 0 | K33: =表1温室气体盘查表!AJ19 -> 0 | L33: =表1温室气体盘查表!AK19 -> 0 | M33: =表1温室气体盘查表!AL19 -> 0
B34: 1.4.3 | C34: =表1温室气体盘查表!C20 -> 废钢 | D34: =表1温室气体盘查表!D20 -> 炼钢 | F34: =SUM(G34:M34) -> 41425.779 | G34: =表1温室气体盘查表!AF20 -> 41425.779 | H34: =表1温室气体盘查表!AG20 -> 0 | I34: =表1温室气体盘查表!AH20 -> 0 | J34: =表1温室气体盘查表!AI20 -> 0 | K34: =表1温室气体盘查表!AJ20 -> 0 | L34: =表1温室气体盘查表!AK20 -> 0 | M34: =表1温室气体盘查表!AL20 -> 0
B35: 1.4.4 | C35: =表1温室气体盘查表!C21 -> 高碳锰铁 | D35: =表1温室气体盘查表!D21 -> 炼钢 | F35: =SUM(G35:M35) -> 11407.872 | G35: =表1温室气体盘查表!AF21 -> 11407.872 | H35: =表1温室气体盘查表!AG21 -> 0 | I35: =表1温室气体盘查表!AH21 -> 0 | J35: =表1温室气体盘查表!AI21 -> 0 | K35: =表1温室气体盘查表!AJ21 -> 0 | L35: =表1温室气体盘查表!AK21 -> 0 | M35: =表1温室气体盘查表!AL21 -> 0
B36: 1.4.5 | C36: =表1温室气体盘查表!C22 -> 锰硅合金 | D36: =表1温室气体盘查表!D22 -> 炼钢 | F36: =SUM(G36:M36) -> 265.66748 | G36: =表1温室气体盘查表!AF22 -> 265.66748 | H36: =表1温室气体盘查表!AG22 -> 0 | I36: =表1温室气体盘查表!AH22 -> 0 | J36: =表1温室气体盘查表!AI22 -> 0 | K36: =表1温室气体盘查表!AJ22 -> 0 | L36: =表1温室气体盘查表!AK22 -> 0 | M36: =表1温室气体盘查表!AL22 -> 0
B37: 1.4.6 | C37: =表1温室气体盘查表!C23 -> 镍铁 | D37: =表1温室气体盘查表!D23 -> 炼钢 | F37: =SUM(G37:M37) -> 367.8984 | G37: =表1温室气体盘查表!AF23 -> 367.8984 | H37: =表1温室气体盘查表!AG23 -> 0 | I37: =表1温室气体盘查表!AH23 -> 0 | J37: =表1温室气体盘查表!AI23 -> 0 | K37: =表1温室气体盘查表!AJ23 -> 0 | L37: =表1温室气体盘查表!AK23 -> 0 | M37: =表1温室气体盘查表!AL23 -> 0
B38: 1.4.7 | C38: =表1温室气体盘查表!C24 -> 高碳铬铁 | D38: =表1温室气体盘查表!D24 -> 炼钢 | F38: =SUM(G38:M38) -> 13992.429 | G38: =表1温室气体盘查表!AF24 -> 13992.429 | H38: =表1温室气体盘查表!AG24 -> 0 | I38: =表1温室气体盘查表!AH24 -> 0 | J38: =表1温室气体盘查表!AI24 -> 0 | K38: =表1温室气体盘查表!AJ24 -> 0 | L38: =表1温室气体盘查表!AK24 -> 0 | M38: =表1温室气体盘查表!AL24 -> 0
B39: 1.4.8 | C39: =表1温室气体盘查表!C25 -> 硅铁 | D39: =表1温室气体盘查表!D25 -> 炼钢 | F39: =SUM(G39:M39) -> 82.65656 | G39: =表1温室气体盘查表!AF25 -> 82.65656 | H39: =表1温室气体盘查表!AG25 -> 0 | I39: =表1温室气体盘查表!AH25 -> 0 | J39: =表1温室气体盘查表!AI25 -> 0 | K39: =表1温室气体盘查表!AJ25 -> 0 | L39: =表1温室气体盘查表!AK25 -> 0 | M39: =表1温室气体盘查表!AL25 -> 0
B40: 1.4.9 | C40: =表1温室气体盘查表!C26 -> 钼铁 | D40: =表1温室气体盘查表!D26 -> 炼钢 | F40: =SUM(G40:M40) -> 130.83696 | G40: =表1温室气体盘查表!AF26 -> 130.83696 | H40: =表1温室气体盘查表!AG26 -> 0 | I40: =表1温室气体盘查表!AH26 -> 0 | J40: =表1温室气体盘查表!AI26 -> 0 | K40: =表1温室气体盘查表!AJ26 -> 0 | L40: =表1温室气体盘查表!AK26 -> 0 | M40: =表1温室气体盘查表!AL26 -> 0
...

Sheet 表1温室气体盘查表
A1: 温室气体盘查表
A2: 编号 | B2: GHG排放类别 | C2: 排放源 | D2: 设施 | E2: 报告边界 | F2: 活动数据 | I2: 排放因子&系数 | AF2: 排放量
I3: CO2 | L3: CH4 | O3: N2O | R3: HFCs | V3: PFCs | Z3: SF6 | AC3: NF3 | AF3: CO2 | AG3: CH4 | AH3: N2O | AI3: HFCs | AJ3: PFCs | AK3: SF6 | AL3: NF3 | AM3: 总量
F4: 数值 | G4: 计量单位 | H4: 数据来源 | I4: EF | J4: 计量单位 | K4: GWP | L4: EF | M4: 计量单位 | N4: GWP | O4: EF | P4: 计量单位 | Q4: GWP | R4: EF | S4: 计量单位 | T4: GWP | U4: 型号 | V4: EF | W4: 计量单位 | X4: GWP | Y4: 型号 | Z4: EF | AA4: 计量单位 | AB4: GWP | AC4: EF | AD4: 计量单位 | AE4: GWP | AF4: tCO2e | AO4: 2024 | AP4: 变化量
A5: 1 | B5: 固定燃烧 | C5: 天然气燃烧 | D5: 热处理炉（加热炉） | E5: 范围一 | F5: =ROUND(1454.003,2) -> 1454 | G5: 10000Nm3 | H5: 《天然气发票》 | I5: =SUMIF('附表2-EF'!$D$5:$D$15,表1温室气体盘查表!C5,'附表2-EF'!$L$5:$L$15) -> 21.621888 | J5: tCO2/10000Nm3 | K5: ='附表1-GWP TABLE'!E3 -> 1 | L5: =SUMIF('附表2-EF'!$D$5:$D$15,表1温室气体盘查表!C5,'附表2-EF'!$M$5:$M$15) -> 0.0003854169 | N5: ='附表1-GWP TABLE'!E4 -> 27.9 | O5: =SUMIF('附表2-EF'!$D$5:$D$15,表1温室气体盘查表!C5,'附表2-EF'!$N$5:$N$15) -> 3.854169e-05 | Q5: ='附表1-GWP TABLE'!E5 -> 273 | AF5: =F5*I5*K5 -> 31438.225 | AG5: =F5*L5*N5 -> 15.635053 | AH5: =F5*O5*Q5 -> 15.298816 | AI5: =F5*R5*T5 -> 0 | AJ5: =F5*V5*X5 -> 0 | AK5: =F5*Z5*AB5 -> 0 | AL5: =F5*AC5*AE5 -> 0 | AM5: =SUM(AF5:AL5) -> 31469.159 | AN5: 天然气燃烧 | AO5: 38881.726 | AP5: =AM5-AO5 -> -7412.5669
A6: 2 | B6: 固定燃烧 | C6: 液化石油气燃烧 | D6: 冶钢宾馆 | E6: 范围一 | F6: =ROUND(9.4345,2) -> 9.43 | G6: t | H6: 《2025全年液化气明细表》 | I6: =SUMIF('附表2-EF'!$D$5:$D$15,表1温室气体盘查表!C6,'附表2-EF'!$L$5:$L$15) -> 3.102969 | J6: tCO2/t | K6: 1 | L6: =SUMIF('附表2-EF'!$D$5:$D$15,表1温室气体盘查表!C6,'附表2-EF'!$M$5:$M$15) -> 4.917542e-05 | N6: ='附表1-GWP TABLE'!E4 -> 27.9 | O6: =SUMIF('附表2-EF'!$D$5:$D$15,表1温室气体盘查表!C6,'附表2-EF'!$N$5:$N$15) -> 4.917542e-06 | Q6: ='附表1-GWP TABLE'!E5 -> 273 | AF6: =F6*I6*K6 -> 29.260998 | AG6: =F6*L6*N6 -> 0.012937905 | AH6: =F6*O6*Q6 -> 0.012659671 | AI6: =F6*R6*T6 -> 0 | AJ6: =F6*V6*X6 -> 0 | AK6: =F6*Z6*AB6 -> 0 | AL6: =F6*AC6*AE6 -> 0 | AM6: =SUM(AF6:AL6) -> 29.286595 | AN6: 液化石油气燃烧 | AO6: 29.162368 | AP6: =AM6-AO6 -> 0.12422734
A7: 3 | B7: 固定燃烧 | C7: 烟煤燃烧 | D7: 高炉 | E7: 范围一 | F7: 323067.87 | G7: t | H7: 《冶钢2025年度碳排放报表》（来源为过磅单） | I7: =SUMIF('附表2-EF'!$D$5:$D$15,表1温室气体盘查表!C7,'附表2-EF'!$L$5:$L$15) -> 2.3099163 | J7: tCO2/t | K7: ='附表1-GWP TABLE'!E3 -> 1 | L7: =SUMIF('附表2-EF'!$D$5:$D$15,表1温室气体盘查表!C7,'附表2-EF'!$M$5:$M$15) -> 2.349864e-05 | N7: ='附表1-GWP TABLE'!E4 -> 27.9 | O7: =SUMIF('附表2-EF'!$D$5:$D$15,表1温室气体盘查表!C7,'附表2-EF'!$N$5:$N$15) -> 3.524796e-05 | Q7: ='附表1-GWP TABLE'!E5 -> 273 | AF7: =F7*I7*K7 -> 746259.74 | AG7: =F7*L7*N7 -> 211.80719 | AH7: =F7*O7*Q7 -> 3108.783 | AI7: =F7*R7*T7 -> 0 | AJ7: =F7*V7*X7 -> 0 | AK7: =F7*Z7*AB7 -> 0 | AL7: =F7*AC7*AE7 -> 0 | AM7: =SUM(AF7:AL7) -> 749580.33 | AN7: 烟煤燃烧 | AO7: 925941.32 | AP7: =AM7-AO7 -> -176360.99
A8: 4 | B8: 固定燃烧 | C8: 无烟煤燃烧 | D8: 高炉、烧结 | E8: 范围一 | F8: 335482.33 | G8: t | H8: 《冶钢2025年度碳排放报表》（来源为过磅单） | I8: =SUMIF('附表2-EF'!$D$5:$D$15,表1温室气体盘查表!C8,'附表2-EF'!$L$5:$L$15) -> 2.4352606 | J8: tCO2/t | K8: ='附表1-GWP TABLE'!E3 -> 1 | L8: =SUMIF('附表2-EF'!$D$5:$D$15,表1温室气体盘查表!C8,'附表2-EF'!$M$5:$M$15) -> 2.477376e-05 | N8: ='附表1-GWP TABLE'!E4 -> 27.9 | O8: =SUMIF('附表2-EF'!$D$5:$D$15,表1温室气体盘查表!C8,'附表2-EF'!$N$5:$N$15) -> 3.716064e-05 | Q8: ='附表1-GWP TABLE'!E5 -> 273 | AF8: =F8*I8*K8 -> 816986.9 | AG8: =F8*L8*N8 -> 231.88133 | AH8: =F8*O8*Q8 -> 3403.4195 | AI8: =F8*R8*T8 -> 0 | AJ8: =F8*V8*X8 -> 0 | AK8: =F8*Z8*AB8 -> 0 | AL8: =F8*AC8*AE8 -> 0 | AM8: =SUM(AF8:AL8) -> 820622.2 | AN8: 无烟煤燃烧 | AO8: 637282.39 | AP8: =AM8-AO8 -> 183339.81
A9: 5 | B9: 固定燃烧 | C9: 洗精煤燃烧 | D9: 焦炉 | E9: 范围一 | F9: 2093622.8 | G9: t | H9: 《冶钢2025年度碳排放报表》（来源为过磅单） | I9: =SUMIF('附表2-EF'!$D$5:$D$15,表1温室气体盘查表!C9,'附表2-EF'!$L$5:$L$15) -> 2.467221 | J9: tCO2/t | K9: ='附表1-GWP TABLE'!E3 -> 1 | L9: =SUMIF('附表2-EF'!$D$5:$D$15,表1温室气体盘查表!C9,'附表2-EF'!$M$5:$M$15) -> 2.608056e-05 | N9: ='附表1-GWP TABLE'!E4 -> 27.9 | O9: =SUMIF('附表2-EF'!$D$5:$D$15,表1温室气体盘查表!C9,'附表2-EF'!$N$5:$N$15) -> 3.912084e-05 | Q9: ='附表1-GWP TABLE'!E5 -> 273 | AF9: =F9*I9*K9 -> 5165430 | AG9: =F9*L9*N9 -> 1523.4196 | AH9: =F9*O9*Q9 -> 22359.869 | AI9: =F9*R9*T9 -> 0 | AJ9: =F9*V9*X9 -> 0 | AK9: =F9*Z9*AB9 -> 0 | AL9: =F9*AC9*AE9 -> 0 | AM9: =SUM(AF9:AL9) -> 5189313.3 | AN9: 洗精煤燃烧 | AO9: 4824841.6 | AP9: =AM9-AO9 -> 364471.73
A10: 6 | B10: 固定燃烧 | C10: 焦炭燃烧 | D10: 高炉 | E10: 范围一 | F10: 221509.17 | G10: t | H10: 《冶钢2025年度碳排放报表》（来源为过磅单） | I10: =SUMIF('附表2-EF'!$D$5:$D$15,表1温室气体盘查表!C10,'附表2-EF'!$L$5:$L$15) -> 3.0121195 | J10: tCO2/t | K10: ='附表1-GWP TABLE'!E3 -> 1 | L10: =SUMIF('附表2-EF'!$D$5:$D$15,表1温室气体盘查表!C10,'附表2-EF'!$M$5:$M$15) -> 2.815065e-05 | N10: ='附表1-GWP TABLE'!E4 -> 27.9 | O10: =SUMIF('附表2-EF'!$D$5:$D$15,表1温室气体盘查表!C10,'附表2-EF'!$N$5:$N$15) -> 4.2225975e-05 | Q10: ='附表1-GWP TABLE'!E5 -> 273 | AF10: =F10*I10*K10 -> 667212.1 | AG10: =F10*L10*N10 -> 173.974 | AH10: =F10*O10*Q10 -> 2553.4893 | AI10: =F10*R10*T10 -> 0 | AJ10: =F10*V10*X10 -> 0 | AK10: =F10*Z10*AB10 -> 0 | AL10: =F10*AC10*AE10 -> 0 | AM10: =SUM(AF10:AL10) -> 669939.56 | AN10: 焦炭燃烧 | AO10: 439843.84 | AP10: =AM10-AO10 -> 230095.72
A11: 7 | B11: 固定燃烧 | C11: 焦炉煤气燃烧 | D11: 外售 | E11: 范围一 | F11: =ROUND(-7887272.44/10000,2) -> -788.73 | G11: 10000Nm3 | H11: 焦炉煤气外供结算单 | I11: =SUMIF('附表2-EF'!$D$5:$D$15,表1温室气体盘查表!C11,'附表2-EF'!$L$5:$L$15) -> 7.6419264 | J11: tCO2/10000Nm3 | K11: 1 | L11: =SUMIF('附表2-EF'!$D$5:$D$15,表1温室气体盘查表!C11,'附表2-EF'!$M$5:$M$15) -> 0.00017211546 | N11: ='附表1-GWP TABLE'!E4 -> 27.9 | O11: =SUMIF('附表2-EF'!$D$5:$D$15,表1温室气体盘查表!C11,'附表2-EF'!$N$5:$N$15) -> 1.7211546e-05 | Q11: ='附表1-GWP TABLE'!E5 -> 273 | AF11: =F11*I11*K11 -> -6027.4166 | AG11: =F11*L11*N11 -> -3.7874983 | AH11: =F11*O11*Q11 -> -3.7060467 | AI11: =F11*R11*T11 -> 0 | AJ11: =F11*V11*X11 -> 0 | AK11: =F11*Z11*AB11 -> 0 | AL11: =F11*AC11*AE11 -> 0 | AM11: =SUM(AF11:AL11) -> -6034.9102 | AN11: 焦炉煤气燃烧 | AO11: -3833.1355 | AP11: =AM11-AO11 -> -2201.7747
A12: 8 | B12: 移动燃烧 | C12: 柴油燃烧 | D12: 场内运输 | E12: 范围一 | F12: =ROUND(1422.693,2) -> 1422.69 | G12: t | H12: 《收发存汇总表-发出量》 | I12: =SUMIF('附表2-EF'!$D$5:$D$15,表1温室气体盘查表!C12,'附表2-EF'!$L$5:$L$15) -> 3.0973029 | J12: tCO2/t | K12: 1 | L12: =SUMIF('附表2-EF'!$D$5:$D$15,表1温室气体盘查表!C12,'附表2-EF'!$M$5:$M$15) -> 0.00016301594 | N12: ='附表1-GWP TABLE'!E4 -> 27.9 | O12: =SUMIF('附表2-EF'!$D$5:$D$15,表1温室气体盘查表!C12,'附表2-EF'!$N$5:$N$15) -> 0.00016301594 | Q12: ='附表1-GWP TABLE'!E5 -> 273 | AF12: =F12*I12*K12 -> 4406.5019 | AG12: =F12*L12*N12 -> 6.4706002 | AH12: =F12*O12*Q12 -> 63.314475 | AI12: =F12*R12*T12 -> 0 | AJ12: =F12*V12*X12 -> 0 | AK12: =F12*Z12*AB12 -> 0 | AL12: =F12*AC12*AE12 -> 0 | AM12: =SUM(AF12:AL12) -> 4476.287 | AN12: 0#柴油燃烧 | AO12: 4417.0726 | AP12: =AM12-AO12 -> 59.21439
A13: 9 | B13: 移动燃烧 | C13: 汽油燃烧 | D13: 公务车 | E13: 范围一 | F13: =ROUND(61085.82*0.775/10^3,2) -> 47.34 | G13: t | H13: 《办公室小车队燃油表》 | I13: =SUMIF('附表2-EF'!$D$5:$D$15,表1温室气体盘查表!C13,'附表2-EF'!$L$5:$L$15) -> 2.925056 | J13: tCO2/t | K13: 1 | L13: =SUMIF('附表2-EF'!$D$5:$D$15,表1温室气体盘查表!C13,'附表2-EF'!$M$5:$M$15) -> 0.001055215 | N13: ='附表1-GWP TABLE'!E4 -> 27.9 | O13: =SUMIF('附表2-EF'!$D$5:$D$15,表1温室气体盘查表!C13,'附表2-EF'!$N$5:$N$15) -> 0.0003376688 | Q13: ='附表1-GWP TABLE'!E5 -> 273 | AF13: =F13*I13*K13 -> 138.47215 | AG13: =F13*L13*N13 -> 1.3937132 | AH13: =F13*O13*Q13 -> 4.3639708 | AI13: =F13*R13*T13 -> 0 | AJ13: =F13*V13*X13 -> 0 | AK13: =F13*Z13*AB13 -> 0 | AL13: =F13*AC13*AE13 -> 0 | AM13: =SUM(AF13:AL13) -> 144.22983 | AN13: 92#汽油燃烧 | AO13: 149.47012 | AP13: =AM13-AO13 -> -5.2402897
A14: 10 | B14: 逸散排放 | C14: 制冷剂逸散（R32） | D14: 分体式空调 | E14: 范围一 | F14: =ROUND(1471.6233/1000/2,2) -> 0.74 | G14: t | H14: 《空调加氟汇总表》 | R14: 1 | S14: tHFCs/t | T14: ='附表1-GWP TABLE'!F8 -> 771 | U14: HFC-32 | AF14: =F14*I14*K14 -> 0 | AG14: =F14*L14*N14 -> 0 | AH14: =F14*O14*Q14 -> 0 | AI14: =F14*R14*T14 -> 570.54 | AJ14: =F14*V14*X14 -> 0 | AK14: =F14*Z14*AB14 -> 0 | AL14: =F14*AC14*AE14 -> 0 | AM14: =SUM(AF14:AL14) -> 570.54 | AN14: 制冷剂逸散（R32） | AO14: 717.03 | AP14: =AM14-AO14 -> -146.49
A15: 11 | B15: 逸散排放 | C15: CO2逸散 | D15: 二氧化碳灭火器 | E15: 范围一 | F15: =ROUND(564/1000,2) -> 0.56 | G15: t | H15: 《收发存汇总表》 | I15: ='附表2-EF'!F37 -> 1 | J15: tCO2/t | K15: 1 | AF15: =F15*I15*K15 -> 0.56 | AG15: =F15*L15*N15 -> 0 | AH15: =F15*O15*Q15 -> 0 | AI15: =F15*R15*T15 -> 0 | AJ15: =F15*V15*X15 -> 0 | AK15: =F15*Z15*AB15 -> 0 | AL15: =F15*AC15*AE15 -> 0 | AM15: =SUM(AF15:AL15) -> 0.56 | AN15: CO2逸散 | AO15: 0.66 | AP15: =AM15-AO15 -> -0.1
A16: 12 | B16: 逸散排放 | C16: CH4逸散 | D16: 化粪池 | E16: 范围一 | F16: =ROUND(7003*'附表2-EF'!J41*248/10^6*8/24,2) -> 23.16 | G16: tBOD | H16: 《人数统计表》 | L16: ='附表2-EF'!J39 -> 0.18 | M16: tCH4/tBOD | N16: ='附表1-GWP TABLE'!E4 -> 27.9 | AF16: =F16*I16*K16 -> 0 | AG16: =F16*L16*N16 -> 116.30952 | AH16: =F16*O16*Q16 -> 0 | AI16: =F16*R16*T16 -> 0 | AJ16: =F16*V16*X16 -> 0 | AK16: =F16*Z16*AB16 -> 0 | AL16: =F16*AC16*AE16 -> 0 | AM16: =SUM(AF16:AL16) -> 116.30952 | AN16: CH4逸散 | AO16: 112.29192 | AP16: =AM16-AO16 -> 4.0176
A17: 13 | B17: 逸散排放 | C17: CH4逸散 | D17: 耗氧池 | E17: 范围一 | F17: =ROUND((18.93-8.7)/10^6*2439525+(56.46-5.51)/10^6*9968019+(4234-45.99)/10^6*832316,2) -> 4018.57 | G17: tCOD | H17: 《2025年工业废水处置》 | L17: ='附表2-EF'!J40 -> 0.075 | M17: tCH4/tCOD | N17: ='附表1-GWP TABLE'!E4 -> 27.9 | AF17: =F17*I17*K17 -> 0 | AG17: =F17*L17*N17 -> 8408.8577 | AH17: =F17*O17*Q17 -> 0 | AI17: =F17*R17*T17 -> 0 | AJ17: =F17*V17*X17 -> 0 | AK17: =F17*Z17*AB17 -> 0 | AL17: =F17*AC17*AE17 -> 0 | AM17: =SUM(AF17:AL17) -> 8408.8577 | AN17: CH4逸散 | AO17: 365.58067 | AP17: =AM17-AO17 -> 8043.277
A18: 14 | B18: 制程排放 | C18: 白云石 | D18: 高炉 | E18: 范围一 | F18: =ROUND(38669.446,2) -> 38669.45 | G18: t | H18: 《2025年统计月报（转炉）》 | I18: =SUMIF('附表2-EF'!$D$19:$D$32,表1温室气体盘查表!C18,'附表2-EF'!$F$19:$F$32) -> 0.476 | J18: tCO2/t | K18: 1 | AF18: =F18*I18*K18 -> 18406.658 | AG18: =F18*L18*N18 -> 0 | AH18: =F18*O18*Q18 -> 0 | AI18: =F18*R18*T18 -> 0 | AJ18: =F18*V18*X18 -> 0 | AK18: =F18*Z18*AB18 -> 0 | AL18: =F18*AC18*AE18 -> 0 | AM18: =SUM(AF18:AL18) -> 18406.658 | AN18: 白云石 | AO18: 169593.75 | AP18: =AM18-AO18 -> -151187.09
A19: 15 | B19: 制程排放 | C19: 电极 | D19: 炼钢 | E19: 范围一 | F19: =ROUND(2292.859+709.398+2003.195,2) -> 5005.45 | G19: t | H19: 《2025年统计月报（转炉）》《2025年50t电炉台账》《2025年大电炉台账》 | I19: =SUMIF('附表2-EF'!$D$19:$D$32,表1温室气体盘查表!C19,'附表2-EF'!$F$19:$F$32) -> 3.663 | J19: tCO2/t | K19: 1 | AF19: =F19*I19*K19 -> 18334.963 | AG19: =F19*L19*N19 -> 0 | AH19: =F19*O19*Q19 -> 0 | AI19: =F19*R19*T19 -> 0 | AJ19: =F19*V19*X19 -> 0 | AK19: =F19*Z19*AB19 -> 0 | AL19: =F19*AC19*AE19 -> 0 | AM19: =SUM(AF19:AL19) -> 18334.963 | AN19: 电极 | AO19: 17447.125 | AP19: =AM19-AO19 -> 887.83794
A20: 16 | B20: 制程排放 | C20: 废钢 | D20: 炼钢 | E20: 范围一 | F20: =ROUND(462441.162+136808.562+520365.934,2) -> 1119615.7 | G20: t | H20: 《2025年统计月报（转炉）》《2025年50t电炉台账》《2025年大电炉台账》 | I20: =SUMIF('附表2-EF'!$D$19:$D$32,表1温室气体盘查表!C20,'附表2-EF'!$F$19:$F$32) -> 0.037 | J20: tCO2/t | K20: 1 | AF20: =F20*I20*K20 -> 41425.779 | AG20: =F20*L20*N20 -> 0 | AH20: =F20*O20*Q20 -> 0 | AI20: =F20*R20*T20 -> 0 | AJ20: =F20*V20*X20 -> 0 | AK20: =F20*Z20*AB20 -> 0 | AL20: =F20*AC20*AE20 -> 0 | AM20: =SUM(AF20:AL20) -> 41425.779 | AN20: 废钢 | AO20: 39875.738 | AP20: =AM20-AO20 -> 1550.0416
A21: 17 | B21: 制程排放 | C21: 高碳锰铁 | D21: 炼钢 | E21: 范围一 | F21: =ROUND(33390.439+851.616+7241.11,2) -> 41483.17 | G21: t | H21: 《2025年统计月报（转炉）》《50t电炉原材料 消耗汇总表》《70t电炉原材料 消耗汇总表》 | I21: =SUMIF('附表2-EF'!$D$19:$D$32,表1温室气体盘查表!C21,'附表2-EF'!$F$19:$F$32) -> 0.275 | J21: tCO2/t | K21: 1 | AF21: =F21*I21*K21 -> 11407.872 | AG21: =F21*L21*N21 -> 0 | AH21: =F21*O21*Q21 -> 0 | AI21: =F21*R21*T21 -> 0 | AJ21: =F21*V21*X21 -> 0 | AK21: =F21*Z21*AB21 -> 0 | AL21: =F21*AC21*AE21 -> 0 | AM21: =SUM(AF21:AL21) -> 11407.872 | AN21: 锰铁 | AO21: 13114.101 | AP21: =AM21-AO21 -> -1706.2293
A22: 18 | B22: 制程排放 | C22: 锰硅合金 | D22: 炼钢 | E22: 范围一 | F22: =ROUND(0+189.062+2698.627,2) -> 2887.69 | G22: t | H22: 《50t电炉原材料 消耗汇总表》《70t电炉原材料 消耗汇总表》 | I22: =SUMIF('附表2-EF'!$D$19:$D$32,表1温室气体盘查表!C22,'附表2-EF'!$F$19:$F$32) -> 0.092 | J22: tCO2/t | K22: 1 | AF22: =F22*I22*K22 -> 265.66748 | AG22: =F22*L22*N22 -> 0 | AH22: =F22*O22*Q22 -> 0 | AI22: =F22*R22*T22 -> 0 | AJ22: =F22*V22*X22 -> 0 | AK22: =F22*Z22*AB22 -> 0 | AL22: =F22*AC22*AE22 -> 0 | AM22: =SUM(AF22:AL22) -> 265.66748 | AN22: 锰铁 | AO22: 13114.101 | AP22: =AM22-AO22 -> -12848.434
A23: 19 | B23: 制程排放 | C23: 镍铁 | D23: 炼钢 | E23: 范围一 | F23: =ROUND(7856.706+367.47+1719.027,2) -> 9943.2 | G23: t | H23: 《2025年统计月报（转炉）》《50t电炉原材料 消耗汇总表》《70t电炉原材料 消耗汇总表》 | I23: =SUMIF('附表2-EF'!$D$19:$D$32,表1温室气体盘查表!C23,'附表2-EF'!$F$19:$F$32) -> 0.037 | J23: tCO2/t | K23: 1 | AF23: =F23*I23*K23 -> 367.8984 | AG23: =F23*L23*N23 -> 0 | AH23: =F23*O23*Q23 -> 0 | AI23: =F23*R23*T23 -> 0 | AJ23: =F23*V23*X23 -> 0 | AK23: =F23*Z23*AB23 -> 0 | AL23: =F23*AC23*AE23 -> 0 | AM23: =SUM(AF23:AL23) -> 367.8984 | AN23: 镍铁 | AO23: 349.46907 | AP23: =AM23-AO23 -> 18.42933
A24: 20 | B24: 制程排放 | C24: 高碳铬铁 | D24: 炼钢 | E24: 范围一 | F24: =ROUND(30491.606+3776.482+5940.04,2) -> 40208.13 | G24: t | H24: 《2025年统计月报（转炉）》《50t电炉原材料 消耗汇总表》《70t电炉原材料 消耗汇总表》 | I24: =SUMIF('附表2-EF'!$D$19:$D$32,表1温室气体盘查表!C24,'附表2-EF'!$F$19:$F$32) -> 0.348 | J24: tCO2/t | K24: 1 | AF24: =F24*I24*K24 -> 13992.429 | AG24: =F24*L24*N24 -> 0 | AH24: =F24*O24*Q24 -> 0 | AI24: =F24*R24*T24 -> 0 | AJ24: =F24*V24*X24 -> 0 | AK24: =F24*Z24*AB24 -> 0 | AL24: =F24*AC24*AE24 -> 0 | AM24: =SUM(AF24:AL24) -> 13992.429 | AN24: 铬铁 | AO24: 22918.907 | AP24: =AM24-AO24 -> -8926.4781
A25: 21 | B25: 制程排放 | C25: 硅铁 | D25: 炼钢 | E25: 范围一 | F25: =ROUND(7938.683+997.832+2871.568,2) -> 11808.08 | G25: t | H25: 《2025年统计月报（转炉）》《50t电炉原材料 消耗汇总表》《70t电炉原材料 消耗汇总表》 | I25: =SUMIF('附表2-EF'!$D$19:$D$32,表1温室气体盘查表!C25,'附表2-EF'!$F$19:$F$32) -> 0.007 | J25: tCO2/t | K25: 1 | AF25: =F25*I25*K25 -> 82.65656 | AG25: =F25*L25*N25 -> 0 | AH25: =F25*O25*Q25 -> 0 | AI25: =F25*R25*T25 -> 0 | AJ25: =F25*V25*X25 -> 0 | AK25: =F25*Z25*AB25 -> 0 | AL25: =F25*AC25*AE25 -> 0 | AM25: =SUM(AF25:AL25) -> 82.65656 | AN25: 硅铁 | AO25: 74.70736 | AP25: =AM25-AO25 -> 7.9492
A26: 22 | B26: 制程排放 | C26: 钼铁 | D26: 炼钢 | E26: 范围一 | F26: =ROUND(3621.161+1134.107+2513.451,2) -> 7268.72 | G26: t | H26: 《2025年统计月报（转炉）》《50t电炉原材料 消耗汇总表》《70t电炉原材料 消耗汇总表》 | I26: =SUMIF('附表2-EF'!$D$19:$D$32,表1温室气体盘查表!C26,'附表2-EF'!$F$19:$F$32) -> 0.018 | J26: tCO2/t | K26: 1 | AF26: =F26*I26*K26 -> 130.83696 | AG26: =F26*L26*N26 -> 0 | AH26: =F26*O26*Q26 -> 0 | AI26: =F26*R26*T26 -> 0 | AJ26: =F26*V26*X26 -> 0 | AK26: =F26*Z26*AB26 -> 0 | AL26: =F26*AC26*AE26 -> 0 | AM26: =SUM(AF26:AL26) -> 130.83696 | AN26: 钼铁 | AO26: 143.01295 | AP26: =AM26-AO26 -> -12.175992
A27: 23 | B27: 制程排放 | C27: 粗钢 | D27: 固碳产品 | E27: 范围一 | F27: =-ROUND(3107726.623+1201742.787+175073.244,2) -> -4484542.7 | G27: t | H27: 《2025年统计月报（转炉厂）》《70t电炉台账》《50t电炉台账》 | I27: =SUMIF('附表2-EF'!$D$19:$D$32,表1温室气体盘查表!C27,'附表2-EF'!$F$19:$F$32) -> 0.037 | J27: tCO2/t | K27: 1 | AF27: =F27*I27*K27 -> -165928.08 | AG27: =F27*L27*N27 -> 0 | AH27: =F27*O27*Q27 -> 0 | AI27: =F27*R27*T27 -> 0 | AJ27: =F27*V27*X27 -> 0 | AK27: =F27*Z27*AB27 -> 0 | AL27: =F27*AC27*AE27 -> 0 | AM27: =SUM(AF27:AL27) -> -165928.08 | AN27: 钢坯 | AO27: -160314.41 | AP27: =AM27-AO27 -> -5613.6663
A28: 24 | B28: 制程排放 | C28: 粗苯 | D28: 外售 | E28: 范围一 | F28: =-ROUND(20393.52,2) -> -20393.52 | G28: t | H28: 《附表3：冶钢2025PCF补充数据表》 | I28: =SUMIF('附表2-EF'!$D$19:$D$32,表1温室气体盘查表!C28,'附表2-EF'!$F$19:$F$32) -> 3.382 | J28: tCO2/t | K28: 1 | AF28: =F28*I28*K28 -> -68970.885 | AG28: =F28*L28*N28 -> 0 | AH28: =F28*O28*Q28 -> 0 | AI28: =F28*R28*T28 -> 0 | AJ28: =F28*V28*X28 -> 0 | AK28: =F28*Z28*AB28 -> 0 | AL28: =F28*AC28*AE28 -> 0 | AM28: =SUM(AF28:AL28) -> -68970.885 | AN28: 粗苯 | AO28: -65952.991 | AP28: =AM28-AO28 -> -3017.8939
A29: 25 | B29: 制程排放 | C29: 焦油 | D29: 危废处置 | E29: 范围一 | F29: =-ROUND(60565.6,2) -> -60565.6 | G29: t | H29: 《汽车衡结净计量实绩_焦油2025年度》 | I29: =SUMIF('附表2-EF'!$D$19:$D$32,表1温室气体盘查表!C29,'附表2-EF'!$F$19:$F$32) -> 2.699 | J29: tCO2/t | K29: 1 | AF29: =F29*I29*K29 -> -163466.55 | AG29: =F29*L29*N29 -> 0 | AH29: =F29*O29*Q29 -> 0 | AI29: =F29*R29*T29 -> 0 | AJ29: =F29*V29*X29 -> 0 | AK29: =F29*Z29*AB29 -> 0 | AL29: =F29*AC29*AE29 -> 0 | AM29: =SUM(AF29:AL29) -> -163466.55 | AN29: 煤焦油 | AO29: -159387.02 | AP29: =AM29-AO29 -> -4079.5385
A30: 26 | B30: 输入能源间接温室气体排放 | C30: 外购电力（基于位置） | D30: 用电设备 | E30: 范围二 | F30: =ROUND(1966850.825,2) -> 1966850.8 | G30: MWh | H30: 《电费发票》 | I30: ='附表2-EF'!F44 -> 0.5306 | J30: tCO2/MWh | K30: 1 | AF30: =F30*I30*K30 -> 1043611.1 | AG30: =F30*L30*N30 -> 0 | AH30: =F30*O30*Q30 -> 0 | AI30: =F30*R30*T30 -> 0 | AJ30: =F30*V30*X30 -> 0 | AK30: =F30*Z30*AB30 -> 0 | AL30: =F30*AC30*AE30 -> 0 | AM30: =SUM(AF30:AL30) -> 1043611.1 | AN30: 外购电力（基于位置）
A31: 27 | B31: 输入能源间接温室气体排放 | C31: 外购电力（基于市场） | D31: 用电设备 | E31: 范围二 | F31: =ROUND(1946850.825,2) -> 1946850.8 | G31: MWh | H31: 《电费发票》《绿证》 | I31: ='附表2-EF'!F45 -> 0.6096 | J31: tCO2/MWh | K31: 1 | AF31: =F31*I31*K31 -> 1186800.3 | AG31: =F31*L31*N31 -> 0 | AH31: =F31*O31*Q31 -> 0 | AI31: =F31*R31*T31 -> 0 | AJ31: =F31*V31*X31 -> 0 | AK31: =F31*Z31*AB31 -> 0 | AL31: =F31*AC31*AE31 -> 0 | AM31: =SUM(AF31:AL31) -> 1186800.3 | AN31: 外购电力（基于市场）
A32: 28 | B32: 外购商品和服务的上游排放 | C32: 铁矿石生产 | D32: 烧结 | E32: 范围三 类别1 | F32: =ROUND(816374.146+4037949.92633333,2) -> 4854324.1 | G32: t | H32: 《2025年统计月报（烧结）》《2025年统计报表（中高炉）》 | I32: =SUMIF('附表2-EF'!$D$49:$D$72,表1温室气体盘查表!C32,'附表2-EF'!$G$49:$G$72) -> 0.098847 | J32: tCO2/t | K32: 1 | AF32: =F32*I32*K32 -> 479835.37 | AG32: =F32*L32*N32 -> 0 | AH32: =F32*O32*Q32 -> 0 | AI32: =F32*R32*T32 -> 0 | AJ32: =F32*V32*X32 -> 0 | AK32: =F32*Z32*AB32 -> 0 | AL32: =F32*AC32*AE32 -> 0 | AM32: =SUM(AF32:AL32) -> 479835.37 | AN32: 铁矿石生产 | AO32: 448588.58 | AP32: =AM32-AO32 -> 31246.795
A33: 29 | B33: 外购商品和服务的上游排放 | C33: 生石灰生产 | D33: 烧结、转炉、电炉 | E33: 范围三 类别1 | F33: =ROUND(127889.871+11121.076+60171.413,2) -> 199182.36 | G33: t | H33: 《2025年统计月报（转炉）》《2025年50t电炉台账》《2025年大电炉台账》 | I33: =SUMIF('附表2-EF'!$D$49:$D$72,表1温室气体盘查表!C33,'附表2-EF'!$G$49:$G$72) -> 1.1896699 | J33: tCO2/t | K33: 1 | AF33: =F33*I33*K33 -> 236961.26 | AG33: =F33*L33*N33 -> 0 | AH33: =F33*O33*Q33 -> 0 | AI33: =F33*R33*T33 -> 0 | AJ33: =F33*V33*X33 -> 0 | AK33: =F33*Z33*AB33 -> 0 | AL33: =F33*AC33*AE33 -> 0 | AM33: =SUM(AF33:AL33) -> 236961.26 | AN33: 生石灰生产 | AO33: 727500.38 | AP33: =AM33-AO33 -> -490539.12
A34: 30 | B34: 外购商品和服务的上游排放 | C34: 白云石生产 | D34: 烧结、转炉、电炉 | E34: 范围三 类别1 | F34: =ROUND(38669.446,2) -> 38669.45 | G34: t | H34: 《2025年统计月报（转炉）》 | I34: =SUMIF('附表2-EF'!$D$49:$D$72,表1温室气体盘查表!C34,'附表2-EF'!$G$49:$G$72) -> 0.13033 | J34: tCO2/t | K34: 1 | AF34: =F34*I34*K34 -> 5039.7894 | AG34: =F34*L34*N34 -> 0 | AH34: =F34*O34*Q34 -> 0 | AI34: =F34*R34*T34 -> 0 | AJ34: =F34*V34*X34 -> 0 | AK34: =F34*Z34*AB34 -> 0 | AL34: =F34*AC34*AE34 -> 0 | AM34: =SUM(AF34:AL34) -> 5039.7894 | AN34: 白云石生产 | AO34: 46435.196 | AP34: =AM34-AO34 -> -41395.407
A35: 31 | B35: 外购商品和服务的上游排放 | C35: 球团生产 | D35: 高炉、转炉 | E35: 范围三 类别1 | F35: =ROUND(679912.97+2080.92,2) -> 681993.89 | G35: t | H35: 《2025年统计报表（中高炉）》《2025年统计月报（转炉）》 | I35: =SUMIF('附表2-EF'!$D$49:$D$72,表1温室气体盘查表!C35,'附表2-EF'!$G$49:$G$72) -> 0.10446 | J35: tCO2/t | K35: 1 | AF35: =F35*I35*K35 -> 71241.082 | AG35: =F35*L35*N35 -> 0 | AH35: =F35*O35*Q35 -> 0 | AI35: =F35*R35*T35 -> 0 | AJ35: =F35*V35*X35 -> 0 | AK35: =F35*Z35*AB35 -> 0 | AL35: =F35*AC35*AE35 -> 0 | AM35: =SUM(AF35:AL35) -> 71241.082 | AN35: 球团生产 | AO35: 71601.051 | AP35: =AM35-AO35 -> -359.96916
A36: 32 | B36: 外购商品和服务的上游排放 | C36: 废钢生产 | D36: 转炉、电炉 | E36: 范围三 类别1 | F36: =F20 -> 1119615.7 | G36: t | H36: 《2025年统计月报（转炉）》《2025年50t电炉台账》《2025年大电炉台账》 | I36: =SUMIF('附表2-EF'!$D$49:$D$72,表1温室气体盘查表!C36,'附表2-EF'!$G$49:$G$72) -> 0.074179 | J36: tCO2/t | K36: 1 | AF36: =F36*I36*K36 -> 83051.97 | AG36: =F36*L36*N36 -> 0 | AH36: =F36*O36*Q36 -> 0 | AI36: =F36*R36*T36 -> 0 | AJ36: =F36*V36*X36 -> 0 | AK36: =F36*Z36*AB36 -> 0 | AL36: =F36*AC36*AE36 -> 0 | AM36: =SUM(AF36:AL36) -> 83051.97 | AN36: 废钢生产 | AO36: 79944.388 | AP36: =AM36-AO36 -> 3107.5821
A37: 33 | B37: 外购商品和服务的上游排放 | C37: 电极生产 | D37: 转炉、电炉 | E37: 范围三 类别1 | F37: =ROUND(2292.859+709.398+2003.195,2) -> 5005.45 | G37: t | H37: 《2025年统计月报（转炉）》《2025年50t电炉台账》《2025年大电炉台账》 | I37: =SUMIF('附表2-EF'!$D$49:$D$72,表1温室气体盘查表!C37,'附表2-EF'!$G$49:$G$72) -> 12.17913 | J37: tCO2/t | K37: 1 | AF37: =F37*I37*K37 -> 60962.024 | AG37: =F37*L37*N37 -> 0 | AH37: =F37*O37*Q37 -> 0 | AI37: =F37*R37*T37 -> 0 | AJ37: =F37*V37*X37 -> 0 | AK37: =F37*Z37*AB37 -> 0 | AL37: =F37*AC37*AE37 -> 0 | AM37: =SUM(AF37:AL37) -> 60962.024 | AN37: 电极生产 | AO37: 37742.812 | AP37: =AM37-AO37 -> 23219.212
A38: 34 | B38: 外购商品和服务的上游排放 | C38: 锰铁生产 | D38: 转炉、电炉 | E38: 范围三 类别1 | F38: =F21 -> 41483.17 | G38: t | H38: 《2025年统计月报（转炉）》《50t电炉原材料 消耗汇总表》《70t电炉原材料 消耗汇总表》 | I38: =SUMIF('附表2-EF'!$D$49:$D$72,表1温室气体盘查表!C38,'附表2-EF'!$G$49:$G$72) -> 2.9772 | J38: tCO2/t | K38: 1 | AF38: =F38*I38*K38 -> 123503.69 | AG38: =F38*L38*N38 -> 0 | AH38: =F38*O38*Q38 -> 0 | AI38: =F38*R38*T38 -> 0 | AJ38: =F38*V38*X38 -> 0 | AK38: =F38*Z38*AB38 -> 0 | AL38: =F38*AC38*AE38 -> 0 | AM38: =SUM(AF38:AL38) -> 123503.69 | AN38: 锰铁生产 | AO38: 141868.58 | AP38: =AM38-AO38 -> -18364.888
A39: 35 | B39: 外购商品和服务的上游排放 | C39: 镍铁生产 | D39: 转炉、电炉 | E39: 范围三 类别1 | F39: =F23 -> 9943.2 | G39: t | H39: 《2025年统计月报（转炉）》《50t电炉原材料 消耗汇总表》《70t电炉原材料 消耗汇总表》 | I39: =SUMIF('附表2-EF'!$D$49:$D$72,表1温室气体盘查表!C39,'附表2-EF'!$G$49:$G$72) -> 8.7547 | J39: tCO2/t | K39: 1 | AF39: =F39*I39*K39 -> 87049.733 | AG39: =F39*L39*N39 -> 0 | AH39: =F39*O39*Q39 -> 0 | AI39: =F39*R39*T39 -> 0 | AJ39: =F39*V39*X39 -> 0 | AK39: =F39*Z39*AB39 -> 0 | AL39: =F39*AC39*AE39 -> 0 | AM39: =SUM(AF39:AL39) -> 87049.733 | AN39: 镍铁生产 | AO39: 84819.123 | AP39: =AM39-AO39 -> 2230.61
A40: 36 | B40: 外购商品和服务的上游排放 | C40: 铬铁生产 | D40: 转炉、电炉 | E40: 范围三 类别1 | F40: =F24 -> 40208.13 | G40: t | H40: 《2025年统计月报（转炉）》《50t电炉原材料 消耗汇总表》《70t电炉原材料 消耗汇总表》 | I40: =SUMIF('附表2-EF'!$D$49:$D$72,表1温室气体盘查表!C40,'附表2-EF'!$G$49:$G$72) -> 5.0921 | J40: tCO2/t | K40: 1 | AF40: =F40*I40*K40 -> 204743.82 | AG40: =F40*L40*N40 -> 0 | AH40: =F40*O40*Q40 -> 0 | AI40: =F40*R40*T40 -> 0 | AJ40: =F40*V40*X40 -> 0 | AK40: =F40*Z40*AB40 -> 0 | AL40: =F40*AC40*AE40 -> 0 | AM40: =SUM(AF40:AL40) -> 204743.82 | AN40: 铬铁生产 | AO40: 345101.44 | AP40: =AM40-AO40 -> -140357.63
...

Sheet 表2.1不确定性评估——基于位置
A1: 不确定性评估表
A2: 编号 | B2: 排放源 | C2: 设施 | D2: 活动数据类别 | E2: 排放因子类别 | F2: 校准频率 | G2: 活动数据级别 | H2: 排放因子级别 | I2: 校准级别 | J2: 平均得分 | K2: 排放量(tCO2e) | L2: 排放量占比 | M2: 加权平均积分
A3: 1 | B3: =表1温室气体盘查表!C5 -> 天然气燃烧 | C3: =表1温室气体盘查表!D5 -> 热处理炉（加热炉） | D3: 自动连续量测 | E3: 国际排放因子 | F3: 校准且合格 | G3: =IF(D3="自动连续量测",6,IF(D3="定期量测/抄表/铭牌",3,1)) -> 6 | H3: =IF(E3="量测/质量平衡排放因子",6,IF(E3="制程/设备排放因子",5,IF(E3="制造商提供的排放因子",4,IF(E3="区域排放因子",3,IF(E3="国家排放因子",2,1))))) -> 1 | I3: =IF(F3="校准且合格",6,IF(F3="未校准",1,3)) -> 6 | J3: =AVERAGE(G3:I3) -> 4.3333333 | K3: =表1温室气体盘查表!AM5 -> 31469.159 | L3: =K3/$K$96 -> 0.0020460845 | M3: =J3*L3 -> 0.0088663662
A4: 2 | B4: =表1温室气体盘查表!C6 -> 液化石油气燃烧 | C4: =表1温室气体盘查表!D6 -> 冶钢宾馆 | D4: 定期量测/抄表/铭牌 | E4: 国际排放因子 | F4: 校准且合格 | G4: =IF(D4="自动连续量测",6,IF(D4="定期量测/抄表/铭牌",3,1)) -> 3 | H4: =IF(E4="量测/质量平衡排放因子",6,IF(E4="制程/设备排放因子",5,IF(E4="制造商提供的排放因子",4,IF(E4="区域排放因子",3,IF(E4="国家排放因子",2,1))))) -> 1 | I4: =IF(F4="校准且合格",6,IF(F4="未校准",1,3)) -> 6 | J4: =AVERAGE(G4:I4) -> 3.3333333 | K4: =表1温室气体盘查表!AM6 -> 29.286595 | L4: =K4/$K$96 -> 1.904177e-06 | M4: =J4*L4 -> 6.3472566e-06
A5: 3 | B5: =表1温室气体盘查表!C7 -> 烟煤燃烧 | C5: =表1温室气体盘查表!D7 -> 高炉 | D5: 自动连续量测 | E5: 国际排放因子 | F5: 校准且合格 | G5: =IF(D5="自动连续量测",6,IF(D5="定期量测/抄表/铭牌",3,1)) -> 6 | H5: =IF(E5="量测/质量平衡排放因子",6,IF(E5="制程/设备排放因子",5,IF(E5="制造商提供的排放因子",4,IF(E5="区域排放因子",3,IF(E5="国家排放因子",2,1))))) -> 1 | I5: =IF(F5="校准且合格",6,IF(F5="未校准",1,3)) -> 6 | J5: =AVERAGE(G5:I5) -> 4.3333333 | K5: =表1温室气体盘查表!AM7 -> 749580.33 | L5: =K5/$K$96 -> 0.048736755 | M5: =J5*L5 -> 0.21119261
A6: 4 | B6: =表1温室气体盘查表!C8 -> 无烟煤燃烧 | C6: =表1温室气体盘查表!D8 -> 高炉、烧结 | D6: 自动连续量测 | E6: 国际排放因子 | F6: 校准且合格 | G6: =IF(D6="自动连续量测",6,IF(D6="定期量测/抄表/铭牌",3,1)) -> 6 | H6: =IF(E6="量测/质量平衡排放因子",6,IF(E6="制程/设备排放因子",5,IF(E6="制造商提供的排放因子",4,IF(E6="区域排放因子",3,IF(E6="国家排放因子",2,1))))) -> 1 | I6: =IF(F6="校准且合格",6,IF(F6="未校准",1,3)) -> 6 | J6: =AVERAGE(G6:I6) -> 4.3333333 | K6: =表1温室气体盘查表!AM8 -> 820622.2 | L6: =K6/$K$96 -> 0.053355807 | M6: =J6*L6 -> 0.2312085
A7: 5 | B7: =表1温室气体盘查表!C9 -> 洗精煤燃烧 | C7: =表1温室气体盘查表!D9 -> 焦炉 | D7: 自动连续量测 | E7: 国际排放因子 | F7: 校准且合格 | G7: =IF(D7="自动连续量测",6,IF(D7="定期量测/抄表/铭牌",3,1)) -> 6 | H7: =IF(E7="量测/质量平衡排放因子",6,IF(E7="制程/设备排放因子",5,IF(E7="制造商提供的排放因子",4,IF(E7="区域排放因子",3,IF(E7="国家排放因子",2,1))))) -> 1 | I7: =IF(F7="校准且合格",6,IF(F7="未校准",1,3)) -> 6 | J7: =AVERAGE(G7:I7) -> 4.3333333 | K7: =表1温室气体盘查表!AM9 -> 5189313.3 | L7: =K7/$K$96 -> 0.33740252 | M7: =J7*L7 -> 1.4620776
A8: 6 | B8: =表1温室气体盘查表!C10 -> 焦炭燃烧 | C8: =表1温室气体盘查表!D10 -> 高炉 | D8: 自动连续量测 | E8: 国际排放因子 | F8: 校准且合格 | G8: =IF(D8="自动连续量测",6,IF(D8="定期量测/抄表/铭牌",3,1)) -> 6 | H8: =IF(E8="量测/质量平衡排放因子",6,IF(E8="制程/设备排放因子",5,IF(E8="制造商提供的排放因子",4,IF(E8="区域排放因子",3,IF(E8="国家排放因子",2,1))))) -> 1 | I8: =IF(F8="校准且合格",6,IF(F8="未校准",1,3)) -> 6 | J8: =AVERAGE(G8:I8) -> 4.3333333 | K8: =表1温室气体盘查表!AM10 -> 669939.56 | L8: =K8/$K$96 -> 0.043558614 | M8: =J8*L8 -> 0.18875399
A9: 7 | B9: =表1温室气体盘查表!C11 -> 焦炉煤气燃烧 | C9: =表1温室气体盘查表!D11 -> 外售 | D9: 自动连续量测 | E9: 国际排放因子 | F9: 校准且合格 | G9: =IF(D9="自动连续量测",6,IF(D9="定期量测/抄表/铭牌",3,1)) -> 6 | H9: =IF(E9="量测/质量平衡排放因子",6,IF(E9="制程/设备排放因子",5,IF(E9="制造商提供的排放因子",4,IF(E9="区域排放因子",3,IF(E9="国家排放因子",2,1))))) -> 1 | I9: =IF(F9="校准且合格",6,IF(F9="未校准",1,3)) -> 6 | J9: =AVERAGE(G9:I9) -> 4.3333333 | K9: =表1温室气体盘查表!AM11 -> -6034.9102 | L9: =K9/$K$96 -> -0.00039238215 | M9: =J9*L9 -> -0.0017003226
A10: 8 | B10: =表1温室气体盘查表!C12 -> 柴油燃烧 | C10: =表1温室气体盘查表!D12 -> 场内运输 | D10: 定期量测/抄表/铭牌 | E10: 国际排放因子 | F10: 校准但不合格/未校准但数据可查证 | G10: =IF(D10="自动连续量测",6,IF(D10="定期量测/抄表/铭牌",3,1)) -> 3 | H10: =IF(E10="量测/质量平衡排放因子",6,IF(E10="制程/设备排放因子",5,IF(E10="制造商提供的排放因子",4,IF(E10="区域排放因子",3,IF(E10="国家排放因子",2,1))))) -> 1 | I10: =IF(F10="校准且合格",6,IF(F10="未校准",1,3)) -> 3 | J10: =AVERAGE(G10:I10) -> 2.3333333 | K10: =表1温室气体盘查表!AM12 -> 4476.287 | L10: =K10/$K$96 -> 0.00029104246 | M10: =J10*L10 -> 0.00067909907
A11: 9 | B11: =表1温室气体盘查表!C13 -> 汽油燃烧 | C11: =表1温室气体盘查表!D13 -> 公务车 | D11: 定期量测/抄表/铭牌 | E11: 国际排放因子 | F11: 校准但不合格/未校准但数据可查证 | G11: =IF(D11="自动连续量测",6,IF(D11="定期量测/抄表/铭牌",3,1)) -> 3 | H11: =IF(E11="量测/质量平衡排放因子",6,IF(E11="制程/设备排放因子",5,IF(E11="制造商提供的排放因子",4,IF(E11="区域排放因子",3,IF(E11="国家排放因子",2,1))))) -> 1 | I11: =IF(F11="校准且合格",6,IF(F11="未校准",1,3)) -> 3 | J11: =AVERAGE(G11:I11) -> 2.3333333 | K11: =表1温室气体盘查表!AM13 -> 144.22983 | L11: =K11/$K$96 -> 9.3776394e-06 | M11: =J11*L11 -> 2.1881159e-05
A12: 10 | B12: =表1温室气体盘查表!C14 -> 制冷剂逸散（R32） | C12: =表1温室气体盘查表!D14 -> 分体式空调 | D12: 定期量测/抄表/铭牌 | E12: 国家排放因子 | F12: 校准且合格 | G12: =IF(D12="自动连续量测",6,IF(D12="定期量测/抄表/铭牌",3,1)) -> 3 | H12: =IF(E12="量测/质量平衡排放因子",6,IF(E12="制程/设备排放因子",5,IF(E12="制造商提供的排放因子",4,IF(E12="区域排放因子",3,IF(E12="国家排放因子",2,1))))) -> 2 | I12: =IF(F12="校准且合格",6,IF(F12="未校准",1,3)) -> 6 | J12: =AVERAGE(G12:I12) -> 3.6666667 | K12: =表1温室气体盘查表!AM14 -> 570.54 | L12: =K12/$K$96 -> 3.7095781e-05 | M12: =J12*L12 -> 0.00013601787
A13: 11 | B13: =表1温室气体盘查表!C15 -> CO2逸散 | C13: =表1温室气体盘查表!D15 -> 二氧化碳灭火器 | D13: 定期量测/抄表/铭牌 | E13: 国家排放因子 | F13: 校准且合格 | G13: =IF(D13="自动连续量测",6,IF(D13="定期量测/抄表/铭牌",3,1)) -> 3 | H13: =IF(E13="量测/质量平衡排放因子",6,IF(E13="制程/设备排放因子",5,IF(E13="制造商提供的排放因子",4,IF(E13="区域排放因子",3,IF(E13="国家排放因子",2,1))))) -> 2 | I13: =IF(F13="校准且合格",6,IF(F13="未校准",1,3)) -> 6 | J13: =AVERAGE(G13:I13) -> 3.6666667 | K13: =表1温室气体盘查表!AM15 -> 0.56 | L13: =K13/$K$96 -> 3.6410484e-08 | M13: =J13*L13 -> 1.3350511e-07
A14: 12 | B14: =表1温室气体盘查表!C16 -> CH4逸散 | C14: =表1温室气体盘查表!D16 -> 化粪池 | D14: 定期量测/抄表/铭牌 | E14: 国际排放因子 | F14: 校准且合格 | G14: =IF(D14="自动连续量测",6,IF(D14="定期量测/抄表/铭牌",3,1)) -> 3 | H14: =IF(E14="量测/质量平衡排放因子",6,IF(E14="制程/设备排放因子",5,IF(E14="制造商提供的排放因子",4,IF(E14="区域排放因子",3,IF(E14="国家排放因子",2,1))))) -> 1 | I14: =IF(F14="校准且合格",6,IF(F14="未校准",1,3)) -> 6 | J14: =AVERAGE(G14:I14) -> 3.3333333 | K14: =表1温室气体盘查表!AM16 -> 116.30952 | L14: =K14/$K$96 -> 7.5622963e-06 | M14: =J14*L14 -> 2.5207654e-05
... A28: 26 | B28: =表1温室气体盘查表!C30 -> 外购电力（基于位置） | C28: =表1温室气体盘查表!D30 -> 用电设备 | D28: 自动连续量测 | E28: 国家排放因子 | F28: 校准且合格 | G28: =IF(D28="自动连续量测",6,IF(D28="定期量测/抄表/铭牌",3,1)) -> 6 | H28: =IF(E28="量测/质量平衡排放因子",6,IF(E28="制程/设备排放因子",5,IF(E28="制造商提供的排放因子",4,IF(E28="区域排放因子",3,IF(E28="国家排放因子",2,1))))) -> 2 | I28: =IF(F28="校准且合格",6,IF(F28="未校准",1,3)) -> 6 | J28: =AVERAGE(G28:I28) -> 4.6666667 | K28: =表1温室气体盘查表!AM30 -> 1043611.1 | L28: =K28/$K$96 -> 0.067854256 | M28: =J28*L28 -> 0.3166532
A29: 27 | B29: =表1温室气体盘查表!C32 -> 铁矿石生产 | C29: =表1温室气体盘查表!D32 -> 烧结 | D29: 定期量测/抄表/铭牌 | E29: 国家排放因子 | F29: 校准且合格 | G29: =IF(D29="自动连续量测",6,IF(D29="定期量测/抄表/铭牌",3,1)) -> 3 | H29: =IF(E29="量测/质量平衡排放因子",6,IF(E29="制程/设备排放因子",5,IF(E29="制造商提供的排放因子",4,IF(E29="区域排放因子",3,IF(E29="国家排放因子",2,1))))) -> 2 | I29: =IF(F29="校准且合格",6,IF(F29="未校准",1,3)) -> 6 | J29: =AVERAGE(G29:I29) -> 3.6666667 | K29: =表1温室气体盘查表!AM32 -> 479835.37 | L29: =K29/$K$96 -> 0.031198282 | M29: =J29*L29 -> 0.1143937
A30: 28 | B30: =表1温室气体盘查表!C33 -> 生石灰生产 | C30: =表1温室气体盘查表!D33 -> 烧结、转炉、电炉 | D30: 定期量测/抄表/铭牌 | E30: 国际排放因子 | F30: 校准且合格 | G30: =IF(D30="自动连续量测",6,IF(D30="定期量测/抄表/铭牌",3,1)) -> 3 | H30: =IF(E30="量测/质量平衡排放因子",6,IF(E30="制程/设备排放因子",5,IF(E30="制造商提供的排放因子",4,IF(E30="区域排放因子",3,IF(E30="国家排放因子",2,1))))) -> 1 | I30: =IF(F30="校准且合格",6,IF(F30="未校准",1,3)) -> 6 | J30: =AVERAGE(G30:I30) -> 3.3333333 | K30: =表1温室气体盘查表!AM33 -> 236961.26 | L30: =K30/$K$96 -> 0.015406918 | M30: =J30*L30 -> 0.051356394
A31: 29 | B31: =表1温室气体盘查表!C34 -> 白云石生产 | C31: =表1温室气体盘查表!D34 -> 烧结、转炉、电炉 | D31: 定期量测/抄表/铭牌 | E31: 国际排放因子 | F31: 校准且合格 | G31: =IF(D31="自动连续量测",6,IF(D31="定期量测/抄表/铭牌",3,1)) -> 3 | H31: =IF(E31="量测/质量平衡排放因子",6,IF(E31="制程/设备排放因子",5,IF(E31="制造商提供的排放因子",4,IF(E31="区域排放因子",3,IF(E31="国家排放因子",2,1))))) -> 1 | I31: =IF(F31="校准且合格",6,IF(F31="未校准",1,3)) -> 6 | J31: =AVERAGE(G31:I31) -> 3.3333333 | K31: =表1温室气体盘查表!AM34 -> 5039.7894 | L31: =K31/$K$96 -> 0.00032768067 | M31: =J31*L31 -> 0.0010922689
A32: 30 | B32: =表1温室气体盘查表!C35 -> 球团生产 | C32: =表1温室气体盘查表!D35 -> 高炉、转炉 | D32: 定期量测/抄表/铭牌 | E32: 国际排放因子 | F32: 校准且合格 | G32: =IF(D32="自动连续量测",6,IF(D32="定期量测/抄表/铭牌",3,1)) -> 3 | H32: =IF(E32="量测/质量平衡排放因子",6,IF(E32="制程/设备排放因子",5,IF(E32="制造商提供的排放因子",4,IF(E32="区域排放因子",3,IF(E32="国家排放因子",2,1))))) -> 1 | I32: =IF(F32="校准且合格",6,IF(F32="未校准",1,3)) -> 6 | J32: =AVERAGE(G32:I32) -> 3.3333333 | K32: =表1温室气体盘查表!AM35 -> 71241.082 | L32: =K32/$K$96 -> 0.0046320041 | M32: =J32*L32 -> 0.015440014
A33: 31 | B33: =表1温室气体盘查表!C36 -> 废钢生产 | C33: =表1温室气体盘查表!D36 -> 转炉、电炉 | D33: 定期量测/抄表/铭牌 | E33: 国际排放因子 | F33: 校准且合格 | G33: =IF(D33="自动连续量测",6,IF(D33="定期量测/抄表/铭牌",3,1)) -> 3 | H33: =IF(E33="量测/质量平衡排放因子",6,IF(E33="制程/设备排放因子",5,IF(E33="制造商提供的排放因子",4,IF(E33="区域排放因子",3,IF(E33="国家排放因子",2,1))))) -> 1 | I33: =IF(F33="校准且合格",6,IF(F33="未校准",1,3)) -> 6 | J33: =AVERAGE(G33:I33) -> 3.3333333 | K33: =表1温室气体盘查表!AM36 -> 83051.97 | L33: =K33/$K$96 -> 0.0053999329 | M33: =J33*L33 -> 0.017999776
A34: 32 | B34: =表1温室气体盘查表!C37 -> 电极生产 | C34: =表1温室气体盘查表!D37 -> 转炉、电炉 | D34: 定期量测/抄表/铭牌 | E34: 国际排放因子 | F34: 校准且合格 | G34: =IF(D34="自动连续量测",6,IF(D34="定期量测/抄表/铭牌",3,1)) -> 3 | H34: =IF(E34="量测/质量平衡排放因子",6,IF(E34="制程/设备排放因子",5,IF(E34="制造商提供的排放因子",4,IF(E34="区域排放因子",3,IF(E34="国家排放因子",2,1))))) -> 1 | I34: =IF(F34="校准且合格",6,IF(F34="未校准",1,3)) -> 6 | J34: =AVERAGE(G34:I34) -> 3.3333333 | K34: =表1温室气体盘查表!AM37 -> 60962.024 | L34: =K34/$K$96 -> 0.0039636729 | M34: =J34*L34 -> 0.013212243
A35: 33 | B35: =表1温室气体盘查表!C38 -> 锰铁生产 | C35: =表1温室气体盘查表!D38 -> 转炉、电炉 | D35: 定期量测/抄表/铭牌 | E35: 国际排放因子 | F35: 校准且合格 | G35: =IF(D35="自动连续量测",6,IF(D35="定期量测/抄表/铭牌",3,1)) -> 3 | H35: =IF(E35="量测/质量平衡排放因子",6,IF(E35="制程/设备排放因子",5,IF(E35="制造商提供的排放因子",4,IF(E35="区域排放因子",3,IF(E35="国家排放因子",2,1))))) -> 1 | I35: =IF(F35="校准且合格",6,IF(F35="未校准",1,3)) -> 6 | J35: =AVERAGE(G35:I35) -> 3.3333333 | K35: =表1温室气体盘查表!AM38 -> 123503.69 | L35: =K35/$K$96 -> 0.0080300523 | M35: =J35*L35 -> 0.026766841
A36: 34 | B36: =表1温室气体盘查表!C39 -> 镍铁生产 | C36: =表1温室气体盘查表!D39 -> 转炉、电炉 | D36: 定期量测/抄表/铭牌 | E36: 国际排放因子 | F36: 校准且合格 | G36: =IF(D36="自动连续量测",6,IF(D36="定期量测/抄表/铭牌",3,1)) -> 3 | H36: =IF(E36="量测/质量平衡排放因子",6,IF(E36="制程/设备排放因子",5,IF(E36="制造商提供的排放因子",4,IF(E36="区域排放因子",3,IF(E36="国家排放因子",2,1))))) -> 1 | I36: =IF(F36="校准且合格",6,IF(F36="未校准",1,3)) -> 6 | J36: =AVERAGE(G36:I36) -> 3.3333333 | K36: =表1温室气体盘查表!AM39 -> 87049.733 | L36: =K36/$K$96 -> 0.0056598624 | M36: =J36*L36 -> 0.018866208
A37: 35 | B37: =表1温室气体盘查表!C40 -> 铬铁生产 | C37: =表1温室气体盘查表!D40 -> 转炉、电炉 | D37: 定期量测/抄表/铭牌 | E37: 国际排放因子 | F37: 校准且合格 | G37: =IF(D37="自动连续量测",6,IF(D37="定期量测/抄表/铭牌",3,1)) -> 3 | H37: =IF(E37="量测/质量平衡排放因子",6,IF(E37="制程/设备排放因子",5,IF(E37="制造商提供的排放因子",4,IF(E37="区域排放因子",3,IF(E37="国家排放因子",2,1))))) -> 1 | I37: =IF(F37="校准且合格",6,IF(F37="未校准",1,3)) -> 6 | J37: =AVERAGE(G37:I37) -> 3.3333333 | K37: =表1温室气体盘查表!AM40 -> 204743.82 | L37: =K37/$K$96 -> 0.013312181 | M37: =J37*L37 -> 0.044373938
A38: 36 | B38: =表1温室气体盘查表!C41 -> 萤石生产 | C38: =表1温室气体盘查表!D41 -> 转炉、电炉 | D38: 定期量测/抄表/铭牌 | E38: 国际排放因子 | F38: 校准且合格 | G38: =IF(D38="自动连续量测",6,IF(D38="定期量测/抄表/铭牌",3,1)) -> 3 | H38: =IF(E38="量测/质量平衡排放因子",6,IF(E38="制程/设备排放因子",5,IF(E38="制造商提供的排放因子",4,IF(E38="区域排放因子",3,IF(E38="国家排放因子",2,1))))) -> 1 | I38: =IF(F38="校准且合格",6,IF(F38="未校准",1,3)) -> 6 | J38: =AVERAGE(G38:I38) -> 3.3333333 | K38: =表1温室气体盘查表!AM41 -> 88473.44 | L38: =K38/$K$96 -> 0.00575243 | M38: =J38*L38 -> 0.019174767
A39: 37 | B39: =表1温室气体盘查表!C42 -> 硅铁生产 | C39: =表1温室气体盘查表!D42 -> 转炉、电炉 | D39: 定期量测/抄表/铭牌 | E39: 国际排放因子 | F39: 校准且合格 | G39: =IF(D39="自动连续量测",6,IF(D39="定期量测/抄表/铭牌",3,1)) -> 3 | H39: =IF(E39="量测/质量平衡排放因子",6,IF(E39="制程/设备排放因子",5,IF(E39="制造商提供的排放因子",4,IF(E39="区域排放因子",3,IF(E39="国家排放因子",2,1))))) -> 1 | I39: =IF(F39="校准且合格",6,IF(F39="未校准",1,3)) -> 6 | J39: =AVERAGE(G39:I39) -> 3.3333333 | K39: =表1温室气体盘查表!AM42 -> 149088.59 | L39: =K39/$K$96 -> 0.0096935493 | M39: =J39*L39 -> 0.032311831
A40: 38 | B40: =表1温室气体盘查表!C43 -> 钼铁生产 | C40: =表1温室气体盘查表!D43 -> 转炉、电炉 | D40: 定期量测/抄表/铭牌 | E40: 国际排放因子 | F40: 校准且合格 | G40: =IF(D40="自动连续量测",6,IF(D40="定期量测/抄表/铭牌",3,1)) -> 3 | H40: =IF(E40="量测/质量平衡排放因子",6,IF(E40="制程/设备排放因子",5,IF(E40="制造商提供的排放因子",4,IF(E40="区域排放因子",3,IF(E40="国家排放因子",2,1))))) -> 1 | I40: =IF(F40="校准且合格",6,IF(F40="未校准",1,3)) -> 6 | J40: =AVERAGE(G40:I40) -> 3.3333333 | K40: =表1温室气体盘查表!AM43 -> 58876.632 | L40: =K40/$K$96 -> 0.0038280834 | M40: =J40*L40 -> 0.012760278
... A95: 93 | B95: =表1温室气体盘查表!C98 -> 产品报废 | C95: =表1温室气体盘查表!D98 -> 下游钢铁厂 | D95: 自行推估 | E95: 国际排放因子 | F95: 校准但不合格/未校准但数据可查证 | G95: =IF(D95="自动连续量测",6,IF(D95="定期量测/抄表/铭牌",3,1)) -> 1 | H95: =IF(E95="量测/质量平衡排放因子",6,IF(E95="制程/设备排放因子",5,IF(E95="制造商提供的排放因子",4,IF(E95="区域排放因子",3,IF(E95="国家排放因子",2,1))))) -> 1 | I95: =IF(F95="校准且合格",6,IF(F95="未校准",1,3)) -> 3 | J95: =AVERAGE(G95:I95) -> 1.6666667 | K95: =表1温室气体盘查表!AM98 -> 3589.115 | L95: =K95/$K$96 -> 0.00023335967 | M95: =J95*L95 -> 0.00038893278
K96: =SUM(K3:K95) -> 15380185 | L96: 加权合计 | M96: =SUM(M3:M95) -> 3.6885263 | N96: uncertainty_score_location_based
L97: 加权等级 | M97: =IF(M96<2,"差",IF(M96<3,"一般",IF(M96<4,"良",IF(M96<5,"优","优+")))) -> 良
A107: 优+ | B107: >=5.0
A108: 优 | B108: <5.0,>=4.0
A109: 良 | B109: <4.0,>=3.0
A110: 一般 | B110: <3.0,>=2.0
A111: 差 | B111: <2.0

Sheet 表2.1不确定性评估——基于市场
A1: 不确定性评估表
A2: 编号 | B2: 排放源 | C2: 设施 | D2: 活动数据类别 | E2: 排放因子类别 | F2: 校准频率 | G2: 活动数据级别 | H2: 排放因子级别 | I2: 校准级别 | J2: 平均得分 | K2: 排放量(tCO2e) | L2: 排放量占比 | M2: 加权平均积分
A3: 1 | B3: =表1温室气体盘查表!C5 -> 天然气燃烧 | C3: =表1温室气体盘查表!D5 -> 热处理炉（加热炉） | D3: 自动连续量测 | E3: 国际排放因子 | F3: 校准且合格 | G3: =IF(D3="自动连续量测",6,IF(D3="定期量测/抄表/铭牌",3,1)) -> 6 | H3: =IF(E3="量测/质量平衡排放因子",6,IF(E3="制程/设备排放因子",5,IF(E3="制造商提供的排放因子",4,IF(E3="区域排放因子",3,IF(E3="国家排放因子",2,1))))) -> 1 | I3: =IF(F3="校准且合格",6,IF(F3="未校准",1,3)) -> 6 | J3: =AVERAGE(G3:I3) -> 4.3333333 | K3: =表1温室气体盘查表!AM5 -> 31469.159 | L3: =K3/$K$96 -> 0.0020272112 | M3: =J3*L3 -> 0.0087845819
A4: 2 | B4: =表1温室气体盘查表!C6 -> 液化石油气燃烧 | C4: =表1温室气体盘查表!D6 -> 冶钢宾馆 | D4: 定期量测/抄表/铭牌 | E4: 国际排放因子 | F4: 校准且合格 | G4: =IF(D4="自动连续量测",6,IF(D4="定期量测/抄表/铭牌",3,1)) -> 3 | H4: =IF(E4="量测/质量平衡排放因子",6,IF(E4="制程/设备排放因子",5,IF(E4="制造商提供的排放因子",4,IF(E4="区域排放因子",3,IF(E4="国家排放因子",2,1))))) -> 1 | I4: =IF(F4="校准且合格",6,IF(F4="未校准",1,3)) -> 6 | J4: =AVERAGE(G4:I4) -> 3.3333333 | K4: =表1温室气体盘查表!AM6 -> 29.286595 | L4: =K4/$K$96 -> 1.8866127e-06 | M4: =J4*L4 -> 6.2887089e-06
A5: 3 | B5: =表1温室气体盘查表!C7 -> 烟煤燃烧 | C5: =表1温室气体盘查表!D7 -> 高炉 | D5: 自动连续量测 | E5: 国际排放因子 | F5: 校准且合格 | G5: =IF(D5="自动连续量测",6,IF(D5="定期量测/抄表/铭牌",3,1)) -> 6 | H5: =IF(E5="量测/质量平衡排放因子",6,IF(E5="制程/设备排放因子",5,IF(E5="制造商提供的排放因子",4,IF(E5="区域排放因子",3,IF(E5="国家排放因子",2,1))))) -> 1 | I5: =IF(F5="校准且合格",6,IF(F5="未校准",1,3)) -> 6 | J5: =AVERAGE(G5:I5) -> 4.3333333 | K5: =表1温室气体盘查表!AM7 -> 749580.33 | L5: =K5/$K$96 -> 0.048287202 | M5: =J5*L5 -> 0.20924454
A6: 4 | B6: =表1温室气体盘查表!C8 -> 无烟煤燃烧 | C6: =表1温室气体盘查表!D8 -> 高炉、烧结 | D6: 自动连续量测 | E6: 国际排放因子 | F6: 校准且合格 | G6: =IF(D6="自动连续量测",6,IF(D6="定期量测/抄表/铭牌",3,1)) -> 6 | H6: =IF(E6="量测/质量平衡排放因子",6,IF(E6="制程/设备排放因子",5,IF(E6="制造商提供的排放因子",4,IF(E6="区域排放因子",3,IF(E6="国家排放因子",2,1))))) -> 1 | I6: =IF(F6="校准且合格",6,IF(F6="未校准",1,3)) -> 6 | J6: =AVERAGE(G6:I6) -> 4.3333333 | K6: =表1温室气体盘查表!AM8 -> 820622.2 | L6: =K6/$K$96 -> 0.052863647 | M6: =J6*L6 -> 0.2290758
A7: 5 | B7: =表1温室气体盘查表!C9 -> 洗精煤燃烧 | C7: =表1温室气体盘查表!D9 -> 焦炉 | D7: 自动连续量测 | E7: 国际排放因子 | F7: 校准且合格 | G7: =IF(D7="自动连续量测",6,IF(D7="定期量测/抄表/铭牌",3,1)) -> 6 | H7: =IF(E7="量测/质量平衡排放因子",6,IF(E7="制程/设备排放因子",5,IF(E7="制造商提供的排放因子",4,IF(E7="区域排放因子",3,IF(E7="国家排放因子",2,1))))) -> 1 | I7: =IF(F7="校准且合格",6,IF(F7="未校准",1,3)) -> 6 | J7: =AVERAGE(G7:I7) -> 4.3333333 | K7: =表1温室气体盘查表!AM9 -> 5189313.3 | L7: =K7/$K$96 -> 0.33429028 | M7: =J7*L7 -> 1.4485912
A8: 6 | B8: =表1温室气体盘查表!C10 -> 焦炭燃烧 | C8: =表1温室气体盘查表!D10 -> 高炉 | D8: 自动连续量测 | E8: 国际排放因子 | F8: 校准且合格 | G8: =IF(D8="自动连续量测",6,IF(D8="定期量测/抄表/铭牌",3,1)) -> 6 | H8: =IF(E8="量测/质量平衡排放因子",6,IF(E8="制程/设备排放因子",5,IF(E8="制造商提供的排放因子",4,IF(E8="区域排放因子",3,IF(E8="国家排放因子",2,1))))) -> 1 | I8: =IF(F8="校准且合格",6,IF(F8="未校准",1,3)) -> 6 | J8: =AVERAGE(G8:I8) -> 4.3333333 | K8: =表1温室气体盘查表!AM10 -> 669939.56 | L8: =K8/$K$96 -> 0.043156825 | M8: =J8*L8 -> 0.18701291
A9: 7 | B9: =表1温室气体盘查表!C11 -> 焦炉煤气燃烧 | C9: =表1温室气体盘查表!D11 -> 外售 | D9: 自动连续量测 | E9: 国际排放因子 | F9: 校准且合格 | G9: =IF(D9="自动连续量测",6,IF(D9="定期量测/抄表/铭牌",3,1)) -> 6 | H9: =IF(E9="量测/质量平衡排放因子",6,IF(E9="制程/设备排放因子",5,IF(E9="制造商提供的排放因子",4,IF(E9="区域排放因子",3,IF(E9="国家排放因子",2,1))))) -> 1 | I9: =IF(F9="校准且合格",6,IF(F9="未校准",1,3)) -> 6 | J9: =AVERAGE(G9:I9) -> 4.3333333 | K9: =表1温室气体盘查表!AM11 -> -6034.9102 | L9: =K9/$K$96 -> -0.00038876277 | M9: =J9*L9 -> -0.0016846387
A10: 8 | B10: =表1温室气体盘查表!C12 -> 柴油燃烧 | C10: =表1温室气体盘查表!D12 -> 场内运输 | D10: 定期量测/抄表/铭牌 | E10: 国际排放因子 | F10: 校准但不合格/未校准但数据可查证 | G10: =IF(D10="自动连续量测",6,IF(D10="定期量测/抄表/铭牌",3,1)) -> 3 | H10: =IF(E10="量测/质量平衡排放因子",6,IF(E10="制程/设备排放因子",5,IF(E10="制造商提供的排放因子",4,IF(E10="区域排放因子",3,IF(E10="国家排放因子",2,1))))) -> 1 | I10: =IF(F10="校准且合格",6,IF(F10="未校准",1,3)) -> 3 | J10: =AVERAGE(G10:I10) -> 2.3333333 | K10: =表1温室气体盘查表!AM12 -> 4476.287 | L10: =K10/$K$96 -> 0.00028835785 | M10: =J10*L10 -> 0.00067283499
A11: 9 | B11: =表1温室气体盘查表!C13 -> 汽油燃烧 | C11: =表1温室气体盘查表!D13 -> 公务车 | D11: 定期量测/抄表/铭牌 | E11: 国际排放因子 | F11: 校准但不合格/未校准但数据可查证 | G11: =IF(D11="自动连续量测",6,IF(D11="定期量测/抄表/铭牌",3,1)) -> 3 | H11: =IF(E11="量测/质量平衡排放因子",6,IF(E11="制程/设备排放因子",5,IF(E11="制造商提供的排放因子",4,IF(E11="区域排放因子",3,IF(E11="国家排放因子",2,1))))) -> 1 | I11: =IF(F11="校准且合格",6,IF(F11="未校准",1,3)) -> 3 | J11: =AVERAGE(G11:I11) -> 2.3333333 | K11: =表1温室气体盘查表!AM13 -> 144.22983 | L11: =K11/$K$96 -> 9.2911391e-06 | M11: =J11*L11 -> 2.1679325e-05
A12: 10 | B12: =表1温室气体盘查表!C14 -> 制冷剂逸散（R32） | C12: =表1温室气体盘查表!D14 -> 分体式空调 | D12: 定期量测/抄表/铭牌 | E12: 国家排放因子 | F12: 校准且合格 | G12: =IF(D12="自动连续量测",6,IF(D12="定期量测/抄表/铭牌",3,1)) -> 3 | H12: =IF(E12="量测/质量平衡排放因子",6,IF(E12="制程/设备排放因子",5,IF(E12="制造商提供的排放因子",4,IF(E12="区域排放因子",3,IF(E12="国家排放因子",2,1))))) -> 2 | I12: =IF(F12="校准且合格",6,IF(F12="未校准",1,3)) -> 6 | J12: =AVERAGE(G12:I12) -> 3.6666667 | K12: =表1温室气体盘查表!AM14 -> 570.54 | L12: =K12/$K$96 -> 3.6753606e-05 | M12: =J12*L12 -> 0.00013476322
