Workbook
Name CONST_CNTR_TotProd: #REF!
Name CONST_ElecConsumption: #REF!

Sheet 温室气体盘查清册 (2)
B1: 温室气体盘查清册 | L1: 编号：DY-GHG-2025-01
L2: 版本/版次：A/1
L3: 日期：2025/7/3
B4: 组织名称： | C4: 大冶特殊钢有限公司
B5: 组织边界： | C5: 湖北省黄石市黄石大道316号
B6: 盘查覆盖周期: | C6: 2024年1月1日至2024年12月31日
B7: 编制 ： | E7: 审核： | K7: 核准：
B8: 报告边界 | C8: 运营控制权 | E8: 范围一排放量： | F8: =F14 -> 7122248.8 | K8: 单位：tCO2e
E9: 范围二（基于位置）排放量： | F9: =F47 -> 1069378.7
E10: 范围二（基于市场）排放量： | F10: =F48 -> 1161900.3
B11: 排放 | E11: 范围三排放量： | F11: =SUM(F50,F76,F89,F101,F106,F113,F118,F124,F130,F136) -> 7328574.6
B12: 编号 | C12: 排放源 | D12: 排放设施 | E12: 备注 | F12: 总排放量 | G12: CO2 | H12: CH4 | I12: N2O | J12: HFCs | K12: PFCs | L12: SF6 | M12: NF3
G13: tCO2e
B14: 范围一 直接排放 | F14: =F15+F24+F27+F33 -> 7122248.8 | G14: =G15+G24+G27+G33 -> 7086080.3 | H14: =H15+H24+H27+H33 -> 2569.6835 | I14: =I15+I24+I27+I33 -> 30422.615 | J14: =J15+J24+J27+J33 -> 717.03 | K14: =K15+K24+K27+K33 -> 0 | L14: =L15+L24+L27+L33 -> 2459.16 | M14: =M15+M24+M27+M33 -> 0
B15: 1.1 | C15: 固定源燃烧直接排放 | F15: =SUM(G15:M15) -> 7227644.2 | G15: =SUM(G16:G23) -> 7195204.6 | H15: =SUM(H16:H23) -> 2083.9816 | I15: =SUM(I16:I23) -> 30355.616 | J15: =SUM(J16:J23) -> 0 | K15: =SUM(K16:K23) -> 0 | L15: =SUM(L16:L23) -> 0 | M15: =SUM(M16:M23) -> 0
B16: 1.1.1 | C16: =表1温室气体盘查表!C5 -> 天然气燃烧 | D16: =表1温室气体盘查表!D5 -> 热处理炉（加热炉） | F16: =SUM(G16:M16) -> 38881.726 | G16: =表1温室气体盘查表!AE5 -> 38843.506 | H16: =表1温室气体盘查表!AF5 -> 19.317893 | I16: =表1温室气体盘查表!AG5 -> 18.902455 | J16: =表1温室气体盘查表!AH5 -> 0 | K16: =表1温室气体盘查表!AI5 -> 0 | L16: =表1温室气体盘查表!AJ5 -> 0 | M16: =表1温室气体盘查表!AK5 -> 0
B17: 1.1.2 | C17: =表1温室气体盘查表!C6 -> 液化石油气燃烧 | D17: =表1温室气体盘查表!D6 -> 冶钢宾馆 | F17: =SUM(G17:M17) -> 29.162368 | G17: =表1温室气体盘查表!AE6 -> 29.136879 | H17: =表1温室气体盘查表!AF6 -> 0.012883026 | I17: =表1温室气体盘查表!AG6 -> 0.012605971 | J17: =表1温室气体盘查表!AH6 -> 0 | K17: =表1温室气体盘查表!AI6 -> 0 | L17: =表1温室气体盘查表!AJ6 -> 0 | M17: =表1温室气体盘查表!AK6 -> 0
B18: 1.1.3 | C18: =表1温室气体盘查表!C7 -> 烟煤燃烧 | D18: =表1温室气体盘查表!D7 -> 高炉 | F18: =SUM(G18:M18) -> 925941.32 | G18: =表1温室气体盘查表!AE7 -> 921839.46 | H18: =表1温室气体盘查表!AF7 -> 261.64111 | I18: =表1温室气体盘查表!AG7 -> 3840.2163 | J18: =表1温室气体盘查表!AH7 -> 0 | K18: =表1温室气体盘查表!AI7 -> 0 | L18: =表1温室气体盘查表!AJ7 -> 0 | M18: =表1温室气体盘查表!AK7 -> 0
B19: 1.1.4 | C19: =表1温室气体盘查表!C8 -> 无烟煤燃烧 | D19: =表1温室气体盘查表!D8 -> 高炉、烧结 | F19: =SUM(G19:M19) -> 637282.39 | G19: =表1温室气体盘查表!AE8 -> 634459.27 | H19: =表1温室气体盘查表!AF8 -> 180.07542 | I19: =表1温室气体盘查表!AG8 -> 2643.0424 | J19: =表1温室气体盘查表!AH8 -> 0 | K19: =表1温室气体盘查表!AI8 -> 0 | L19: =表1温室气体盘查表!AJ8 -> 0 | M19: =表1温室气体盘查表!AK8 -> 0
B20: 1.1.5 | C20: =表1温室气体盘查表!C9 -> 洗精煤燃烧 | D20: =表1温室气体盘查表!D9 -> 焦炉 | F20: =SUM(G20:M20) -> 4824841.6 | G20: =表1温室气体盘查表!AE9 -> 4802635.7 | H20: =表1温室气体盘查表!AF9 -> 1416.4222 | I20: =表1温室气体盘查表!AG9 -> 20789.422 | J20: =表1温室气体盘查表!AH9 -> 0 | K20: =表1温室气体盘查表!AI9 -> 0 | L20: =表1温室气体盘查表!AJ9 -> 0 | M20: =表1温室气体盘查表!AK9 -> 0
B21: 1.1.6 | C21: =表1温室气体盘查表!C10 -> 焦炭燃烧 | D21: =表1温室气体盘查表!D10 -> 高炉 | F21: =SUM(G21:M21) -> 439843.84 | G21: =表1温室气体盘查表!AE10 -> 438053.15 | H21: =表1温室气体盘查表!AF10 -> 114.22134 | I21: =表1温室气体盘查表!AG10 -> 1676.4744 | J21: =表1温室气体盘查表!AH10 -> 0 | K21: =表1温室气体盘查表!AI10 -> 0 | L21: =表1温室气体盘查表!AJ10 -> 0 | M21: =表1温室气体盘查表!AK10 -> 0
B22: 1.1.7 | C22: =表1温室气体盘查表!C11 -> 焦屑燃烧 | D22: =表1温室气体盘查表!D11 -> 烧结、高炉 | F22: =SUM(G22:M22) -> 364657.36 | G22: =表1温室气体盘查表!AE11 -> 363172.76 | H22: =表1温室气体盘查表!AF11 -> 94.696449 | I22: =表1温室气体盘查表!AG11 -> 1389.8995 | J22: =表1温室气体盘查表!AH11 -> 0 | K22: =表1温室气体盘查表!AI11 -> 0 | L22: =表1温室气体盘查表!AJ11 -> 0 | M22: =表1温室气体盘查表!AK11 -> 0
B23: 1.1.8 | C23: =表1温室气体盘查表!C12 -> 焦炉煤气燃烧 | D23: =表1温室气体盘查表!D12 -> 外售 | F23: =SUM(G23:M23) -> -3833.1355 | G23: =表1温室气体盘查表!AE12 -> -3828.3759 | H23: =表1温室气体盘查表!AF12 -> -2.4056686 | I23: =表1温室气体盘查表!AG12 -> -2.3539338 | J23: =表1温室气体盘查表!AH12 -> 0 | K23: =表1温室气体盘查表!AI12 -> 0 | L23: =表1温室气体盘查表!AJ12 -> 0 | M23: =表1温室气体盘查表!AK12 -> 0
B24: 1.2 | C24: 移动源燃烧直接排放 | F24: =SUM(G24:M24) -> 4566.5427 | G24: =SUM(G25:G26) -> 4491.7139 | H24: =SUM(H25:H26) -> 7.8293549 | I24: =SUM(I25:I26) -> 66.999448 | J24: =SUM(J25:J26) -> 0 | K24: =SUM(K25:K26) -> 0 | L24: =SUM(L25:L26) -> 0 | M24: =SUM(M25:M26) -> 0
B25: 1.2.1 | C25: =表1温室气体盘查表!C13 -> 0#柴油燃烧 | D25: =表1温室气体盘查表!D13 -> 场内运输 | F25: =SUM(G25:M25) -> 4417.0726 | G25: =表1温室气体盘查表!AE13 -> 4348.2107 | H25: =表1温室气体盘查表!AF13 -> 6.3850041 | I25: =表1温室气体盘查表!AG13 -> 62.476922 | J25: =表1温室气体盘查表!AH13 -> 0 | K25: =表1温室气体盘查表!AI13 -> 0 | L25: =表1温室气体盘查表!AJ13 -> 0 | M25: =表1温室气体盘查表!AK13 -> 0
B26: 1.2.2 | C26: =表1温室气体盘查表!C14 -> 92#汽油燃烧 | D26: =表1温室气体盘查表!D14 -> 公务车 | F26: =SUM(G26:M26) -> 149.47012 | G26: =表1温室气体盘查表!AE14 -> 143.50325 | H26: =表1温室气体盘查表!AF14 -> 1.4443509 | I26: =表1温室气体盘查表!AG14 -> 4.5225266 | J26: =表1温室气体盘查表!AH14 -> 0 | K26: =表1温室气体盘查表!AI14 -> 0 | L26: =表1温室气体盘查表!AJ14 -> 0 | M26: =表1温室气体盘查表!AK14 -> 0
B27: 1.3 | C27: 逸散源直接排放 | F27: =SUM(G27:M27) -> 3654.7226 | G27: =SUM(G28:G32) -> 0.66 | H27: =SUM(H28:H32) -> 477.87259 | I27: =SUM(I28:I32) -> 0 | J27: =SUM(J28:J32) -> 717.03 | K27: =SUM(K28:K32) -> 0 | L27: =SUM(L28:L32) -> 2459.16 | M27: =SUM(M28:M32) -> 0
B28: 1.3.1 | C28: =表1温室气体盘查表!C15 -> 制冷剂逸散（R32） | D28: =表1温室气体盘查表!D15 -> 分体式空调 | F28: =SUM(G28:M28) -> 717.03 | G28: =表1温室气体盘查表!AE15 -> 0 | H28: =表1温室气体盘查表!AF15 -> 0 | I28: =表1温室气体盘查表!AG15 -> 0 | J28: =表1温室气体盘查表!AH15 -> 717.03 | K28: =表1温室气体盘查表!AI15 -> 0 | L28: =表1温室气体盘查表!AJ15 -> 0 | M28: =表1温室气体盘查表!AK15 -> 0
B29: 1.3.2 | C29: =表1温室气体盘查表!C16 -> CO2逸散 | D29: =表1温室气体盘查表!D16 -> 二氧化碳灭火器 | F29: =SUM(G29:M29) -> 0.66 | G29: =表1温室气体盘查表!AE16 -> 0.66 | H29: =表1温室气体盘查表!AF16 -> 0 | I29: =表1温室气体盘查表!AG16 -> 0 | J29: =表1温室气体盘查表!AH16 -> 0 | K29: =表1温室气体盘查表!AI16 -> 0 | L29: =表1温室气体盘查表!AJ16 -> 0 | M29: =表1温室气体盘查表!AK16 -> 0
B30: 1.3.3 | C30: =表1温室气体盘查表!C17 -> CH4逸散 | D30: =表1温室气体盘查表!D17 -> 化粪池 | F30: =SUM(G30:M30) -> 112.29192 | G30: =表1温室气体盘查表!AE17 -> 0 | H30: =表1温室气体盘查表!AF17 -> 112.29192 | I30: =表1温室气体盘查表!AG17 -> 0 | J30: =表1温室气体盘查表!AH17 -> 0 | K30: =表1温室气体盘查表!AI17 -> 0 | L30: =表1温室气体盘查表!AJ17 -> 0 | M30: =表1温室气体盘查表!AK17 -> 0
B31: 1.3.4 | C31: =表1温室气体盘查表!C18 -> CH4逸散 | D31: =表1温室气体盘查表!D18 -> 耗氧池 | F31: =SUM(G31:M31) -> 365.58067 | G31: =表1温室气体盘查表!AE18 -> 0 | H31: =表1温室气体盘查表!AF18 -> 365.58067 | I31: =表1温室气体盘查表!AG18 -> 0 | J31: =表1温室气体盘查表!AH18 -> 0 | K31: =表1温室气体盘查表!AI18 -> 0 | L31: =表1温室气体盘查表!AJ18 -> 0 | M31: =表1温室气体盘查表!AK18 -> 0
B32: 1.3.5 | C32: =表1温室气体盘查表!C19 -> SF6逸散 | D32: =表1温室气体盘查表!D19 -> 高压开关 | F32: =SUM(G32:M32) -> 2459.16 | G32: =表1温室气体盘查表!AE19 -> 0 | H32: =表1温室气体盘查表!AF19 -> 0 | I32: =表1温室气体盘查表!AG19 -> 0 | J32: =表1温室气体盘查表!AH19 -> 0 | K32: =表1温室气体盘查表!AI19 -> 0 | L32: =表1温室气体盘查表!AJ19 -> 2459.16 | M32: =表1温室气体盘查表!AK19 -> 0
B33: 1.4 | C33: 制程排放 | F33: =SUM(G33:M33) -> -113616.67 | G33: =SUM(G34:G45) -> -113616.67 | H33: =SUM(H34:H45) -> 0 | I33: =SUM(I34:I45) -> 0 | J33: =SUM(J34:J45) -> 0 | K33: =SUM(K34:K45) -> 0 | L33: =SUM(L34:L45) -> 0 | M33: =SUM(M34:M45) -> 0
B34: 1.4.1 | C34: =表1温室气体盘查表!C20 -> 石灰石 | D34: =表1温室气体盘查表!D20 -> 石灰窑 | F34: =SUM(G34:M34) -> 8520.9388 | G34: =表1温室气体盘查表!AE20 -> 8520.9388 | H34: =表1温室气体盘查表!AF20 -> 0 | I34: =表1温室气体盘查表!AG20 -> 0 | J34: =表1温室气体盘查表!AH20 -> 0 | K34: =表1温室气体盘查表!AI20 -> 0 | L34: =表1温室气体盘查表!AJ20 -> 0 | M34: =表1温室气体盘查表!AK20 -> 0
B35: 1.4.2 | C35: =表1温室气体盘查表!C21 -> 白云石 | D35: =表1温室气体盘查表!D21 -> 高炉 | F35: =SUM(G35:M35) -> 169593.75 | G35: =表1温室气体盘查表!AE21 -> 169593.75 | H35: =表1温室气体盘查表!AF21 -> 0 | I35: =表1温室气体盘查表!AG21 -> 0 | J35: =表1温室气体盘查表!AH21 -> 0 | K35: =表1温室气体盘查表!AI21 -> 0 | L35: =表1温室气体盘查表!AJ21 -> 0 | M35: =表1温室气体盘查表!AK21 -> 0
B36: 1.4.3 | C36: =表1温室气体盘查表!C22 -> 电极 | D36: =表1温室气体盘查表!D22 -> 炼钢 | F36: =SUM(G36:M36) -> 17447.125 | G36: =表1温室气体盘查表!AE22 -> 17447.125 | H36: =表1温室气体盘查表!AF22 -> 0 | I36: =表1温室气体盘查表!AG22 -> 0 | J36: =表1温室气体盘查表!AH22 -> 0 | K36: =表1温室气体盘查表!AI22 -> 0 | L36: =表1温室气体盘查表!AJ22 -> 0 | M36: =表1温室气体盘查表!AK22 -> 0
B37: 1.4.4 | C37: =表1温室气体盘查表!C23 -> 废钢 | D37: =表1温室气体盘查表!D23 -> 炼钢 | F37: =SUM(G37:M37) -> 39875.738 | G37: =表1温室气体盘查表!AE23 -> 39875.738 | H37: =表1温室气体盘查表!AF23 -> 0 | I37: =表1温室气体盘查表!AG23 -> 0 | J37: =表1温室气体盘查表!AH23 -> 0 | K37: =表1温室气体盘查表!AI23 -> 0 | L37: =表1温室气体盘查表!AJ23 -> 0 | M37: =表1温室气体盘查表!AK23 -> 0
B38: 1.4.5 | C38: =表1温室气体盘查表!C24 -> 锰铁 | D38: =表1温室气体盘查表!D24 -> 炼钢 | F38: =SUM(G38:M38) -> 13114.101 | G38: =表1温室气体盘查表!AE24 -> 13114.101 | H38: =表1温室气体盘查表!AF24 -> 0 | I38: =表1温室气体盘查表!AG24 -> 0 | J38: =表1温室气体盘查表!AH24 -> 0 | K38: =表1温室气体盘查表!AI24 -> 0 | L38: =表1温室气体盘查表!AJ24 -> 0 | M38: =表1温室气体盘查表!AK24 -> 0
B39: 1.4.6 | C39: =表1温室气体盘查表!C25 -> 镍铁 | D39: =表1温室气体盘查表!D25 -> 炼钢 | F39: =SUM(G39:M39) -> 349.46907 | G39: =表1温室气体盘查表!AE25 -> 349.46907 | H39: =表1温室气体盘查表!AF25 -> 0 | I39: =表1温室气体盘查表!AG25 -> 0 | J39: =表1温室气体盘查表!AH25 -> 0 | K39: =表1温室气体盘查表!AI25 -> 0 | L39: =表1温室气体盘查表!AJ25 -> 0 | M39: =表1温室气体盘查表!AK25 -> 0
B40: 1.4.7 | C40: =表1温室气体盘查表!C26 -> 铬铁 | D40: =表1温室气体盘查表!D26 -> 炼钢 | F40: =SUM(G40:M40) -> 22918.907 | G40: =表1温室气体盘查表!AE26 -> 22918.907 | H40: =表1温室气体盘查表!AF26 -> 0 | I40: =表1温室气体盘查表!AG26 -> 0 | J40: =表1温室气体盘查表!AH26 -> 0 | K40: =表1温室气体盘查表!AI26 -> 0 | L40: =表1温室气体盘查表!AJ26 -> 0 | M40: =表1温室气体盘查表!AK26 -> 0
...

Sheet 基本信息
A1: 变量名 | B1: 变量名 | C1: 值
A2: 公司名称 | B2: company_name | C2: 大冶特殊钢有限公司
A3: 报告周期 | B3: reporting_period | C3: 2024年1月1日至2024年12月31日
A4: 报告编号 | B4: document_number | C4: DY-GHG-2025-02
A5: 生成日期 | B5: posted_time | C5: 45841
A6: 统一社会信用代码 | B6: Unified_Social_Credit_Identifier | C6: 91420000798750168P
A7: 法人代表 | B7: legal_person | C7: 蒋乔
A8: 注册资金 | B8: registered_capital | C8: 207218.53万元
A9: 注册日期 | B9: date_of_establishment | C9: 39150
A10: 注册地址 | B10: registered_address | C10: 湖北省黄石市黄石大道316号
A11: 生产地址 | B11: production_address | C11: 湖北省黄石市黄石大道316号
A12: 经营范围 | B12: scope_of_business | C12: 大冶特殊钢有限公司成立于2007年03月09日，注册地位于湖北省黄石市黄石大道316号，法定代表人为蒋乔。经营范围包括黑色、有色金属冶炼、压延加工；生产、销售高温合金材料、耐蚀合金材料、铁矿石、钢坯、钢锭、钢材、金属制品、钢管及管件和相应的工业辅助材料及承接来料加工业务；钢铁和合金材料检测；再生资源回收经营；货物或技术进出口（国家限定公司经营或禁止进出口的商品和技术除外）；机械零件、汽车零部件制造和加工；机械、仪表、电器制造和修理；化工产品（不含危险品和限制类产品）制造；港口码头建设及经营；煤气、热力、自来水、工业用水生产和供应；餐饮经营与管理。（涉及许可经营项目，应取得相关部门许可后方可经营）。
A13: 公司简介 | B13: company_profile | C13: 大冶特殊钢有限公司（简称：大冶特钢）是中国近代“钢铁摇篮”，地处中国矿冶之都、先进制造业基地湖北省黄石市。隶属中信泰富特钢集团，是其沿海沿江产业链的战略布局中的重要一环。 大冶特钢是国家高新技术企业、全国首批两化融合示范企业、全国首批绿色制造示范企业、全国绿化模范单位。拥有国家认定企业技术中心、院士专家工作站、博士后科研工作站、高品质特殊钢湖北省重点实验室，先后承担国家多项冶金课题的项目攻关，主持或参与起草修订了多项国家和行业技术标准。先后荣获“全国质量奖”、“全国质量标杆”、“中国工业大奖表彰奖”，多项产品荣获国家冶金产品实物质量“金杯奖”、“国家科学技术进步一等奖、二等奖”、“冶金科学技术奖一等奖”、“国家知识产权优势企业”、“中国航天突出贡献供应商”、“中国工模具行业最具影响力钢厂品牌”等奖项。 大冶特钢是中国品种规格最齐全的高品质棒材、高端中厚壁无缝钢管、高合金锻材三大特钢生产基地，工艺技术和装备具备世界先进水平。主要产品有轴承钢、汽车用钢、能源用钢、工程机械用钢、航空航天用钢等。主要服务于航天航空、海洋、核电、风电、交通、火电、油气、工程机械、重燃、船舶、石化、汽车、高铁等关键领域。 从中国第一炉电渣钢到第一根极薄壁高温合金旋压管，从第一个飞机用高温合金涡轮盘，到第一根轧制的飞机大梁(毛坯)，从中国第一颗人造地球卫星，到神舟系列飞船的上天，到“嫦娥”奔月，再到“天宫”“北斗”发射升空，大冶特钢均提供了关键部件的用钢。工程机械用无缝钢管已连续13年产销量全国第一、13年全球第一，石油工具及装备用中厚壁无缝钢管连续10年产销量全国第一，大口径厚壁高压锅炉用管连续5年产销量全国第一。 大冶特钢秉承“诚信、创新、融合、卓越”的理念，牢记为客户创造价值，为员工创造幸福，为股东创造效益，为社会创造财富的企业使命，致力于为客户提供多规格、多品种、高品质的特殊钢产品及整体服务方案，致力于“创建全球最具竞争力的特钢企业集团”。
A14: DDL | B14: deadline | C14: 2025年6月底前
A15: 规则文件 | B15: rule_file | C15: 《大冶特殊钢温室气体盘查控制程序（DY-GHG-2023）》
A16: GWP值来源文件 | B16: GWP_Value_Reference_Document | C16: IPCC 2021年出具的《第六次评估报告AR6》
B17: source_file | C17: 《温室气体盘查清册》-表2 不确定性评估
A18: 制作 | B18: producer | C18: 杨春英
A19: 审核 | B19: auditor
A20: 核准 | B20: approver
A21: 报告年 | B21: reporting_year | C21: 2024
A22: 下一年 | B22: next_year | C22: 2025

Sheet Sheet1
A1: {%tr for item in act_summary_loc %}
A2: {{item.number}} | B2: {{item.emission_source_type_loc}} | C2: {{item.emission_source_loc}} | D2: {{item. report_boundary_loc}} | E2: {{item.act_summary_loc}} | F2: {{item.act_summary_loc_unit}} | G2: {{item.CO2_emissions}} | H2: {{item.CH4_emissions}} | I2: {{item.N2O_emissions}} | J2: {{item.HFCs_emissions}} | K2: {{item.PFCs_emissions}} | L2: {{item.SF6_emissions}} | M2: {{item.NF3_emissions}} | N2: {{item.total_green_house_gas_emissions}}
A3: {%tr endfor %}
G4: {{loc_CO2_emissions_sum_formatted}} | H4: {{loc_CH4_emissions_sum_formatted}} | I4: {{loc_N2O_emissions_sum_formatted}} | J4: {{loc_HFCs_emissions_sum_formatted}} | K4: {{loc_PFCs_emissions_sum_formatted}} | L4: {{loc_SF6_emissions_sum_formatted}} | M4: {{loc_NF3_emissions_sum_formatted}} | N4: {{loc_total_green_house_gas_emissions_sum_formatted}}
A7: {%tr for item in act_summary_mar %}
A8: {{item.number}} | B8: {{item.emission_source_type_mar}} | C8: {{item.emission_source_mar}} | D8: {{item. report_boundary_mar}} | E8: {{item.act_summary_mar}} | F8: {{item.act_summary_mar_unit}} | G8: {{item.CO2_emissions}} | H8: {{item.CH4_emissions}} | I8: {{item.N2O_emissions}} | J8: {{item.HFCs_emissions}} | K8: {{item.PFCs_emissions}} | L8: {{item.SF6_emissions}} | M8: {{item.NF3_emissions}} | N8: {{item.total_green_house_gas_emissions}}
A9: {%tr endfor %}
G10: {{mar_CO2_emissions_sum_formatted}} | H10: {{mar_CH4_emissions_sum_formatted}} | I10: {{mar_N2O_emissions_sum_formatted}} | J10: {{mar_HFCs_emissions_sum_formatted}} | K10: {{mar_PFCs_emissions_sum_formatted}} | L10: {{mar_SF6_emissions_sum_formatted}} | M10: {{mar_NF3_emissions_sum_formatted}} | N10: {{mar_total_green_house_gas_emissions_sum_formatted}}
A14: 编号 | B14: GHG排放类别 | C14: 排放源 | D14: 设施 | E14: 低位发热量 | F14: 单位 | G14: 氧化率 | H14: 基于热值排放系数，t GHG/GJ | K14: 排放因子，t GHG/10000m³
H15: IPCC-2006缺省值 | K15: 计算值
E16: 企业温室气体排放核算与报告指南 钢铁行业 | G16: 企业温室气体排放核算与报告指南 钢铁行业 | H16: CO2 | I16: CH4 | J16: N2O | K16: CO2 | L16: CH4 | M16: N2O
A17: {%tr for item in com_ef_items %}
A18: {{item.number}} | B18: {{item.emission_source_type_dir}} | C18: {{item.emission_source_dir}} | D18: {{item.emission_facilities_dir}} | E18: {{item.ncv_dir}} | F18: {{item.emission_unit_dir}} | G18: {{item.emission_oa_dir}} | H18: {{item.CO2_emission_cv_factor}} | I18: {{item.CH4_emission_cv_factor}} | J18: {{item.N2O_emission_cv_factor}} | K18: {{item.CO2_emission_factor}} | L18: {{item.CH4_emission_factor}} | M18: {{item.N2O_emission_factor}}
A19: {%tr endfor %}
A22: 编号 | B22: GHG排放类别 | C22: 排放源 | D22: 设施 | E22: CO2排放因子 | F22: 单位
E23: 企业温室气体排放核算与报告指南 钢铁行业
A24: {%tr for item in pro_ef_items %}
A25: {{item.number}} | B25: {{item.emission_source_type_dir}} | C25: {{item.emission_source_dir}} | D25: {{item.emission_facilities_dir}} | E25: {{item.CO2_emission_factor}} | F25: {{item.emission_unit_dir}}
A26: {%tr endfor %}
A28: 编号 | B28: GHG排放类别 | C28: 排放源 | D28: 设施 | E28: HFCs/PFCs | G28: MCF | H28: Bo | I28: 排放因子 | J28: 单位 | K28: 排放因子引用源
E29: EF估计值 | F29: 单位
A30: {%tr for item in fug_ef_items %}
A31: {{item.number}} | B31: {{item.emission_source_type_dir}} | C31: {{item.emission_source_dir}} | D31: {{item.emission_facilities_dir}} | E31: {{item.HFCs_PCFs_emission_factor}} | F31: {{item.emission_unit_dir}} | G31: {{item.MCF}} | H31: {{item.Bo}} | I31: {{item.emission_factor}} | J31: {{item.emission_unit_dir}} | K31: {{item.emission_source_dir}}
A32: {%tr endfor %}
A34: 编号 | B34: GHG排放类别 | C34: 排放源 | D34: 设施 | E34: EF | F34: 单位 | G34: 排放因子引用源
A35: {%tr for item in indir_ef_items %}
A36: {{item.number}} | B36: {{item.emission_source_type_indir}} | C36: {{item.emission_source_indir}} | D36: {{item.emission_facilities_indir}} | E36: {{item.elec_emission_factor}} | F36: {{item.elec_emission_unit}} | G36: {{item.elec_emission_source}}
A37: {%tr endfor %}
A39: 编号 | B39: GHG排放类别 | C39: 排放源 | D39: Activity name | E39: Geography | F39: CO2 | H39: 引用源
F40: 排放因子 | G40: 单位 | H40: 缺省排放因子
A41: {%tr for item in cat1_ef_items %}
A42: {{item.number}} | B42: {{item.emission_source_type_cat1}} | C42: {{item.emission_source_cat1}} | D42: {{item.emission_name_cat1}} | E42: {{item.emission_geo_cat1}} | F42: {{item.cat1_emission_factor}} | G42: {{item.cat1_emission_unit}} | H42: {{item.cat1_emission_source}}
A43: {%tr endfor %}
A45: 编号 | B45: GHG排放类别 | C45: 排放源 | D45: Activity name | E45: CO2 | G45: 引用源
E46: 排放因子 | F46: 单位 | G46: 缺省排放因子
A47: {%tr for item in cat2_ef_items %}
A48: {{item.number}} | B48: {{item.emission_source_type_cat2}} | C48: {{item.emission_source_cat2}} | D48: {{item.emission_name_cat2}} | E48: {{item.cat2_emission_factor}} | F48: {{item.cat2_emission_unit}} | G48: {{item.cat2_emission_source}}
A49: {%tr endfor %}
A51: 编号 | B51: GHG排放类别 | C51: 排放源 | D51: Activity name | E51: Geography | F51: CO2 | H51: 引用源
F52: 排放因子 | G52: 单位 | H52: 缺省排放因子
...

Sheet 温室气体盘查清册
B1: 温室气体盘查清册 | L1: 编号：DY-GHG-2025-01
L2: 版本/版次：A/1
L3: 日期：2025/7/3
B4: 组织名称： | C4: 大冶特殊钢有限公司
B5: 组织边界： | C5: 湖北省黄石市黄石大道316号
B6: 盘查覆盖周期: | C6: 2024年1月1日至2024年12月31日
B7: 编制 ： | E7: 审核： | K7: 核准：
B8: 报告边界 | C8: 运营控制权 | E8: 范围一排放量： | F8: =F14 -> 7122248.8 | K8: 单位：tCO2e
E9: 范围二（基于位置）排放量： | F9: =F47 -> 1069378.7
E10: 范围二（基于市场）排放量： | F10: =F48 -> 1161900.3
B11: 排放 | E11: 范围三排放量： | F11: =SUM(F50,F76,F89,F101,F106,F113,F118,F124,F130,F139,F136) -> 7332407.7
B12: 编号 | C12: 排放源 | D12: 排放设施 | E12: 备注 | F12: 总排放量 | G12: CO2 | H12: CH4 | I12: N2O | J12: HFCs | K12: PFCs | L12: SF6 | M12: NF3
G13: tCO2e
B14: 范围一 直接排放 | F14: =F15+F24+F27+F33 -> 7122248.8 | G14: =G15+G24+G27+G33 -> 7086080.3 | H14: =H15+H24+H27+H33 -> 2569.6835 | I14: =I15+I24+I27+I33 -> 30422.615 | J14: =J15+J24+J27+J33 -> 717.03 | K14: =K15+K24+K27+K33 -> 0 | L14: =L15+L24+L27+L33 -> 2459.16 | M14: =M15+M24+M27+M33 -> 0
B15: 1.1 | C15: 固定源燃烧直接排放 | F15: =SUM(G15:M15) -> 7227644.2 | G15: =SUM(G16:G23) -> 7195204.6 | H15: =SUM(H16:H23) -> 2083.9816 | I15: =SUM(I16:I23) -> 30355.616 | J15: =SUM(J16:J23) -> 0 | K15: =SUM(K16:K23) -> 0 | L15: =SUM(L16:L23) -> 0 | M15: =SUM(M16:M23) -> 0
B16: 1.1.1 | C16: =表1温室气体盘查表!C5 -> 天然气燃烧 | D16: =表1温室气体盘查表!D5 -> 热处理炉（加热炉） | F16: =SUM(G16:M16) -> 38881.726 | G16: =表1温室气体盘查表!AE5 -> 38843.506 | H16: =表1温室气体盘查表!AF5 -> 19.317893 | I16: =表1温室气体盘查表!AG5 -> 18.902455 | J16: =表1温室气体盘查表!AH5 -> 0 | K16: =表1温室气体盘查表!AI5 -> 0 | L16: =表1温室气体盘查表!AJ5 -> 0 | M16: =表1温室气体盘查表!AK5 -> 0
B17: 1.1.2 | C17: =表1温室气体盘查表!C6 -> 液化石油气燃烧 | D17: =表1温室气体盘查表!D6 -> 冶钢宾馆 | F17: =SUM(G17:M17) -> 29.162368 | G17: =表1温室气体盘查表!AE6 -> 29.136879 | H17: =表1温室气体盘查表!AF6 -> 0.012883026 | I17: =表1温室气体盘查表!AG6 -> 0.012605971 | J17: =表1温室气体盘查表!AH6 -> 0 | K17: =表1温室气体盘查表!AI6 -> 0 | L17: =表1温室气体盘查表!AJ6 -> 0 | M17: =表1温室气体盘查表!AK6 -> 0
B18: 1.1.3 | C18: =表1温室气体盘查表!C7 -> 烟煤燃烧 | D18: =表1温室气体盘查表!D7 -> 高炉 | F18: =SUM(G18:M18) -> 925941.32 | G18: =表1温室气体盘查表!AE7 -> 921839.46 | H18: =表1温室气体盘查表!AF7 -> 261.64111 | I18: =表1温室气体盘查表!AG7 -> 3840.2163 | J18: =表1温室气体盘查表!AH7 -> 0 | K18: =表1温室气体盘查表!AI7 -> 0 | L18: =表1温室气体盘查表!AJ7 -> 0 | M18: =表1温室气体盘查表!AK7 -> 0
B19: 1.1.4 | C19: =表1温室气体盘查表!C8 -> 无烟煤燃烧 | D19: =表1温室气体盘查表!D8 -> 高炉、烧结 | F19: =SUM(G19:M19) -> 637282.39 | G19: =表1温室气体盘查表!AE8 -> 634459.27 | H19: =表1温室气体盘查表!AF8 -> 180.07542 | I19: =表1温室气体盘查表!AG8 -> 2643.0424 | J19: =表1温室气体盘查表!AH8 -> 0 | K19: =表1温室气体盘查表!AI8 -> 0 | L19: =表1温室气体盘查表!AJ8 -> 0 | M19: =表1温室气体盘查表!AK8 -> 0
B20: 1.1.5 | C20: =表1温室气体盘查表!C9 -> 洗精煤燃烧 | D20: =表1温室气体盘查表!D9 -> 焦炉 | F20: =SUM(G20:M20) -> 4824841.6 | G20: =表1温室气体盘查表!AE9 -> 4802635.7 | H20: =表1温室气体盘查表!AF9 -> 1416.4222 | I20: =表1温室气体盘查表!AG9 -> 20789.422 | J20: =表1温室气体盘查表!AH9 -> 0 | K20: =表1温室气体盘查表!AI9 -> 0 | L20: =表1温室气体盘查表!AJ9 -> 0 | M20: =表1温室气体盘查表!AK9 -> 0
B21: 1.1.6 | C21: =表1温室气体盘查表!C10 -> 焦炭燃烧 | D21: =表1温室气体盘查表!D10 -> 高炉 | F21: =SUM(G21:M21) -> 439843.84 | G21: =表1温室气体盘查表!AE10 -> 438053.15 | H21: =表1温室气体盘查表!AF10 -> 114.22134 | I21: =表1温室气体盘查表!AG10 -> 1676.4744 | J21: =表1温室气体盘查表!AH10 -> 0 | K21: =表1温室气体盘查表!AI10 -> 0 | L21: =表1温室气体盘查表!AJ10 -> 0 | M21: =表1温室气体盘查表!AK10 -> 0
B22: 1.1.7 | C22: =表1温室气体盘查表!C11 -> 焦屑燃烧 | D22: =表1温室气体盘查表!D11 -> 烧结、高炉 | F22: =SUM(G22:M22) -> 364657.36 | G22: =表1温室气体盘查表!AE11 -> 363172.76 | H22: =表1温室气体盘查表!AF11 -> 94.696449 | I22: =表1温室气体盘查表!AG11 -> 1389.8995 | J22: =表1温室气体盘查表!AH11 -> 0 | K22: =表1温室气体盘查表!AI11 -> 0 | L22: =表1温室气体盘查表!AJ11 -> 0 | M22: =表1温室气体盘查表!AK11 -> 0
B23: 1.1.8 | C23: =表1温室气体盘查表!C12 -> 焦炉煤气燃烧 | D23: =表1温室气体盘查表!D12 -> 外售 | F23: =SUM(G23:M23) -> -3833.1355 | G23: =表1温室气体盘查表!AE12 -> -3828.3759 | H23: =表1温室气体盘查表!AF12 -> -2.4056686 | I23: =表1温室气体盘查表!AG12 -> -2.3539338 | J23: =表1温室气体盘查表!AH12 -> 0 | K23: =表1温室气体盘查表!AI12 -> 0 | L23: =表1温室气体盘查表!AJ12 -> 0 | M23: =表1温室气体盘查表!AK12 -> 0
B24: 1.2 | C24: 移动源燃烧直接排放 | F24: =SUM(G24:M24) -> 4566.5427 | G24: =SUM(G25:G26) -> 4491.7139 | H24: =SUM(H25:H26) -> 7.8293549 | I24: =SUM(I25:I26) -> 66.999448 | J24: =SUM(J25:J26) -> 0 | K24: =SUM(K25:K26) -> 0 | L24: =SUM(L25:L26) -> 0 | M24: =SUM(M25:M26) -> 0
B25: 1.2.1 | C25: =表1温室气体盘查表!C13 -> 0#柴油燃烧 | D25: =表1温室气体盘查表!D13 -> 场内运输 | F25: =SUM(G25:M25) -> 4417.0726 | G25: =表1温室气体盘查表!AE13 -> 4348.2107 | H25: =表1温室气体盘查表!AF13 -> 6.3850041 | I25: =表1温室气体盘查表!AG13 -> 62.476922 | J25: =表1温室气体盘查表!AH13 -> 0 | K25: =表1温室气体盘查表!AI13 -> 0 | L25: =表1温室气体盘查表!AJ13 -> 0 | M25: =表1温室气体盘查表!AK13 -> 0
B26: 1.2.2 | C26: =表1温室气体盘查表!C14 -> 92#汽油燃烧 | D26: =表1温室气体盘查表!D14 -> 公务车 | F26: =SUM(G26:M26) -> 149.47012 | G26: =表1温室气体盘查表!AE14 -> 143.50325 | H26: =表1温室气体盘查表!AF14 -> 1.4443509 | I26: =表1温室气体盘查表!AG14 -> 4.5225266 | J26: =表1温室气体盘查表!AH14 -> 0 | K26: =表1温室气体盘查表!AI14 -> 0 | L26: =表1温室气体盘查表!AJ14 -> 0 | M26: =表1温室气体盘查表!AK14 -> 0
B27: 1.3 | C27: 逸散源直接排放 | F27: =SUM(G27:M27) -> 3654.7226 | G27: =SUM(G28:G32) -> 0.66 | H27: =SUM(H28:H32) -> 477.87259 | I27: =SUM(I28:I32) -> 0 | J27: =SUM(J28:J32) -> 717.03 | K27: =SUM(K28:K32) -> 0 | L27: =SUM(L28:L32) -> 2459.16 | M27: =SUM(M28:M32) -> 0
B28: 1.3.1 | C28: =表1温室气体盘查表!C15 -> 制冷剂逸散（R32） | D28: =表1温室气体盘查表!D15 -> 分体式空调 | F28: =SUM(G28:M28) -> 717.03 | G28: =表1温室气体盘查表!AE15 -> 0 | H28: =表1温室气体盘查表!AF15 -> 0 | I28: =表1温室气体盘查表!AG15 -> 0 | J28: =表1温室气体盘查表!AH15 -> 717.03 | K28: =表1温室气体盘查表!AI15 -> 0 | L28: =表1温室气体盘查表!AJ15 -> 0 | M28: =表1温室气体盘查表!AK15 -> 0
B29: 1.3.2 | C29: =表1温室气体盘查表!C16 -> CO2逸散 | D29: =表1温室气体盘查表!D16 -> 二氧化碳灭火器 | F29: =SUM(G29:M29) -> 0.66 | G29: =表1温室气体盘查表!AE16 -> 0.66 | H29: =表1温室气体盘查表!AF16 -> 0 | I29: =表1温室气体盘查表!AG16 -> 0 | J29: =表1温室气体盘查表!AH16 -> 0 | K29: =表1温室气体盘查表!AI16 -> 0 | L29: =表1温室气体盘查表!AJ16 -> 0 | M29: =表1温室气体盘查表!AK16 -> 0
B30: 1.3.3 | C30: =表1温室气体盘查表!C17 -> CH4逸散 | D30: =表1温室气体盘查表!D17 -> 化粪池 | F30: =SUM(G30:M30) -> 112.29192 | G30: =表1温室气体盘查表!AE17 -> 0 | H30: =表1温室气体盘查表!AF17 -> 112.29192 | I30: =表1温室气体盘查表!AG17 -> 0 | J30: =表1温室气体盘查表!AH17 -> 0 | K30: =表1温室气体盘查表!AI17 -> 0 | L30: =表1温室气体盘查表!AJ17 -> 0 | M30: =表1温室气体盘查表!AK17 -> 0
B31: 1.3.4 | C31: =表1温室气体盘查表!C18 -> CH4逸散 | D31: =表1温室气体盘查表!D18 -> 耗氧池 | F31: =SUM(G31:M31) -> 365.58067 | G31: =表1温室气体盘查表!AE18 -> 0 | H31: =表1温室气体盘查表!AF18 -> 365.58067 | I31: =表1温室气体盘查表!AG18 -> 0 | J31: =表1温室气体盘查表!AH18 -> 0 | K31: =表1温室气体盘查表!AI18 -> 0 | L31: =表1温室气体盘查表!AJ18 -> 0 | M31: =表1温室气体盘查表!AK18 -> 0
B32: 1.3.5 | C32: =表1温室气体盘查表!C19 -> SF6逸散 | D32: =表1温室气体盘查表!D19 -> 高压开关 | F32: =SUM(G32:M32) -> 2459.16 | G32: =表1温室气体盘查表!AE19 -> 0 | H32: =表1温室气体盘查表!AF19 -> 0 | I32: =表1温室气体盘查表!AG19 -> 0 | J32: =表1温室气体盘查表!AH19 -> 0 | K32: =表1温室气体盘查表!AI19 -> 0 | L32: =表1温室气体盘查表!AJ19 -> 2459.16 | M32: =表1温室气体盘查表!AK19 -> 0
B33: 1.4 | C33: 制程排放 | F33: =SUM(G33:M33) -> -113616.67 | G33: =SUM(G34:G45) -> -113616.67 | H33: =SUM(H34:H45) -> 0 | I33: =SUM(I34:I45) -> 0 | J33: =SUM(J34:J45) -> 0 | K33: =SUM(K34:K45) -> 0 | L33: =SUM(L34:L45) -> 0 | M33: =SUM(M34:M45) -> 0
B34: 1.4.1 | C34: =表1温室气体盘查表!C20 -> 石灰石 | D34: =表1温室气体盘查表!D20 -> 石灰窑 | F34: =SUM(G34:M34) -> 8520.9388 | G34: =表1温室气体盘查表!AE20 -> 8520.9388 | H34: =表1温室气体盘查表!AF20 -> 0 | I34: =表1温室气体盘查表!AG20 -> 0 | J34: =表1温室气体盘查表!AH20 -> 0 | K34: =表1温室气体盘查表!AI20 -> 0 | L34: =表1温室气体盘查表!AJ20 -> 0 | M34: =表1温室气体盘查表!AK20 -> 0
B35: 1.4.2 | C35: =表1温室气体盘查表!C21 -> 白云石 | D35: =表1温室气体盘查表!D21 -> 高炉 | F35: =SUM(G35:M35) -> 169593.75 | G35: =表1温室气体盘查表!AE21 -> 169593.75 | H35: =表1温室气体盘查表!AF21 -> 0 | I35: =表1温室气体盘查表!AG21 -> 0 | J35: =表1温室气体盘查表!AH21 -> 0 | K35: =表1温室气体盘查表!AI21 -> 0 | L35: =表1温室气体盘查表!AJ21 -> 0 | M35: =表1温室气体盘查表!AK21 -> 0
B36: 1.4.3 | C36: =表1温室气体盘查表!C22 -> 电极 | D36: =表1温室气体盘查表!D22 -> 炼钢 | F36: =SUM(G36:M36) -> 17447.125 | G36: =表1温室气体盘查表!AE22 -> 17447.125 | H36: =表1温室气体盘查表!AF22 -> 0 | I36: =表1温室气体盘查表!AG22 -> 0 | J36: =表1温室气体盘查表!AH22 -> 0 | K36: =表1温室气体盘查表!AI22 -> 0 | L36: =表1温室气体盘查表!AJ22 -> 0 | M36: =表1温室气体盘查表!AK22 -> 0
B37: 1.4.4 | C37: =表1温室气体盘查表!C23 -> 废钢 | D37: =表1温室气体盘查表!D23 -> 炼钢 | F37: =SUM(G37:M37) -> 39875.738 | G37: =表1温室气体盘查表!AE23 -> 39875.738 | H37: =表1温室气体盘查表!AF23 -> 0 | I37: =表1温室气体盘查表!AG23 -> 0 | J37: =表1温室气体盘查表!AH23 -> 0 | K37: =表1温室气体盘查表!AI23 -> 0 | L37: =表1温室气体盘查表!AJ23 -> 0 | M37: =表1温室气体盘查表!AK23 -> 0
B38: 1.4.5 | C38: =表1温室气体盘查表!C24 -> 锰铁 | D38: =表1温室气体盘查表!D24 -> 炼钢 | F38: =SUM(G38:M38) -> 13114.101 | G38: =表1温室气体盘查表!AE24 -> 13114.101 | H38: =表1温室气体盘查表!AF24 -> 0 | I38: =表1温室气体盘查表!AG24 -> 0 | J38: =表1温室气体盘查表!AH24 -> 0 | K38: =表1温室气体盘查表!AI24 -> 0 | L38: =表1温室气体盘查表!AJ24 -> 0 | M38: =表1温室气体盘查表!AK24 -> 0
B39: 1.4.6 | C39: =表1温室气体盘查表!C25 -> 镍铁 | D39: =表1温室气体盘查表!D25 -> 炼钢 | F39: =SUM(G39:M39) -> 349.46907 | G39: =表1温室气体盘查表!AE25 -> 349.46907 | H39: =表1温室气体盘查表!AF25 -> 0 | I39: =表1温室气体盘查表!AG25 -> 0 | J39: =表1温室气体盘查表!AH25 -> 0 | K39: =表1温室气体盘查表!AI25 -> 0 | L39: =表1温室气体盘查表!AJ25 -> 0 | M39: =表1温室气体盘查表!AK25 -> 0
B40: 1.4.7 | C40: =表1温室气体盘查表!C26 -> 铬铁 | D40: =表1温室气体盘查表!D26 -> 炼钢 | F40: =SUM(G40:M40) -> 22918.907 | G40: =表1温室气体盘查表!AE26 -> 22918.907 | H40: =表1温室气体盘查表!AF26 -> 0 | I40: =表1温室气体盘查表!AG26 -> 0 | J40: =表1温室气体盘查表!AH26 -> 0 | K40: =表1温室气体盘查表!AI26 -> 0 | L40: =表1温室气体盘查表!AJ26 -> 0 | M40: =表1温室气体盘查表!AK26 -> 0
...

Sheet 表1温室气体盘查表
A1: 温室气体盘查表
A2: 编号 | B2: GHG排放类别 | C2: 排放源 | D2: 设施 | E2: 报告边界 | F2: 活动数据 | H2: 排放因子&系数 | AE2: 排放量
H3: CO2 | K3: CH4 | N3: N2O | Q3: HFCs | U3: PFCs | Y3: SF6 | AB3: NF3 | AE3: =H3 -> CO2 | AF3: =K3 -> CH4 | AG3: =N3 -> N2O | AH3: =Q3 -> HFCs | AI3: =U3 -> PFCs | AJ3: =Y3 -> SF6 | AK3: =AB3 -> NF3 | AL3: 总量
F4: 数值 | G4: 计量单位 | H4: EF | I4: 计量单位 | J4: GWP | K4: EF | L4: 计量单位 | M4: GWP | N4: EF | O4: 计量单位 | P4: GWP | Q4: EF | R4: 计量单位 | S4: GWP | T4: 型号 | U4: EF | V4: 计量单位 | W4: GWP | X4: 型号 | Y4: EF | Z4: 计量单位 | AA4: GWP | AB4: EF | AC4: 计量单位 | AD4: GWP | AE4: tCO2e
A5: 1 | B5: 固定燃烧 | C5: 天然气燃烧 | D5: 热处理炉（加热炉） | E5: 范围一 | F5: 1796.49 | G5: 10000Nm3 | H5: ='附表2-EF'!L5 -> 21.621888 | I5: tCO2/10000Nm3 | J5: ='附表1-GWP TABLE'!E3 -> 1 | K5: ='附表2-EF'!M5 -> 0.0003854169 | M5: ='附表1-GWP TABLE'!E4 -> 27.9 | N5: ='附表2-EF'!N5 -> 3.854169e-05 | P5: ='附表1-GWP TABLE'!E5 -> 273 | AE5: =F5*H5*J5 -> 38843.506 | AF5: =F5*K5*M5 -> 19.317893 | AG5: =F5*N5*P5 -> 18.902455 | AH5: =F5*Q5*S5 -> 0 | AI5: =F5*U5*W5 -> 0 | AJ5: =F5*Y5*AA5 -> 0 | AK5: =F5*AB5*AD5 -> 0 | AL5: =SUM(AE5:AK5) -> 38881.726
A6: 2 | B6: 固定燃烧 | C6: 液化石油气燃烧 | D6: 冶钢宾馆 | E6: 范围一 | F6: =ROUND(9.391,2) -> 9.39 | G6: t | H6: ='附表2-EF'!L6 -> 3.102969 | I6: tCO2/t | J6: 1 | K6: ='附表2-EF'!M6 -> 4.917542e-05 | M6: ='附表1-GWP TABLE'!E4 -> 27.9 | N6: ='附表2-EF'!N6 -> 4.917542e-06 | P6: ='附表1-GWP TABLE'!E5 -> 273 | AE6: =F6*H6*J6 -> 29.136879 | AF6: =F6*K6*M6 -> 0.012883026 | AG6: =F6*N6*P6 -> 0.012605971 | AH6: =F6*Q6*S6 -> 0 | AI6: =F6*U6*W6 -> 0 | AJ6: =F6*Y6*AA6 -> 0 | AK6: =F6*AB6*AD6 -> 0 | AL6: =SUM(AE6:AK6) -> 29.162368
A7: 3 | B7: 固定燃烧 | C7: 烟煤燃烧 | D7: 高炉 | E7: 范围一 | F7: =ROUND(333590.27/(1-0.1641),2) -> 399079.16 | G7: t | H7: ='附表2-EF'!L7 -> 2.3099163 | I7: tCO2/t | J7: ='附表1-GWP TABLE'!E3 -> 1 | K7: ='附表2-EF'!M7 -> 2.349864e-05 | M7: ='附表1-GWP TABLE'!E4 -> 27.9 | N7: ='附表2-EF'!N7 -> 3.524796e-05 | P7: ='附表1-GWP TABLE'!E5 -> 273 | AE7: =F7*H7*J7 -> 921839.46 | AF7: =F7*K7*M7 -> 261.64111 | AG7: =F7*N7*P7 -> 3840.2163 | AH7: =F7*Q7*S7 -> 0 | AI7: =F7*U7*W7 -> 0 | AJ7: =F7*Y7*AA7 -> 0 | AK7: =F7*AB7*AD7 -> 0 | AL7: =SUM(AE7:AK7) -> 925941.32
A8: 4 | B8: 固定燃烧 | C8: 无烟煤燃烧 | D8: 高炉、烧结 | E8: 范围一 | F8: =ROUND(235649.69/(1-0.0955),2) -> 260530.34 | G8: t | H8: ='附表2-EF'!L8 -> 2.4352606 | I8: tCO2/t | J8: ='附表1-GWP TABLE'!E3 -> 1 | K8: ='附表2-EF'!M8 -> 2.477376e-05 | M8: ='附表1-GWP TABLE'!E4 -> 27.9 | N8: ='附表2-EF'!N8 -> 3.716064e-05 | P8: ='附表1-GWP TABLE'!E5 -> 273 | AE8: =F8*H8*J8 -> 634459.27 | AF8: =F8*K8*M8 -> 180.07542 | AG8: =F8*N8*P8 -> 2643.0424 | AH8: =F8*Q8*S8 -> 0 | AI8: =F8*U8*W8 -> 0 | AJ8: =F8*Y8*AA8 -> 0 | AK8: =F8*AB8*AD8 -> 0 | AL8: =SUM(AE8:AK8) -> 637282.39
A9: 5 | B9: 固定燃烧 | C9: 洗精煤燃烧 | D9: 焦炉 | E9: 范围一 | F9: =ROUND(1790850.884/(1-0.08),2) -> 1946577.1 | G9: t | H9: ='附表2-EF'!L9 -> 2.467221 | I9: tCO2/t | J9: ='附表1-GWP TABLE'!E3 -> 1 | K9: ='附表2-EF'!M9 -> 2.608056e-05 | M9: ='附表1-GWP TABLE'!E4 -> 27.9 | N9: ='附表2-EF'!N9 -> 3.912084e-05 | P9: ='附表1-GWP TABLE'!E5 -> 273 | AE9: =F9*H9*J9 -> 4802635.7 | AF9: =F9*K9*M9 -> 1416.4222 | AG9: =F9*N9*P9 -> 20789.422 | AH9: =F9*Q9*S9 -> 0 | AI9: =F9*U9*W9 -> 0 | AJ9: =F9*Y9*AA9 -> 0 | AK9: =F9*AB9*AD9 -> 0 | AL9: =SUM(AE9:AK9) -> 4824841.6
A10: 6 | B10: 固定燃烧 | C10: 焦炭燃烧 | D10: 高炉 | E10: 范围一 | F10: =ROUND(141299.98/(1-0.0284),2) -> 145430.2 | G10: t | H10: ='附表2-EF'!L10 -> 3.0121195 | I10: tCO2/t | J10: ='附表1-GWP TABLE'!E3 -> 1 | K10: ='附表2-EF'!M10 -> 2.815065e-05 | M10: ='附表1-GWP TABLE'!E4 -> 27.9 | N10: ='附表2-EF'!N10 -> 4.2225975e-05 | P10: ='附表1-GWP TABLE'!E5 -> 273 | AE10: =F10*H10*J10 -> 438053.15 | AF10: =F10*K10*M10 -> 114.22134 | AG10: =F10*N10*P10 -> 1676.4744 | AH10: =F10*Q10*S10 -> 0 | AI10: =F10*U10*W10 -> 0 | AJ10: =F10*Y10*AA10 -> 0 | AK10: =F10*AB10*AD10 -> 0 | AL10: =SUM(AE10:AK10) -> 439843.84
A11: 7 | B11: 固定燃烧 | C11: 焦屑燃烧 | D11: 烧结、高炉 | E11: 范围一 | F11: =ROUND(109912.07/(1-0.0884),2) -> 120570.5 | G11: t | H11: ='附表2-EF'!L10 -> 3.0121195 | I11: tCO2/t | J11: ='附表1-GWP TABLE'!E3 -> 1 | K11: ='附表2-EF'!M10 -> 2.815065e-05 | M11: ='附表1-GWP TABLE'!E4 -> 27.9 | N11: ='附表2-EF'!N10 -> 4.2225975e-05 | P11: ='附表1-GWP TABLE'!E5 -> 273 | AE11: =F11*H11*J11 -> 363172.76 | AF11: =F11*K11*M11 -> 94.696449 | AG11: =F11*N11*P11 -> 1389.8995 | AH11: =F11*Q11*S11 -> 0 | AI11: =F11*U11*W11 -> 0 | AJ11: =F11*Y11*AA11 -> 0 | AK11: =F11*AB11*AD11 -> 0 | AL11: =SUM(AE11:AK11) -> 364657.36
A12: 8 | B12: 固定燃烧 | C12: 焦炉煤气燃烧 | D12: 外售 | E12: 范围一 | F12: =ROUND(-500.973085,2) -> -500.97 | G12: 10000Nm3 | H12: ='附表2-EF'!L11 -> 7.6419264 | I12: tCO2/10000Nm3 | J12: 1 | K12: ='附表2-EF'!M11 -> 0.00017211546 | M12: ='附表1-GWP TABLE'!E4 -> 27.9 | N12: ='附表2-EF'!N11 -> 1.7211546e-05 | P12: ='附表1-GWP TABLE'!E5 -> 273 | AE12: =F12*H12*J12 -> -3828.3759 | AF12: =F12*K12*M12 -> -2.4056686 | AG12: =F12*N12*P12 -> -2.3539338 | AH12: =F12*Q12*S12 -> 0 | AI12: =F12*U12*W12 -> 0 | AJ12: =F12*Y12*AA12 -> 0 | AK12: =F12*AB12*AD12 -> 0 | AL12: =SUM(AE12:AK12) -> -3833.1355
A13: 9 | B13: 移动燃烧 | C13: 0#柴油燃烧 | D13: 场内运输 | E13: 范围一 | F13: =ROUND(1403.865,2) -> 1403.87 | G13: t | H13: ='附表2-EF'!L12 -> 3.0973029 | I13: tCO2/t | J13: 1 | K13: ='附表2-EF'!M12 -> 0.00016301594 | M13: ='附表1-GWP TABLE'!E4 -> 27.9 | N13: ='附表2-EF'!N12 -> 0.00016301594 | P13: ='附表1-GWP TABLE'!E5 -> 273 | AE13: =F13*H13*J13 -> 4348.2107 | AF13: =F13*K13*M13 -> 6.3850041 | AG13: =F13*N13*P13 -> 62.476922 | AH13: =F13*Q13*S13 -> 0 | AI13: =F13*U13*W13 -> 0 | AJ13: =F13*Y13*AA13 -> 0 | AK13: =F13*AB13*AD13 -> 0 | AL13: =SUM(AE13:AK13) -> 4417.0726
A14: 10 | B14: 移动燃烧 | C14: 92#汽油燃烧 | D14: 公务车 | E14: 范围一 | F14: =ROUND(63298.77*0.775/10^3,2) -> 49.06 | G14: t | H14: ='附表2-EF'!L13 -> 2.925056 | I14: tCO2/t | J14: 1 | K14: ='附表2-EF'!M13 -> 0.001055215 | M14: ='附表1-GWP TABLE'!E4 -> 27.9 | N14: ='附表2-EF'!N13 -> 0.0003376688 | P14: ='附表1-GWP TABLE'!E5 -> 273 | AE14: =F14*H14*J14 -> 143.50325 | AF14: =F14*K14*M14 -> 1.4443509 | AG14: =F14*N14*P14 -> 4.5225266 | AH14: =F14*Q14*S14 -> 0 | AI14: =F14*U14*W14 -> 0 | AJ14: =F14*Y14*AA14 -> 0 | AK14: =F14*AB14*AD14 -> 0 | AL14: =SUM(AE14:AK14) -> 149.47012
A15: 11 | B15: 逸散排放 | C15: 制冷剂逸散（R32） | D15: 分体式空调 | E15: 范围一 | F15: =ROUND(0.9274,2) -> 0.93 | G15: t | Q15: 1 | R15: tHFCs/t | S15: ='附表1-GWP TABLE'!F8 -> 771 | T15: HFC-32 | AE15: =F15*H15*J15 -> 0 | AF15: =F15*K15*M15 -> 0 | AG15: =F15*N15*P15 -> 0 | AH15: =F15*Q15*S15 -> 717.03 | AI15: =F15*U15*W15 -> 0 | AJ15: =F15*Y15*AA15 -> 0 | AK15: =F15*AB15*AD15 -> 0 | AL15: =SUM(AE15:AK15) -> 717.03
A16: 12 | B16: 逸散排放 | C16: CO2逸散 | D16: 二氧化碳灭火器 | E16: 范围一 | F16: =ROUND((127*3+56*5)/1000,2) -> 0.66 | G16: t | H16: ='附表2-EF'!F34 -> 1 | I16: tCO2/t | J16: 1 | AE16: =F16*H16*J16 -> 0.66 | AF16: =F16*K16*M16 -> 0 | AG16: =F16*N16*P16 -> 0 | AH16: =F16*Q16*S16 -> 0 | AI16: =F16*U16*W16 -> 0 | AJ16: =F16*Y16*AA16 -> 0 | AK16: =F16*AB16*AD16 -> 0 | AL16: =SUM(AE16:AK16) -> 0.66
A17: 13 | B17: 逸散排放 | C17: CH4逸散 | D17: 化粪池 | E17: 范围一 | F17: =ROUND(6680*'附表2-EF'!J38*251/10^6*8/24,2) -> 22.36 | G17: tBOD | K17: ='附表2-EF'!J36 -> 0.18 | L17: tCH4/tBOD | M17: ='附表1-GWP TABLE'!E4 -> 27.9 | AE17: =F17*H17*J17 -> 0 | AF17: =F17*K17*M17 -> 112.29192 | AG17: =F17*N17*P17 -> 0 | AH17: =F17*Q17*S17 -> 0 | AI17: =F17*U17*W17 -> 0 | AJ17: =F17*Y17*AA17 -> 0 | AK17: =F17*AB17*AD17 -> 0 | AL17: =SUM(AE17:AK17) -> 112.29192
A18: 14 | B18: 逸散排放 | C18: CH4逸散 | D18: 耗氧池 | E18: 范围一 | F18: =ROUND((21.7-7.3)/10^6*9700672+(27.5-8.5)/10^6*1843418,2) -> 174.71 | G18: tCOD | K18: ='附表2-EF'!J37 -> 0.075 | L18: tCH4/tCOD | M18: ='附表1-GWP TABLE'!E4 -> 27.9 | AE18: =F18*H18*J18 -> 0 | AF18: =F18*K18*M18 -> 365.58067 | AG18: =F18*N18*P18 -> 0 | AH18: =F18*Q18*S18 -> 0 | AI18: =F18*U18*W18 -> 0 | AJ18: =F18*Y18*AA18 -> 0 | AK18: =F18*AB18*AD18 -> 0 | AL18: =SUM(AE18:AK18) -> 365.58067
A19: 15 | B19: 逸散排放 | C19: SF6逸散 | D19: 高压开关 | E19: 范围一 | F19: =ROUND((56*24+63*300)/1000,2) -> 20.24 | G19: t | Y19: ='附表2-EF'!F33 -> 0.005 | Z19: tSF6/t | AA19: ='附表1-GWP TABLE'!E48 -> 24300 | AE19: =F19*H19*J19 -> 0 | AF19: =F19*K19*M19 -> 0 | AG19: =F19*N19*P19 -> 0 | AH19: =F19*Q19*S19 -> 0 | AI19: =F19*U19*W19 -> 0 | AJ19: =F19*Y19*AA19 -> 2459.16 | AK19: =F19*AB19*AD19 -> 0 | AL19: =SUM(AE19:AK19) -> 2459.16
A20: 16 | B20: 制程排放 | C20: 石灰石 | D20: 石灰窑 | E20: 范围一 | F20: =ROUND(4595.368+7694.12+7076.28,2) -> 19365.77 | G20: t | H20: ='附表2-EF'!F19 -> 0.44 | I20: tCO2/t | J20: 1 | AE20: =F20*H20*J20 -> 8520.9388 | AF20: =F20*K20*M20 -> 0 | AG20: =F20*N20*P20 -> 0 | AH20: =F20*Q20*S20 -> 0 | AI20: =F20*U20*W20 -> 0 | AJ20: =F20*Y20*AA20 -> 0 | AK20: =F20*AB20*AD20 -> 0 | AL20: =SUM(AE20:AK20) -> 8520.9388
A21: 17 | B21: 制程排放 | C21: 白云石 | D21: 高炉 | E21: 范围一 | F21: =ROUND(356289.39,2) -> 356289.39 | G21: t | H21: ='附表2-EF'!F20 -> 0.476 | I21: tCO2/t | J21: 1 | AE21: =F21*H21*J21 -> 169593.75 | AF21: =F21*K21*M21 -> 0 | AG21: =F21*N21*P21 -> 0 | AH21: =F21*Q21*S21 -> 0 | AI21: =F21*U21*W21 -> 0 | AJ21: =F21*Y21*AA21 -> 0 | AK21: =F21*AB21*AD21 -> 0 | AL21: =SUM(AE21:AK21) -> 169593.75
A22: 18 | B22: 制程排放 | C22: 电极 | D22: 炼钢 | E22: 范围一 | F22: =ROUND(4763.07,2) -> 4763.07 | G22: t | H22: ='附表2-EF'!F21 -> 3.663 | I22: tCO2/t | J22: 1 | AE22: =F22*H22*J22 -> 17447.125 | AF22: =F22*K22*M22 -> 0 | AG22: =F22*N22*P22 -> 0 | AH22: =F22*Q22*S22 -> 0 | AI22: =F22*U22*W22 -> 0 | AJ22: =F22*Y22*AA22 -> 0 | AK22: =F22*AB22*AD22 -> 0 | AL22: =SUM(AE22:AK22) -> 17447.125
A23: 19 | B23: 制程排放 | C23: 废钢 | D23: 炼钢 | E23: 范围一 | F23: 1077722.6 | G23: t | H23: ='附表2-EF'!F27 -> 0.037 | I23: tCO2/t | J23: 1 | AE23: =F23*H23*J23 -> 39875.738 | AF23: =F23*K23*M23 -> 0 | AG23: =F23*N23*P23 -> 0 | AH23: =F23*Q23*S23 -> 0 | AI23: =F23*U23*W23 -> 0 | AJ23: =F23*Y23*AA23 -> 0 | AK23: =F23*AB23*AD23 -> 0 | AL23: =SUM(AE23:AK23) -> 39875.738
A24: 20 | B24: 制程排放 | C24: 锰铁 | D24: 炼钢 | E24: 范围一 | F24: =ROUND(47687.636,2) -> 47687.64 | G24: t | H24: ='附表2-EF'!F26 -> 0.275 | I24: tCO2/t | J24: 1 | AE24: =F24*H24*J24 -> 13114.101 | AF24: =F24*K24*M24 -> 0 | AG24: =F24*N24*P24 -> 0 | AH24: =F24*Q24*S24 -> 0 | AI24: =F24*U24*W24 -> 0 | AJ24: =F24*Y24*AA24 -> 0 | AK24: =F24*AB24*AD24 -> 0 | AL24: =SUM(AE24:AK24) -> 13114.101
A25: 21 | B25: 制程排放 | C25: 镍铁 | D25: 炼钢 | E25: 范围一 | F25: =ROUND(9445.106,2) -> 9445.11 | G25: t | H25: ='附表2-EF'!F22 -> 0.037 | I25: tCO2/t | J25: 1 | AE25: =F25*H25*J25 -> 349.46907 | AF25: =F25*K25*M25 -> 0 | AG25: =F25*N25*P25 -> 0 | AH25: =F25*Q25*S25 -> 0 | AI25: =F25*U25*W25 -> 0 | AJ25: =F25*Y25*AA25 -> 0 | AK25: =F25*AB25*AD25 -> 0 | AL25: =SUM(AE25:AK25) -> 349.46907
A26: 22 | B26: 制程排放 | C26: 铬铁 | D26: 炼钢 | E26: 范围一 | F26: 65858.929 | G26: t | H26: ='附表2-EF'!F23 -> 0.348 | I26: tCO2/t | J26: 1 | AE26: =F26*H26*J26 -> 22918.907 | AF26: =F26*K26*M26 -> 0 | AG26: =F26*N26*P26 -> 0 | AH26: =F26*Q26*S26 -> 0 | AI26: =F26*U26*W26 -> 0 | AJ26: =F26*Y26*AA26 -> 0 | AK26: =F26*AB26*AD26 -> 0 | AL26: =SUM(AE26:AK26) -> 22918.907
A27: 23 | B27: 制程排放 | C27: 硅铁 | D27: 炼钢 | E27: 范围一 | F27: =ROUND(10672.477,2) -> 10672.48 | G27: t | H27: ='附表2-EF'!F25 -> 0.007 | I27: tCO2/t | J27: 1 | AE27: =F27*H27*J27 -> 74.70736 | AF27: =F27*K27*M27 -> 0 | AG27: =F27*N27*P27 -> 0 | AH27: =F27*Q27*S27 -> 0 | AI27: =F27*U27*W27 -> 0 | AJ27: =F27*Y27*AA27 -> 0 | AK27: =F27*AB27*AD27 -> 0 | AL27: =SUM(AE27:AK27) -> 74.70736
A28: 24 | B28: 制程排放 | C28: 钼铁 | D28: 炼钢 | E28: 范围一 | F28: 7945.164 | G28: t | H28: ='附表2-EF'!F24 -> 0.018 | I28: tCO2/t | J28: 1 | AE28: =F28*H28*J28 -> 143.01295 | AF28: =F28*K28*M28 -> 0 | AG28: =F28*N28*P28 -> 0 | AH28: =F28*Q28*S28 -> 0 | AI28: =F28*U28*W28 -> 0 | AJ28: =F28*Y28*AA28 -> 0 | AK28: =F28*AB28*AD28 -> 0 | AL28: =SUM(AE28:AK28) -> 143.01295
A29: 25 | B29: 制程排放 | C29: 钢坯 | D29: 固碳产品 | E29: 范围一 | F29: -4332821.9 | G29: t | H29: ='附表2-EF'!F28 -> 0.037 | I29: tCO2/t | J29: 1 | AE29: =F29*H29*J29 -> -160314.41 | AF29: =F29*K29*M29 -> 0 | AG29: =F29*N29*P29 -> 0 | AH29: =F29*Q29*S29 -> 0 | AI29: =F29*U29*W29 -> 0 | AJ29: =F29*Y29*AA29 -> 0 | AK29: =F29*AB29*AD29 -> 0 | AL29: =SUM(AE29:AK29) -> -160314.41
A30: 26 | B30: 制程排放 | C30: 粗苯 | D30: 外售 | E30: 范围一 | F30: -19501.18 | G30: t | H30: ='附表2-EF'!F17 -> 3.382 | I30: tCO2/t | J30: 1 | AE30: =F30*H30*J30 -> -65952.991 | AF30: =F30*K30*M30 -> 0 | AG30: =F30*N30*P30 -> 0 | AH30: =F30*Q30*S30 -> 0 | AI30: =F30*U30*W30 -> 0 | AJ30: =F30*Y30*AA30 -> 0 | AK30: =F30*AB30*AD30 -> 0 | AL30: =SUM(AE30:AK30) -> -65952.991
A31: 27 | B31: 制程排放 | C31: 煤焦油 | D31: 危废处置 | E31: 范围一 | F31: -59054.1 | G31: t | H31: ='附表2-EF'!F18 -> 2.699 | I31: tCO2/t | J31: 1 | AE31: =F31*H31*J31 -> -159387.02 | AF31: =F31*K31*M31 -> 0 | AG31: =F31*N31*P31 -> 0 | AH31: =F31*Q31*S31 -> 0 | AI31: =F31*U31*W31 -> 0 | AJ31: =F31*Y31*AA31 -> 0 | AK31: =F31*AB31*AD31 -> 0 | AL31: =SUM(AE31:AK31) -> -159387.02
A32: 28 | B32: 输入能源间接温室气体排放 | C32: 外购电力（基于位置） | D32: 用电设备 | E32: 范围二 | F32: =ROUND(1992878.77,2) -> 1992878.8 | G32: MWh | H32: ='附表2-EF'!F41 -> 0.5366 | I32: tCO2/MWh | J32: 1 | AE32: =F32*H32*J32 -> 1069378.7 | AF32: =F32*K32*M32 -> 0 | AG32: =F32*N32*P32 -> 0 | AH32: =F32*Q32*S32 -> 0 | AI32: =F32*U32*W32 -> 0 | AJ32: =F32*Y32*AA32 -> 0 | AK32: =F32*AB32*AD32 -> 0 | AL32: =SUM(AE32:AK32) -> 1069378.7
A33: 29 | B33: 输入能源间接温室气体排放 | C33: 外购电力（基于市场） | D33: 用电设备 | E33: 范围二 | F33: =ROUND(1992878.77-8759.35,2) -> 1984119.4 | G33: MWh | H33: ='附表2-EF'!F42 -> 0.5856 | I33: tCO2/MWh | J33: 1 | AE33: =F33*H33*J33 -> 1161900.3 | AF33: =F33*K33*M33 -> 0 | AG33: =F33*N33*P33 -> 0 | AH33: =F33*Q33*S33 -> 0 | AI33: =F33*U33*W33 -> 0 | AJ33: =F33*Y33*AA33 -> 0 | AK33: =F33*AB33*AD33 -> 0 | AL33: =SUM(AE33:AK33) -> 1161900.3
A34: 30 | B34: 外购商品和服务的上游排放 | C34: 铁矿石生产 | D34: 烧结 | E34: 范围三 类别1 | F34: =ROUND(4538211.339,2) -> 4538211.3 | G34: t | H34: ='附表2-EF'!G46 -> 0.098847 | I34: tCO2/t | J34: 1 | AE34: =F34*H34*J34 -> 448588.58 | AF34: =F34*K34*M34 -> 0 | AG34: =F34*N34*P34 -> 0 | AH34: =F34*Q34*S34 -> 0 | AI34: =F34*U34*W34 -> 0 | AJ34: =F34*Y34*AA34 -> 0 | AK34: =F34*AB34*AD34 -> 0 | AL34: =SUM(AE34:AK34) -> 448588.58
A35: 31 | B35: 外购商品和服务的上游排放 | C35: 生石灰生产 | D35: 烧结、转炉、电炉 | E35: 范围三 类别1 | F35: =ROUND(611514.48,2) -> 611514.48 | G35: t | H35: ='附表2-EF'!G47 -> 1.1896699 | I35: tCO2/t | J35: 1 | AE35: =F35*H35*J35 -> 727500.38 | AF35: =F35*K35*M35 -> 0 | AG35: =F35*N35*P35 -> 0 | AH35: =F35*Q35*S35 -> 0 | AI35: =F35*U35*W35 -> 0 | AJ35: =F35*Y35*AA35 -> 0 | AK35: =F35*AB35*AD35 -> 0 | AL35: =SUM(AE35:AK35) -> 727500.38
A36: 32 | B36: 外购商品和服务的上游排放 | C36: 石灰石生产 | D36: 转炉 | E36: 范围三 类别1 | F36: =F20 -> 19365.77 | G36: t | H36: ='附表2-EF'!G48 -> 0.0030299 | I36: tCO2/t | J36: 1 | AE36: =F36*H36*J36 -> 58.676347 | AF36: =F36*K36*M36 -> 0 | AG36: =F36*N36*P36 -> 0 | AH36: =F36*Q36*S36 -> 0 | AI36: =F36*U36*W36 -> 0 | AJ36: =F36*Y36*AA36 -> 0 | AK36: =F36*AB36*AD36 -> 0 | AL36: =SUM(AE36:AK36) -> 58.676347
A37: 33 | B37: 外购商品和服务的上游排放 | C37: 白云石生产 | D37: 烧结、转炉、电炉 | E37: 范围三 类别1 | F37: =F21 -> 356289.39 | G37: t | H37: ='附表2-EF'!G49 -> 0.13033 | I37: tCO2/t | J37: 1 | AE37: =F37*H37*J37 -> 46435.196 | AF37: =F37*K37*M37 -> 0 | AG37: =F37*N37*P37 -> 0 | AH37: =F37*Q37*S37 -> 0 | AI37: =F37*U37*W37 -> 0 | AJ37: =F37*Y37*AA37 -> 0 | AK37: =F37*AB37*AD37 -> 0 | AL37: =SUM(AE37:AK37) -> 46435.196
A38: 34 | B38: 外购商品和服务的上游排放 | C38: 轻烧白云石生产 | D38: 转炉、电炉 | E38: 范围三 类别1 | F38: =ROUND(2786.84,2) -> 2786.84 | G38: t | H38: =H37 -> 0.13033 | I38: tCO2/t | J38: 1 | AE38: =F38*H38*J38 -> 363.20886 | AF38: =F38*K38*M38 -> 0 | AG38: =F38*N38*P38 -> 0 | AH38: =F38*Q38*S38 -> 0 | AI38: =F38*U38*W38 -> 0 | AJ38: =F38*Y38*AA38 -> 0 | AK38: =F38*AB38*AD38 -> 0 | AL38: =SUM(AE38:AK38) -> 363.20886
A39: 35 | B39: 外购商品和服务的上游排放 | C39: 球团生产 | D39: 高炉、转炉 | E39: 范围三 类别1 | F39: =ROUND(685439.89,2) -> 685439.89 | G39: t | H39: ='附表2-EF'!G50 -> 0.10446 | I39: tCO2/t | J39: 1 | AE39: =F39*H39*J39 -> 71601.051 | AF39: =F39*K39*M39 -> 0 | AG39: =F39*N39*P39 -> 0 | AH39: =F39*Q39*S39 -> 0 | AI39: =F39*U39*W39 -> 0 | AJ39: =F39*Y39*AA39 -> 0 | AK39: =F39*AB39*AD39 -> 0 | AL39: =SUM(AE39:AK39) -> 71601.051
A40: 36 | B40: 外购商品和服务的上游排放 | C40: 废钢生产 | D40: 转炉、电炉 | E40: 范围三 类别1 | F40: =F23 -> 1077722.6 | G40: t | H40: ='附表2-EF'!G51 -> 0.074179 | I40: tCO2/t | J40: 1 | AE40: =F40*H40*J40 -> 79944.388 | AF40: =F40*K40*M40 -> 0 | AG40: =F40*N40*P40 -> 0 | AH40: =F40*Q40*S40 -> 0 | AI40: =F40*U40*W40 -> 0 | AJ40: =F40*Y40*AA40 -> 0 | AK40: =F40*AB40*AD40 -> 0 | AL40: =SUM(AE40:AK40) -> 79944.388
...

Sheet 表2.1不确定性评估——基于位置
A1: 不确定性评估表
A2: 编号 | B2: 排放源 | C2: 设施 | D2: 活动数据类别 | E2: 排放因子类别 | F2: 校准频率 | G2: 活动数据级别 | H2: 排放因子级别 | I2: 校准级别 | J2: 平均得分 | K2: 排放量(tCO2e) | L2: 排放量占比 | M2: 加权平均积分
A3: 1 | B3: =表1温室气体盘查表!C5 -> 天然气燃烧 | C3: =表1温室气体盘查表!D5 -> 热处理炉（加热炉） | D3: 自动连续量测 | E3: 国际排放因子 | F3: 校准且合格 | G3: =IF(D3="自动连续量测",6,IF(D3="定期量测/抄表/铭牌",3,1)) -> 6 | H3: =IF(E3="量测/质量平衡排放因子",6,IF(E3="制程/设备排放因子",5,IF(E3="制造商提供的排放因子",4,IF(E3="区域排放因子",3,IF(E3="国家排放因子",2,1))))) -> 1 | I3: =IF(F3="校准且合格",6,IF(F3="未校准",1,3)) -> 6 | J3: =AVERAGE(G3:I3) -> 4.3333333 | K3: =表1温室气体盘查表!AL5 -> 38881.726 | L3: =K3/$K$101 -> 0.0025046146 | M3: =J3*L3 -> 0.01085333
A4: 2 | B4: =表1温室气体盘查表!C6 -> 液化石油气燃烧 | C4: =表1温室气体盘查表!D6 -> 冶钢宾馆 | D4: 定期量测/抄表/铭牌 | E4: 国际排放因子 | F4: 校准且合格 | G4: =IF(D4="自动连续量测",6,IF(D4="定期量测/抄表/铭牌",3,1)) -> 3 | H4: =IF(E4="量测/质量平衡排放因子",6,IF(E4="制程/设备排放因子",5,IF(E4="制造商提供的排放因子",4,IF(E4="区域排放因子",3,IF(E4="国家排放因子",2,1))))) -> 1 | I4: =IF(F4="校准且合格",6,IF(F4="未校准",1,3)) -> 6 | J4: =AVERAGE(G4:I4) -> 3.3333333 | K4: =表1温室气体盘查表!AL6 -> 29.162368 | L4: =K4/$K$101 -> 1.8785301e-06 | M4: =J4*L4 -> 6.2617671e-06
A5: 3 | B5: =表1温室气体盘查表!C7 -> 烟煤燃烧 | C5: =表1温室气体盘查表!D7 -> 高炉 | D5: 自动连续量测 | E5: 国际排放因子 | F5: 校准且合格 | G5: =IF(D5="自动连续量测",6,IF(D5="定期量测/抄表/铭牌",3,1)) -> 6 | H5: =IF(E5="量测/质量平衡排放因子",6,IF(E5="制程/设备排放因子",5,IF(E5="制造商提供的排放因子",4,IF(E5="区域排放因子",3,IF(E5="国家排放因子",2,1))))) -> 1 | I5: =IF(F5="校准且合格",6,IF(F5="未校准",1,3)) -> 6 | J5: =AVERAGE(G5:I5) -> 4.3333333 | K5: =表1温室气体盘查表!AL7 -> 925941.32 | L5: =K5/$K$101 -> 0.059645659 | M5: =J5*L5 -> 0.25846452
A6: 4 | B6: =表1温室气体盘查表!C8 -> 无烟煤燃烧 | C6: =表1温室气体盘查表!D8 -> 高炉、烧结 | D6: 自动连续量测 | E6: 国际排放因子 | F6: 校准且合格 | G6: =IF(D6="自动连续量测",6,IF(D6="定期量测/抄表/铭牌",3,1)) -> 6 | H6: =IF(E6="量测/质量平衡排放因子",6,IF(E6="制程/设备排放因子",5,IF(E6="制造商提供的排放因子",4,IF(E6="区域排放因子",3,IF(E6="国家排放因子",2,1))))) -> 1 | I6: =IF(F6="校准且合格",6,IF(F6="未校准",1,3)) -> 6 | J6: =AVERAGE(G6:I6) -> 4.3333333 | K6: =表1温室气体盘查表!AL8 -> 637282.39 | L6: =K6/$K$101 -> 0.041051336 | M6: =J6*L6 -> 0.17788912
A7: 5 | B7: =表1温室气体盘查表!C9 -> 洗精煤燃烧 | C7: =表1温室气体盘查表!D9 -> 焦炉 | D7: 自动连续量测 | E7: 国际排放因子 | F7: 校准且合格 | G7: =IF(D7="自动连续量测",6,IF(D7="定期量测/抄表/铭牌",3,1)) -> 6 | H7: =IF(E7="量测/质量平衡排放因子",6,IF(E7="制程/设备排放因子",5,IF(E7="制造商提供的排放因子",4,IF(E7="区域排放因子",3,IF(E7="国家排放因子",2,1))))) -> 1 | I7: =IF(F7="校准且合格",6,IF(F7="未校准",1,3)) -> 6 | J7: =AVERAGE(G7:I7) -> 4.3333333 | K7: =表1温室气体盘查表!AL9 -> 4824841.6 | L7: =K7/$K$101 -> 0.31079816 | M7: =J7*L7 -> 1.346792
A8: 6 | B8: =表1温室气体盘查表!C10 -> 焦炭燃烧 | C8: =表1温室气体盘查表!D10 -> 高炉 | D8: 自动连续量测 | E8: 国际排放因子 | F8: 校准且合格 | G8: =IF(D8="自动连续量测",6,IF(D8="定期量测/抄表/铭牌",3,1)) -> 6 | H8: =IF(E8="量测/质量平衡排放因子",6,IF(E8="制程/设备排放因子",5,IF(E8="制造商提供的排放因子",4,IF(E8="区域排放因子",3,IF(E8="国家排放因子",2,1))))) -> 1 | I8: =IF(F8="校准且合格",6,IF(F8="未校准",1,3)) -> 6 | J8: =AVERAGE(G8:I8) -> 4.3333333 | K8: =表1温室气体盘查表!AL10 -> 439843.84 | L8: =K8/$K$101 -> 0.028333087 | M8: =J8*L8 -> 0.12277671
A9: 7 | B9: =表1温室气体盘查表!C11 -> 焦屑燃烧 | C9: =表1温室气体盘查表!D11 -> 烧结、高炉 | D9: 自动连续量测 | E9: 国际排放因子 | F9: 校准且合格 | G9: =IF(D9="自动连续量测",6,IF(D9="定期量测/抄表/铭牌",3,1)) -> 6 | H9: =IF(E9="量测/质量平衡排放因子",6,IF(E9="制程/设备排放因子",5,IF(E9="制造商提供的排放因子",4,IF(E9="区域排放因子",3,IF(E9="国家排放因子",2,1))))) -> 1 | I9: =IF(F9="校准且合格",6,IF(F9="未校准",1,3)) -> 6 | J9: =AVERAGE(G9:I9) -> 4.3333333 | K9: =表1温室气体盘查表!AL11 -> 364657.36 | L9: =K9/$K$101 -> 0.023489856 | M9: =J9*L9 -> 0.10178938
A10: 8 | B10: =表1温室气体盘查表!C12 -> 焦炉煤气燃烧 | C10: =表1温室气体盘查表!D12 -> 外售 | D10: 自动连续量测 | E10: 国际排放因子 | F10: 校准且合格 | G10: =IF(D10="自动连续量测",6,IF(D10="定期量测/抄表/铭牌",3,1)) -> 6 | H10: =IF(E10="量测/质量平衡排放因子",6,IF(E10="制程/设备排放因子",5,IF(E10="制造商提供的排放因子",4,IF(E10="区域排放因子",3,IF(E10="国家排放因子",2,1))))) -> 1 | I10: =IF(F10="校准且合格",6,IF(F10="未校准",1,3)) -> 6 | J10: =AVERAGE(G10:I10) -> 4.3333333 | K10: =表1温室气体盘查表!AL12 -> -3833.1355 | L10: =K10/$K$101 -> -0.00024691618 | M10: =J10*L10 -> -0.0010699701
A11: 9 | B11: =表1温室气体盘查表!C13 -> 0#柴油燃烧 | C11: =表1温室气体盘查表!D13 -> 场内运输 | D11: 定期量测/抄表/铭牌 | E11: 国际排放因子 | F11: 校准但不合格/未校准但数据可查证 | G11: =IF(D11="自动连续量测",6,IF(D11="定期量测/抄表/铭牌",3,1)) -> 3 | H11: =IF(E11="量测/质量平衡排放因子",6,IF(E11="制程/设备排放因子",5,IF(E11="制造商提供的排放因子",4,IF(E11="区域排放因子",3,IF(E11="国家排放因子",2,1))))) -> 1 | I11: =IF(F11="校准且合格",6,IF(F11="未校准",1,3)) -> 3 | J11: =AVERAGE(G11:I11) -> 2.3333333 | K11: =表1温室气体盘查表!AL13 -> 4417.0726 | L11: =K11/$K$101 -> 0.00028453121 | M11: =J11*L11 -> 0.00066390616
A12: 10 | B12: =表1温室气体盘查表!C14 -> 92#汽油燃烧 | C12: =表1温室气体盘查表!D14 -> 公务车 | D12: 定期量测/抄表/铭牌 | E12: 国际排放因子 | F12: 校准但不合格/未校准但数据可查证 | G12: =IF(D12="自动连续量测",6,IF(D12="定期量测/抄表/铭牌",3,1)) -> 3 | H12: =IF(E12="量测/质量平衡排放因子",6,IF(E12="制程/设备排放因子",5,IF(E12="制造商提供的排放因子",4,IF(E12="区域排放因子",3,IF(E12="国家排放因子",2,1))))) -> 1 | I12: =IF(F12="校准且合格",6,IF(F12="未校准",1,3)) -> 3 | J12: =AVERAGE(G12:I12) -> 2.3333333 | K12: =表1温室气体盘查表!AL14 -> 149.47012 | L12: =K12/$K$101 -> 9.6283035e-06 | M12: =J12*L12 -> 2.2466042e-05
A13: 11 | B13: =表1温室气体盘查表!C15 -> 制冷剂逸散（R32） | C13: =表1温室气体盘查表!D15 -> 分体式空调 | D13: 定期量测/抄表/铭牌 | E13: 国家排放因子 | F13: 校准且合格 | G13: =IF(D13="自动连续量测",6,IF(D13="定期量测/抄表/铭牌",3,1)) -> 3 | H13: =IF(E13="量测/质量平衡排放因子",6,IF(E13="制程/设备排放因子",5,IF(E13="制造商提供的排放因子",4,IF(E13="区域排放因子",3,IF(E13="国家排放因子",2,1))))) -> 2 | I13: =IF(F13="校准且合格",6,IF(F13="未校准",1,3)) -> 6 | J13: =AVERAGE(G13:I13) -> 3.6666667 | K13: =表1温室气体盘查表!AL15 -> 717.03 | L13: =K13/$K$101 -> 4.6188377e-05 | M13: =J13*L13 -> 0.00016935738
A14: 12 | B14: =表1温室气体盘查表!C16 -> CO2逸散 | C14: =表1温室气体盘查表!D16 -> 二氧化碳灭火器 | D14: 定期量测/抄表/铭牌 | E14: 国家排放因子 | F14: 校准且合格 | G14: =IF(D14="自动连续量测",6,IF(D14="定期量测/抄表/铭牌",3,1)) -> 3 | H14: =IF(E14="量测/质量平衡排放因子",6,IF(E14="制程/设备排放因子",5,IF(E14="制造商提供的排放因子",4,IF(E14="区域排放因子",3,IF(E14="国家排放因子",2,1))))) -> 2 | I14: =IF(F14="校准且合格",6,IF(F14="未校准",1,3)) -> 6 | J14: =AVERAGE(G14:I14) -> 3.6666667 | K14: =表1温室气体盘查表!AL16 -> 0.66 | L14: =K14/$K$101 -> 4.2514719e-08 | M14: =J14*L14 -> 1.558873e-07
... A30: 28 | B30: =表1温室气体盘查表!C32 -> 外购电力（基于位置） | C30: =表1温室气体盘查表!D32 -> 用电设备 | D30: 自动连续量测 | E30: 国家排放因子 | F30: 校准且合格 | G30: =IF(D30="自动连续量测",6,IF(D30="定期量测/抄表/铭牌",3,1)) -> 6 | H30: =IF(E30="量测/质量平衡排放因子",6,IF(E30="制程/设备排放因子",5,IF(E30="制造商提供的排放因子",4,IF(E30="区域排放因子",3,IF(E30="国家排放因子",2,1))))) -> 2 | I30: =IF(F30="校准且合格",6,IF(F30="未校准",1,3)) -> 6 | J30: =AVERAGE(G30:I30) -> 4.6666667 | K30: =表1温室气体盘查表!AL32 -> 1069378.7 | L30: =K30/$K$101 -> 0.068885359 | M30: =J30*L30 -> 0.32146501
A31: 29 | B31: =表1温室气体盘查表!C34 -> 铁矿石生产 | C31: =表1温室气体盘查表!D34 -> 烧结 | D31: 定期量测/抄表/铭牌 | E31: 国家排放因子 | F31: 校准且合格 | G31: =IF(D31="自动连续量测",6,IF(D31="定期量测/抄表/铭牌",3,1)) -> 3 | H31: =IF(E31="量测/质量平衡排放因子",6,IF(E31="制程/设备排放因子",5,IF(E31="制造商提供的排放因子",4,IF(E31="区域排放因子",3,IF(E31="国家排放因子",2,1))))) -> 2 | I31: =IF(F31="校准且合格",6,IF(F31="未校准",1,3)) -> 6 | J31: =AVERAGE(G31:I31) -> 3.6666667 | K31: =表1温室气体盘查表!AL34 -> 448588.58 | L31: =K31/$K$101 -> 0.02889639 | M31: =J31*L31 -> 0.10595343
A32: 30 | B32: =表1温室气体盘查表!C35 -> 生石灰生产 | C32: =表1温室气体盘查表!D35 -> 烧结、转炉、电炉 | D32: 定期量测/抄表/铭牌 | E32: 国际排放因子 | F32: 校准且合格 | G32: =IF(D32="自动连续量测",6,IF(D32="定期量测/抄表/铭牌",3,1)) -> 3 | H32: =IF(E32="量测/质量平衡排放因子",6,IF(E32="制程/设备排放因子",5,IF(E32="制造商提供的排放因子",4,IF(E32="区域排放因子",3,IF(E32="国家排放因子",2,1))))) -> 1 | I32: =IF(F32="校准且合格",6,IF(F32="未校准",1,3)) -> 6 | J32: =AVERAGE(G32:I32) -> 3.3333333 | K32: =表1温室气体盘查表!AL35 -> 727500.38 | L32: =K32/$K$101 -> 0.04686284 | M32: =J32*L32 -> 0.15620947
A33: 31 | B33: =表1温室气体盘查表!C36 -> 石灰石生产 | C33: =表1温室气体盘查表!D36 -> 转炉 | D33: 定期量测/抄表/铭牌 | E33: 国际排放因子 | F33: 校准且合格 | G33: =IF(D33="自动连续量测",6,IF(D33="定期量测/抄表/铭牌",3,1)) -> 3 | H33: =IF(E33="量测/质量平衡排放因子",6,IF(E33="制程/设备排放因子",5,IF(E33="制造商提供的排放因子",4,IF(E33="区域排放因子",3,IF(E33="国家排放因子",2,1))))) -> 1 | I33: =IF(F33="校准且合格",6,IF(F33="未校准",1,3)) -> 6 | J33: =AVERAGE(G33:I33) -> 3.3333333 | K33: =表1温室气体盘查表!AL36 -> 58.676347 | L33: =K33/$K$101 -> 3.7797097e-06 | M33: =J33*L33 -> 1.2599032e-05
A34: 32 | B34: =表1温室气体盘查表!C37 -> 白云石生产 | C34: =表1温室气体盘查表!D37 -> 烧结、转炉、电炉 | D34: 定期量测/抄表/铭牌 | E34: 国际排放因子 | F34: 校准且合格 | G34: =IF(D34="自动连续量测",6,IF(D34="定期量测/抄表/铭牌",3,1)) -> 3 | H34: =IF(E34="量测/质量平衡排放因子",6,IF(E34="制程/设备排放因子",5,IF(E34="制造商提供的排放因子",4,IF(E34="区域排放因子",3,IF(E34="国家排放因子",2,1))))) -> 1 | I34: =IF(F34="校准且合格",6,IF(F34="未校准",1,3)) -> 6 | J34: =AVERAGE(G34:I34) -> 3.3333333 | K34: =表1温室气体盘查表!AL37 -> 46435.196 | L34: =K34/$K$101 -> 0.0029911808 | M34: =J34*L34 -> 0.0099706026
A35: 33 | B35: =表1温室气体盘查表!C38 -> 轻烧白云石生产 | C35: =表1温室气体盘查表!D38 -> 转炉、电炉 | D35: 定期量测/抄表/铭牌 | E35: 国际排放因子 | F35: 校准且合格 | G35: =IF(D35="自动连续量测",6,IF(D35="定期量测/抄表/铭牌",3,1)) -> 3 | H35: =IF(E35="量测/质量平衡排放因子",6,IF(E35="制程/设备排放因子",5,IF(E35="制造商提供的排放因子",4,IF(E35="区域排放因子",3,IF(E35="国家排放因子",2,1))))) -> 1 | I35: =IF(F35="校准且合格",6,IF(F35="未校准",1,3)) -> 6 | J35: =AVERAGE(G35:I35) -> 3.3333333 | K35: =表1温室气体盘查表!AL38 -> 363.20886 | L35: =K35/$K$101 -> 2.3396549e-05 | M35: =J35*L35 -> 7.7988498e-05
A36: 34 | B36: =表1温室气体盘查表!C39 -> 球团生产 | C36: =表1温室气体盘查表!D39 -> 高炉、转炉 | D36: 定期量测/抄表/铭牌 | E36: 国际排放因子 | F36: 校准且合格 | G36: =IF(D36="自动连续量测",6,IF(D36="定期量测/抄表/铭牌",3,1)) -> 3 | H36: =IF(E36="量测/质量平衡排放因子",6,IF(E36="制程/设备排放因子",5,IF(E36="制造商提供的排放因子",4,IF(E36="区域排放因子",3,IF(E36="国家排放因子",2,1))))) -> 1 | I36: =IF(F36="校准且合格",6,IF(F36="未校准",1,3)) -> 6 | J36: =AVERAGE(G36:I36) -> 3.3333333 | K36: =表1温室气体盘查表!AL39 -> 71601.051 | L36: =K36/$K$101 -> 0.0046122705 | M36: =J36*L36 -> 0.015374235
A37: 35 | B37: =表1温室气体盘查表!C40 -> 废钢生产 | C37: =表1温室气体盘查表!D40 -> 转炉、电炉 | D37: 定期量测/抄表/铭牌 | E37: 国际排放因子 | F37: 校准且合格 | G37: =IF(D37="自动连续量测",6,IF(D37="定期量测/抄表/铭牌",3,1)) -> 3 | H37: =IF(E37="量测/质量平衡排放因子",6,IF(E37="制程/设备排放因子",5,IF(E37="制造商提供的排放因子",4,IF(E37="区域排放因子",3,IF(E37="国家排放因子",2,1))))) -> 1 | I37: =IF(F37="校准且合格",6,IF(F37="未校准",1,3)) -> 6 | J37: =AVERAGE(G37:I37) -> 3.3333333 | K37: =表1温室气体盘查表!AL40 -> 79944.388 | L37: =K37/$K$101 -> 0.005149717 | M37: =J37*L37 -> 0.017165723
A38: 36 | B38: =表1温室气体盘查表!C41 -> 电极生产 | C38: =表1温室气体盘查表!D41 -> 转炉、电炉 | D38: 定期量测/抄表/铭牌 | E38: 国际排放因子 | F38: 校准且合格 | G38: =IF(D38="自动连续量测",6,IF(D38="定期量测/抄表/铭牌",3,1)) -> 3 | H38: =IF(E38="量测/质量平衡排放因子",6,IF(E38="制程/设备排放因子",5,IF(E38="制造商提供的排放因子",4,IF(E38="区域排放因子",3,IF(E38="国家排放因子",2,1))))) -> 1 | I38: =IF(F38="校准且合格",6,IF(F38="未校准",1,3)) -> 6 | J38: =AVERAGE(G38:I38) -> 3.3333333 | K38: =表1温室气体盘查表!AL41 -> 37742.812 | L38: =K38/$K$101 -> 0.0024312501 | M38: =J38*L38 -> 0.0081041669
A39: 37 | B39: =表1温室气体盘查表!C42 -> 锰铁生产 | C39: =表1温室气体盘查表!D42 -> 转炉、电炉 | D39: 定期量测/抄表/铭牌 | E39: 国际排放因子 | F39: 校准且合格 | G39: =IF(D39="自动连续量测",6,IF(D39="定期量测/抄表/铭牌",3,1)) -> 3 | H39: =IF(E39="量测/质量平衡排放因子",6,IF(E39="制程/设备排放因子",5,IF(E39="制造商提供的排放因子",4,IF(E39="区域排放因子",3,IF(E39="国家排放因子",2,1))))) -> 1 | I39: =IF(F39="校准且合格",6,IF(F39="未校准",1,3)) -> 6 | J39: =AVERAGE(G39:I39) -> 3.3333333 | K39: =表1温室气体盘查表!AL42 -> 141868.58 | L39: =K39/$K$101 -> 0.0091386407 | M39: =J39*L39 -> 0.030462136
A40: 38 | B40: =表1温室气体盘查表!C43 -> 镍铁生产 | C40: =表1温室气体盘查表!D43 -> 转炉、电炉 | D40: 定期量测/抄表/铭牌 | E40: 国际排放因子 | F40: 校准且合格 | G40: =IF(D40="自动连续量测",6,IF(D40="定期量测/抄表/铭牌",3,1)) -> 3 | H40: =IF(E40="量测/质量平衡排放因子",6,IF(E40="制程/设备排放因子",5,IF(E40="制造商提供的排放因子",4,IF(E40="区域排放因子",3,IF(E40="国家排放因子",2,1))))) -> 1 | I40: =IF(F40="校准且合格",6,IF(F40="未校准",1,3)) -> 6 | J40: =AVERAGE(G40:I40) -> 3.3333333 | K40: =表1温室气体盘查表!AL43 -> 84819.123 | L40: =K40/$K$101 -> 0.0054637291 | M40: =J40*L40 -> 0.01821243
A41: 39 | B41: =表1温室气体盘查表!C44 -> 铬铁生产 | C41: =表1温室气体盘查表!D44 -> 转炉、电炉 | D41: 定期量测/抄表/铭牌 | E41: 国际排放因子 | F41: 校准且合格 | G41: =IF(D41="自动连续量测",6,IF(D41="定期量测/抄表/铭牌",3,1)) -> 3 | H41: =IF(E41="量测/质量平衡排放因子",6,IF(E41="制程/设备排放因子",5,IF(E41="制造商提供的排放因子",4,IF(E41="区域排放因子",3,IF(E41="国家排放因子",2,1))))) -> 1 | I41: =IF(F41="校准且合格",6,IF(F41="未校准",1,3)) -> 6 | J41: =AVERAGE(G41:I41) -> 3.3333333 | K41: =表1温室气体盘查表!AL44 -> 345101.44 | L41: =K41/$K$101 -> 0.022230138 | M41: =J41*L41 -> 0.074100459
A42: 40 | B42: =表1温室气体盘查表!C45 -> 萤石生产 | C42: =表1温室气体盘查表!D45 -> 转炉、电炉 | D42: 定期量测/抄表/铭牌 | E42: 国际排放因子 | F42: 校准且合格 | G42: =IF(D42="自动连续量测",6,IF(D42="定期量测/抄表/铭牌",3,1)) -> 3 | H42: =IF(E42="量测/质量平衡排放因子",6,IF(E42="制程/设备排放因子",5,IF(E42="制造商提供的排放因子",4,IF(E42="区域排放因子",3,IF(E42="国家排放因子",2,1))))) -> 1 | I42: =IF(F42="校准且合格",6,IF(F42="未校准",1,3)) -> 6 | J42: =AVERAGE(G42:I42) -> 3.3333333 | K42: =表1温室气体盘查表!AL45 -> 685.06219 | L42: =K42/$K$101 -> 4.4129131e-05 | M42: =J42*L42 -> 0.0001470971
... A100: 98 | B100: =表1温室气体盘查表!C103 -> 产品报废 | C100: =表1温室气体盘查表!D103 -> 下游钢铁厂 | D100: 自行推估 | E100: 国际排放因子 | F100: 校准但不合格/未校准但数据可查证 | G100: =IF(D100="自动连续量测",6,IF(D100="定期量测/抄表/铭牌",3,1)) -> 1 | H100: =IF(E100="量测/质量平衡排放因子",6,IF(E100="制程/设备排放因子",5,IF(E100="制造商提供的排放因子",4,IF(E100="区域排放因子",3,IF(E100="国家排放因子",2,1))))) -> 1 | I100: =IF(F100="校准且合格",6,IF(F100="未校准",1,3)) -> 3 | J100: =AVERAGE(G100:I100) -> 1.6666667 | K100: =表1温室气体盘查表!AL103 -> 3747.347 | L100: =K100/$K$101 -> 0.00024139 | M100: =J100*L100 -> 0.00040231667
K101: =SUM(K3:K100) -> 15524035 | L101: 加权合计 | M101: =SUM(M3:M100) -> 3.717969 | N101: uncertainty_score_location_based
L102: 加权等级 | M102: =IF(M101<2,"差",IF(M101<3,"一般",IF(M101<4,"良",IF(M101<5,"优","优+")))) -> 良
A112: 优+ | B112: >=5.0
A113: 优 | B113: <5.0,>=4.0
A114: 良 | B114: <4.0,>=3.0
A115: 一般 | B115: <3.0,>=2.0
A116: 差 | B116: <2.0

Sheet 表2.1不确定性评估——基于市场
A1: 不确定性评估表
A2: 编号 | B2: 排放源 | C2: 设施 | D2: 活动数据类别 | E2: 排放因子类别 | F2: 校准频率 | G2: 活动数据级别 | H2: 排放因子级别 | I2: 校准级别 | J2: 平均得分 | K2: 排放量(tCO2e) | L2: 排放量占比 | M2: 加权平均积分
A3: 1 | B3: =表1温室气体盘查表!C5 -> 天然气燃烧 | C3: =表1温室气体盘查表!D5 -> 热处理炉（加热炉） | D3: 自动连续量测 | E3: 国际排放因子 | F3: 校准且合格 | G3: =IF(D3="自动连续量测",6,IF(D3="定期量测/抄表/铭牌",3,1)) -> 6 | H3: =IF(E3="量测/质量平衡排放因子",6,IF(E3="制程/设备排放因子",5,IF(E3="制造商提供的排放因子",4,IF(E3="区域排放因子",3,IF(E3="国家排放因子",2,1))))) -> 1 | I3: =IF(F3="校准且合格",6,IF(F3="未校准",1,3)) -> 6 | J3: =AVERAGE(G3:I3) -> 4.3333333 | K3: =表1温室气体盘查表!AL5 -> 38881.726 | L3: =K3/$K$101 -> 0.0024897758 | M3: =J3*L3 -> 0.010789029
A4: 2 | B4: =表1温室气体盘查表!C6 -> 液化石油气燃烧 | C4: =表1温室气体盘查表!D6 -> 冶钢宾馆 | D4: 定期量测/抄表/铭牌 | E4: 国际排放因子 | F4: 校准且合格 | G4: =IF(D4="自动连续量测",6,IF(D4="定期量测/抄表/铭牌",3,1)) -> 3 | H4: =IF(E4="量测/质量平衡排放因子",6,IF(E4="制程/设备排放因子",5,IF(E4="制造商提供的排放因子",4,IF(E4="区域排放因子",3,IF(E4="国家排放因子",2,1))))) -> 1 | I4: =IF(F4="校准且合格",6,IF(F4="未校准",1,3)) -> 6 | J4: =AVERAGE(G4:I4) -> 3.3333333 | K4: =表1温室气体盘查表!AL6 -> 29.162368 | L4: =K4/$K$101 -> 1.8674006e-06 | M4: =J4*L4 -> 6.2246687e-06
A5: 3 | B5: =表1温室气体盘查表!C7 -> 烟煤燃烧 | C5: =表1温室气体盘查表!D7 -> 高炉 | D5: 自动连续量测 | E5: 国际排放因子 | F5: 校准且合格 | G5: =IF(D5="自动连续量测",6,IF(D5="定期量测/抄表/铭牌",3,1)) -> 6 | H5: =IF(E5="量测/质量平衡排放因子",6,IF(E5="制程/设备排放因子",5,IF(E5="制造商提供的排放因子",4,IF(E5="区域排放因子",3,IF(E5="国家排放因子",2,1))))) -> 1 | I5: =IF(F5="校准且合格",6,IF(F5="未校准",1,3)) -> 6 | J5: =AVERAGE(G5:I5) -> 4.3333333 | K5: =表1温室气体盘查表!AL7 -> 925941.32 | L5: =K5/$K$101 -> 0.059292283 | M5: =J5*L5 -> 0.25693323
A6: 4 | B6: =表1温室气体盘查表!C8 -> 无烟煤燃烧 | C6: =表1温室气体盘查表!D8 -> 高炉、烧结 | D6: 自动连续量测 | E6: 国际排放因子 | F6: 校准且合格 | G6: =IF(D6="自动连续量测",6,IF(D6="定期量测/抄表/铭牌",3,1)) -> 6 | H6: =IF(E6="量测/质量平衡排放因子",6,IF(E6="制程/设备排放因子",5,IF(E6="制造商提供的排放因子",4,IF(E6="区域排放因子",3,IF(E6="国家排放因子",2,1))))) -> 1 | I6: =IF(F6="校准且合格",6,IF(F6="未校准",1,3)) -> 6 | J6: =AVERAGE(G6:I6) -> 4.3333333 | K6: =表1温室气体盘查表!AL8 -> 637282.39 | L6: =K6/$K$101 -> 0.040808124 | M6: =J6*L6 -> 0.1768352
A7: 5 | B7: =表1温室气体盘查表!C9 -> 洗精煤燃烧 | C7: =表1温室气体盘查表!D9 -> 焦炉 | D7: 自动连续量测 | E7: 国际排放因子 | F7: 校准且合格 | G7: =IF(D7="自动连续量测",6,IF(D7="定期量测/抄表/铭牌",3,1)) -> 6 | H7: =IF(E7="量测/质量平衡排放因子",6,IF(E7="制程/设备排放因子",5,IF(E7="制造商提供的排放因子",4,IF(E7="区域排放因子",3,IF(E7="国家排放因子",2,1))))) -> 1 | I7: =IF(F7="校准且合格",6,IF(F7="未校准",1,3)) -> 6 | J7: =AVERAGE(G7:I7) -> 4.3333333 | K7: =表1温室气体盘查表!AL9 -> 4824841.6 | L7: =K7/$K$101 -> 0.30895681 | M7: =J7*L7 -> 1.3388128
A8: 6 | B8: =表1温室气体盘查表!C10 -> 焦炭燃烧 | C8: =表1温室气体盘查表!D10 -> 高炉 | D8: 自动连续量测 | E8: 国际排放因子 | F8: 校准且合格 | G8: =IF(D8="自动连续量测",6,IF(D8="定期量测/抄表/铭牌",3,1)) -> 6 | H8: =IF(E8="量测/质量平衡排放因子",6,IF(E8="制程/设备排放因子",5,IF(E8="制造商提供的排放因子",4,IF(E8="区域排放因子",3,IF(E8="国家排放因子",2,1))))) -> 1 | I8: =IF(F8="校准且合格",6,IF(F8="未校准",1,3)) -> 6 | J8: =AVERAGE(G8:I8) -> 4.3333333 | K8: =表1温室气体盘查表!AL10 -> 439843.84 | L8: =K8/$K$101 -> 0.028165225 | M8: =J8*L8 -> 0.12204931
A9: 7 | B9: =表1温室气体盘查表!C11 -> 焦屑燃烧 | C9: =表1温室气体盘查表!D11 -> 烧结、高炉 | D9: 自动连续量测 | E9: 国际排放因子 | F9: 校准且合格 | G9: =IF(D9="自动连续量测",6,IF(D9="定期量测/抄表/铭牌",3,1)) -> 6 | H9: =IF(E9="量测/质量平衡排放因子",6,IF(E9="制程/设备排放因子",5,IF(E9="制造商提供的排放因子",4,IF(E9="区域排放因子",3,IF(E9="国家排放因子",2,1))))) -> 1 | I9: =IF(F9="校准且合格",6,IF(F9="未校准",1,3)) -> 6 | J9: =AVERAGE(G9:I9) -> 4.3333333 | K9: =表1温室气体盘查表!AL11 -> 364657.36 | L9: =K9/$K$101 -> 0.023350689 | M9: =J9*L9 -> 0.10118632
A10: 8 | B10: =表1温室气体盘查表!C12 -> 焦炉煤气燃烧 | C10: =表1温室气体盘查表!D12 -> 外售 | D10: 自动连续量测 | E10: 国际排放因子 | F10: 校准且合格 | G10: =IF(D10="自动连续量测",6,IF(D10="定期量测/抄表/铭牌",3,1)) -> 6 | H10: =IF(E10="量测/质量平衡排放因子",6,IF(E10="制程/设备排放因子",5,IF(E10="制造商提供的排放因子",4,IF(E10="区域排放因子",3,IF(E10="国家排放因子",2,1))))) -> 1 | I10: =IF(F10="校准且合格",6,IF(F10="未校准",1,3)) -> 6 | J10: =AVERAGE(G10:I10) -> 4.3333333 | K10: =表1温室气体盘查表!AL12 -> -3833.1355 | L10: =K10/$K$101 -> -0.0002454533 | M10: =J10*L10 -> -0.001063631
A11: 9 | B11: =表1温室气体盘查表!C13 -> 0#柴油燃烧 | C11: =表1温室气体盘查表!D13 -> 场内运输 | D11: 定期量测/抄表/铭牌 | E11: 国际排放因子 | F11: 校准但不合格/未校准但数据可查证 | G11: =IF(D11="自动连续量测",6,IF(D11="定期量测/抄表/铭牌",3,1)) -> 3 | H11: =IF(E11="量测/质量平衡排放因子",6,IF(E11="制程/设备排放因子",5,IF(E11="制造商提供的排放因子",4,IF(E11="区域排放因子",3,IF(E11="国家排放因子",2,1))))) -> 1 | I11: =IF(F11="校准且合格",6,IF(F11="未校准",1,3)) -> 3 | J11: =AVERAGE(G11:I11) -> 2.3333333 | K11: =表1温室气体盘查表!AL13 -> 4417.0726 | L11: =K11/$K$101 -> 0.00028284548 | M11: =J11*L11 -> 0.0006599728
A12: 10 | B12: =表1温室气体盘查表!C14 -> 92#汽油燃烧 | C12: =表1温室气体盘查表!D14 -> 公务车 | D12: 定期量测/抄表/铭牌 | E12: 国际排放因子 | F12: 校准但不合格/未校准但数据可查证 | G12: =IF(D12="自动连续量测",6,IF(D12="定期量测/抄表/铭牌",3,1)) -> 3 | H12: =IF(E12="量测/质量平衡排放因子",6,IF(E12="制程/设备排放因子",5,IF(E12="制造商提供的排放因子",4,IF(E12="区域排放因子",3,IF(E12="国家排放因子",2,1))))) -> 1 | I12: =IF(F12="校准且合格",6,IF(F12="未校准",1,3)) -> 3 | J12: =AVERAGE(G12:I12) -> 2.3333333 | K12: =表1温室气体盘查表!AL14 -> 149.47012 | L12: =K12/$K$101 -> 9.5712598e-06 | M12: =J12*L12 -> 2.233294e-05
A13: 11 | B13: =表1温室气体盘查表!C15 -> 制冷剂逸散（R32） | C13: =表1温室气体盘查表!D15 -> 分体式空调 | D13: 定期量测/抄表/铭牌 | E13: 国家排放因子 | F13: 校准且合格 | G13: =IF(D13="自动连续量测",6,IF(D13="定期量测/抄表/铭牌",3,1)) -> 3 | H13: =IF(E13="量测/质量平衡排放因子",6,IF(E13="制程/设备排放因子",5,IF(E13="制造商提供的排放因子",4,IF(E13="区域排放因子",3,IF(E13="国家排放因子",2,1))))) -> 2 | I13: =IF(F13="校准且合格",6,IF(F13="未校准",1,3)) -> 6 | J13: =AVERAGE(G13:I13) -> 3.6666667 | K13: =表1温室气体盘查表!AL15 -> 717.03 | L13: =K13/$K$101 -> 4.591473e-05 | M13: =J13*L13 -> 0.00016835401
A14: 12 | B14: =表1温室气体盘查表!C16 -> CO2逸散 | C14: =表1温室气体盘查表!D16 -> 二氧化碳灭火器 | D14: 定期量测/抄表/铭牌 | E14: 国家排放因子 | F14: 校准且合格 | G14: =IF(D14="自动连续量测",6,IF(D14="定期量测/抄表/铭牌",3,1)) -> 3 | H14: =IF(E14="量测/质量平衡排放因子",6,IF(E14="制程/设备排放因子",5,IF(E14="制造商提供的排放因子",4,IF(E14="区域排放因子",3,IF(E14="国家排放因子",2,1))))) -> 2 | I14: =IF(F14="校准且合格",6,IF(F14="未校准",1,3)) -> 6 | J14: =AVERAGE(G14:I14) -> 3.6666667 | K14: =表1温室气体盘查表!AL16 -> 0.66 | L14: =K14/$K$101 -> 4.2262837e-08 | M14: =J14*L14 -> 1.5496374e-07
